Workbook

Sheet START HERE
B2: WEEKLY BILLING REPORT · BPO
B4: =" Week: "&TEXT(Config!$C$7,"dd/mm/yyyy")&" to "&TEXT(Config!$C$8,"dd/mm/yyyy")&" · Target: "&TEXT(Config!$C$9,"0")&" hours per day = 1.0 billing unit" -> Week: 31/08/2026 to 04/09/2026 · Target: 8 hours per day = 1.0 billing unit
B6: THE GOLDEN RULE
B7: Every BPO landman must close EXACTLY 8 HOURS per business day. In BTabs that is written as 1.0 in "Time Worked". Each hour is worth 0.125 (1 h = 0.125 · 2 h = 0.25 · 4 h = 0.5 · 8 h = 1.0). If someone did not work (medical leave, personal day, vacation) they must ALSO log the day as Time Off / BPO Vacation and write the hours at the start of the detail. That way the day still adds up to 8.
B11: HOW TO USE IT EACH WEEK (3 steps)
B12: STEP 1 | D12: Export the BTabs report and paste everything into the RawBtabs tab, starting at cell A2. Do not change the headers in row 1. | F12: Tab RawBtabs
B14: STEP 2 | D14: Go to the Config tab and type the MONDAY of the week you want to review into the yellow cell. That is the only thing you change. | F14: Tab Config
B16: STEP 3 | D16: Open Dashboard, Alerts, TimeOff and SeniorReview. Already calculated. Check DataHealth first, then fill the yellow sign-off cells. | F16: Tab Dashboard
B19: WHAT IS IN EACH TAB
C20: Dashboard | D20: The main board. A traffic light per person per day + the status of the week.
C21: Alerts | D21: Only the days with a problem, with the concrete action to take. This is the work list.
C22: TimeOff | D22: Who did not work billable hours (personal, medical leave, vacation) and whether the day still closed at 8 h.
C23: SeniorReview | D23: Summary by Team Lead + a 7-point control checklist + space for the senior sign-off.
C24: DataHealth | D24: Checks the pasted data itself: missing roster names, weekend entries, duplicates, unapproved rows.
C25: Legend | D25: Every colour, every message and every column explained, plus the glossary. Read this once.
C26: Historical | D26: How many alerts each person accumulates week over week, with a risk indicator.
C27: Detail | D27: Calculation engine: one row per person per day. Technical sheet, no need to touch it.
C28: Config | D28: The parameters: week to report, target hours, tolerance and time off types.
C29: BPOworkers | D29: The roster: who belongs to BPO and who their Team Lead is. Add or remove people here.
B30: COLOR CODE
B31: Yellow | D31: A cell YOU can edit.
B32: Green | D32: Meets the target. All good.
B33: Light red | D33: Under 8 h. There is billing being lost.
B34: Blue | D34: Over 8 h. Check for duplicates.
B35: Dark red | D35: Logged nothing in BTabs that day. The most serious case.
B37: WHERE EVERY NUMBER COMES FROM (the report formula)
B38: TOTAL COUNTED FOR THE DAY = ( Time Worked x 8 ) + Time off hours · "Time Worked" is column K of the BTabs export (1.0 = a full day). · "Time off hours" is the first number in the "Work Performed Detail" field whenever the Work Type is Time Off, BPO Vacation or Holiday. · This is the same logic as the calculated field in the original file; here it is written in native Excel formulas so it works without Google Sheets.
B43: IMPORTANT · This file does NOT use the Google Sheets FILTER or REGEXEXTRACT functions that the original relied on. Everything is in native Excel formulas, so it opens and recalculates in desktop Excel with nothing lost.

Sheet Dashboard
T1: _aux
B2: WEEKLY BILLING DASHBOARD - BPO | T2: =Config!$C$9 -> 8
B3: Green = closed 8 h. Red = under target. Blue = over 8 h. Dark red = no entry in BTabs that day. | T3: =Config!$C$10 -> 0
B5: PEOPLE IN ROSTER | D5: PERFECT WEEK | F5: TO REVIEW | H5: CRITICAL | J5: % COMPLIANCE | L5: BILLED HOURS | N5: TARGET HOURS
B6: =Config!$C$14 -> 38 | D6: =COUNTIF($Q$10:$Q$69,0) -> 33 | F6: =COUNTIF($Q$10:$Q$69,1)+COUNTIF($Q$10:$Q$69,2) -> 3 | H6: =COUNTIF($Q$10:$Q$69,3) -> 2 | J6: =IFERROR($D$6/$B$6,0) -> 0.86842105 | L6: =SUM($J$10:$J$69) -> 1528 | N6: =SUM($K$10:$K$69) -> 1520
B8: # | C8: LANDMAN | D8: TEAM LEAD | E8: HOURS COUNTED PER DAY (target 8 h = 1.0 unit) | J8: TOTAL week | K8: TARGET week | L8: DIFF. vs target | M8: Days with entries | N8: Days on target | O8: Days with alert | P8: WEEK STATUS | Q8: Sev. | R8: WHY - exactly which day is off, and by how much
E9: =LEFT(INDEX(Config!$F$7:$F$11,1),3)&" "&TEXT(Config!$C$7+0,"dd/mm") -> Mon 31/08 | F9: =LEFT(INDEX(Config!$F$7:$F$11,2),3)&" "&TEXT(Config!$C$7+1,"dd/mm") -> Tue 01/09 | G9: =LEFT(INDEX(Config!$F$7:$F$11,3),3)&" "&TEXT(Config!$C$7+2,"dd/mm") -> Wed 02/09 | H9: =LEFT(INDEX(Config!$F$7:$F$11,4),3)&" "&TEXT(Config!$C$7+3,"dd/mm") -> Thu 03/09 | I9: =LEFT(INDEX(Config!$F$7:$F$11,5),3)&" "&TEXT(Config!$C$7+4,"dd/mm") -> Fri 04/09
B10: =IF($C10="","",ROW()-9) -> 1 | C10: =IF(ROW()-9>Config!$C$14,"",INDEX(BPOworkers!$B$6:$B$105,ROW()-9)) -> A Camargo | D10: =IF($C10="","",IFERROR(INDEX(BPOworkers!$E$6:$E$105,MATCH($C10,BPOworkers!$B$6:$B$105,0)),"")) -> BPO Management | E10: =IF($C10="","",IF(INDEX(Detail!$G$4:$G$303,(ROW()-10)*5+1)=0,"",INDEX(Detail!$J$4:$J$303,(ROW()-10)*5+1))) -> 8 | F10: =IF($C10="","",IF(INDEX(Detail!$G$4:$G$303,(ROW()-10)*5+2)=0,"",INDEX(Detail!$J$4:$J$303,(ROW()-10)*5+2))) -> 8 | G10: =IF($C10="","",IF(INDEX(Detail!$G$4:$G$303,(ROW()-10)*5+3)=0,"",INDEX(Detail!$J$4:$J$303,(ROW()-10)*5+3))) -> 8 | H10: =IF($C10="","",IF(INDEX(Detail!$G$4:$G$303,(ROW()-10)*5+4)=0,"",INDEX(Detail!$J$4:$J$303,(ROW()-10)*5+4))) -> 8 | I10: =IF($C10="","",IF(INDEX(Detail!$G$4:$G$303,(ROW()-10)*5+5)=0,"",INDEX(Detail!$J$4:$J$303,(ROW()-10)*5+5))) -> 8 | J10: =IF($C10="","",SUM($E10:$I10)) -> 40 | K10: =IF($C10="","",Config!$C$16) -> 40 | L10: =IF($C10="","",$J10-$K10) -> 0 | M10: =IF($C10="","",COUNT($E10:$I10)) -> 5 | N10: =IF($C10="","",COUNTIFS(Detail!$C$4:$C$303,$C10,Detail!$N$4:$N$303,0)) -> 5 | O10: =IF($C10="","",COUNTIFS(Detail!$C$4:$C$303,$C10,Detail!$N$4:$N$303,">0")) -> 0 | P10: =IF($C10="","",IF($M10=0,"⛔ BILLED NOTHING",IF($M10<5,"⛔ MISSING "&TEXT(5-$M10,"0")&" DAY(S) IN BTABS",IF($O10=0,"✅ PERFECT WEEK",IF($L10<0,"🔻 UNDER TARGET ("&TEXT($L10,"0.##")&" h)",IF($L10>0,"🔺 OVER TARGET (+"&TEXT($L10,"0.##")&" h)","⚠️ CHECK THE DAYS")))))) -> ✅ PERFECT WEEK | Q10: =IF($C10="","",IF($M10<5,3,IF($O10=0,0,IF($L10>0,1,2)))) -> 0 | R10: =IF($C10="","",IF($O10=0,"All 5 days closed at target. Nothing to fix.",TRIM(IF(E10="",LEFT(INDEX(Config!$F$7:$F$11,1),3)&": no entry in BTabs. ",IF(ABS(E10-$T$2)>$T$3,LEFT(INDEX(Config!$F$7:$F$11,1),3)&": "&TEXT(E10,"0.##")&" h instead of "&TEXT($T$2,"0")&" h. ",""))&IF(F10="",LEFT(INDEX(Config!$F$7:$F$11,2),3)&": no entry in BTabs. ",IF(ABS(F10-$T$2)>$T$3,LEFT(INDEX(Config!$F$7:$F$11,2),3)&": "&TEXT(F10,"0.##")&" h instead of "&TEXT($T$2,"0")&" h. ",""))&IF(G10="",LEFT(INDEX(Config!$F$7:$F$11,3),3)&": no entry in BTabs. ",IF(ABS(G10-$T$2)>$T$3,LEFT(INDEX(Config!$F$7:$F$11,3),3)&": "&TEXT(G10,"0.##")&" h instead of "&TEXT($T$2,"0")&" h. ",""))&IF(H10="",LEFT(INDEX(Config!$F$7:$F$11,4),3)&": no entry in BTabs. ",IF(ABS(H10-$T$2)>$T$3,LEFT(INDEX(Config!$F$7:$F$11,4),3)&": "&TEXT(H10,"0.##")&" h instead of "&TEXT($T$2,"0")&" h. ",""))&IF(I10="",LEFT(INDEX(Config!$F$7:$F$11,5),3)&": no entry in BTabs. ",IF(ABS(I10-$T$2)>$T$3,LEFT(INDEX(Config!$F$7:$F$11,5),3)&": "&TEXT(I10,"0.##")&" h instead of "&TEXT($T$2,"0")&" h. ",""))))) -> All 5 days closed at target. Nothing to fix.
B11: =IF($C11="","",ROW()-9) -> 2 | C11: =IF(ROW()-9>Config!$C$14,"",INDEX(BPOworkers!$B$6:$B$105,ROW()-9)) -> A Lopez | D11: =IF($C11="","",IFERROR(INDEX(BPOworkers!$E$6:$E$105,MATCH($C11,BPOworkers!$B$6:$B$105,0)),"")) -> S Romero | E11: =IF($C11="","",IF(INDEX(Detail!$G$4:$G$303,(ROW()-10)*5+1)=0,"",INDEX(Detail!$J$4:$J$303,(ROW()-10)*5+1))) -> 8 | F11: =IF($C11="","",IF(INDEX(Detail!$G$4:$G$303,(ROW()-10)*5+2)=0,"",INDEX(Detail!$J$4:$J$303,(ROW()-10)*5+2))) -> 8 | G11: =IF($C11="","",IF(INDEX(Detail!$G$4:$G$303,(ROW()-10)*5+3)=0,"",INDEX(Detail!$J$4:$J$303,(ROW()-10)*5+3))) -> 8 | H11: =IF($C11="","",IF(INDEX(Detail!$G$4:$G$303,(ROW()-10)*5+4)=0,"",INDEX(Detail!$J$4:$J$303,(ROW()-10)*5+4))) -> 8 | I11: =IF($C11="","",IF(INDEX(Detail!$G$4:$G$303,(ROW()-10)*5+5)=0,"",INDEX(Detail!$J$4:$J$303,(ROW()-10)*5+5))) -> 8 | J11: =IF($C11="","",SUM($E11:$I11)) -> 40 | K11: =IF($C11="","",Config!$C$16) -> 40 | L11: =IF($C11="","",$J11-$K11) -> 0 | M11: =IF($C11="","",COUNT($E11:$I11)) -> 5 | N11: =IF($C11="","",COUNTIFS(Detail!$C$4:$C$303,$C11,Detail!$N$4:$N$303,0)) -> 5 | O11: =IF($C11="","",COUNTIFS(Detail!$C$4:$C$303,$C11,Detail!$N$4:$N$303,">0")) -> 0 | P11: =IF($C11="","",IF($M11=0,"⛔ BILLED NOTHING",IF($M11<5,"⛔ MISSING "&TEXT(5-$M11,"0")&" DAY(S) IN BTABS",IF($O11=0,"✅ PERFECT WEEK",IF($L11<0,"🔻 UNDER TARGET ("&TEXT($L11,"0.##")&" h)",IF($L11>0,"🔺 OVER TARGET (+"&TEXT($L11,"0.##")&" h)","⚠️ CHECK THE DAYS")))))) -> ✅ PERFECT WEEK | Q11: =IF($C11="","",IF($M11<5,3,IF($O11=0,0,IF($L11>0,1,2)))) -> 0 | R11: =IF($C11="","",IF($O11=0,"All 5 days closed at target. Nothing to fix.",TRIM(IF(E11="",LEFT(INDEX(Config!$F$7:$F$11,1),3)&": no entry in BTabs. ",IF(ABS(E11-$T$2)>$T$3,LEFT(INDEX(Config!$F$7:$F$11,1),3)&": "&TEXT(E11,"0.##")&" h instead of "&TEXT($T$2,"0")&" h. ",""))&IF(F11="",LEFT(INDEX(Config!$F$7:$F$11,2),3)&": no entry in BTabs. ",IF(ABS(F11-$T$2)>$T$3,LEFT(INDEX(Config!$F$7:$F$11,2),3)&": "&TEXT(F11,"0.##")&" h instead of "&TEXT($T$2,"0")&" h. ",""))&IF(G11="",LEFT(INDEX(Config!$F$7:$F$11,3),3)&": no entry in BTabs. ",IF(ABS(G11-$T$2)>$T$3,LEFT(INDEX(Config!$F$7:$F$11,3),3)&": "&TEXT(G11,"0.##")&" h instead of "&TEXT($T$2,"0")&" h. ",""))&IF(H11="",LEFT(INDEX(Config!$F$7:$F$11,4),3)&": no entry in BTabs. ",IF(ABS(H11-$T$2)>$T$3,LEFT(INDEX(Config!$F$7:$F$11,4),3)&": "&TEXT(H11,"0.##")&" h instead of "&TEXT($T$2,"0")&" h. ",""))&IF(I11="",LEFT(INDEX(Config!$F$7:$F$11,5),3)&": no entry in BTabs. ",IF(ABS(I11-$T$2)>$T$3,LEFT(INDEX(Config!$F$7:$F$11,5),3)&": "&TEXT(I11,"0.##")&" h instead of "&TEXT($T$2,"0")&" h. ",""))))) -> All 5 days closed at target. Nothing to fix.
B12: =IF($C12="","",ROW()-9) -> 3 | C12: =IF(ROW()-9>Config!$C$14,"",INDEX(BPOworkers!$B$6:$B$105,ROW()-9)) -> A Lorenzo | D12: =IF($C12="","",IFERROR(INDEX(BPOworkers!$E$6:$E$105,MATCH($C12,BPOworkers!$B$6:$B$105,0)),"")) -> BPO Management | E12: =IF($C12="","",IF(INDEX(Detail!$G$4:$G$303,(ROW()-10)*5+1)=0,"",INDEX(Detail!$J$4:$J$303,(ROW()-10)*5+1))) -> 8 | F12: =IF($C12="","",IF(INDEX(Detail!$G$4:$G$303,(ROW()-10)*5+2)=0,"",INDEX(Detail!$J$4:$J$303,(ROW()-10)*5+2))) -> 8 | G12: =IF($C12="","",IF(INDEX(Detail!$G$4:$G$303,(ROW()-10)*5+3)=0,"",INDEX(Detail!$J$4:$J$303,(ROW()-10)*5+3))) -> 8 | H12: =IF($C12="","",IF(INDEX(Detail!$G$4:$G$303,(ROW()-10)*5+4)=0,"",INDEX(Detail!$J$4:$J$303,(ROW()-10)*5+4))) -> 8 | I12: =IF($C12="","",IF(INDEX(Detail!$G$4:$G$303,(ROW()-10)*5+5)=0,"",INDEX(Detail!$J$4:$J$303,(ROW()-10)*5+5))) -> 8 | J12: =IF($C12="","",SUM($E12:$I12)) -> 40 | K12: =IF($C12="","",Config!$C$16) -> 40 | L12: =IF($C12="","",$J12-$K12) -> 0 | M12: =IF($C12="","",COUNT($E12:$I12)) -> 5 | N12: =IF($C12="","",COUNTIFS(Detail!$C$4:$C$303,$C12,Detail!$N$4:$N$303,0)) -> 5 | O12: =IF($C12="","",COUNTIFS(Detail!$C$4:$C$303,$C12,Detail!$N$4:$N$303,">0")) -> 0 | P12: =IF($C12="","",IF($M12=0,"⛔ BILLED NOTHING",IF($M12<5,"⛔ MISSING "&TEXT(5-$M12,"0")&" DAY(S) IN BTABS",IF($O12=0,"✅ PERFECT WEEK",IF($L12<0,"🔻 UNDER TARGET ("&TEXT($L12,"0.##")&" h)",IF($L12>0,"🔺 OVER TARGET (+"&TEXT($L12,"0.##")&" h)","⚠️ CHECK THE DAYS")))))) -> ✅ PERFECT WEEK | Q12: =IF($C12="","",IF($M12<5,3,IF($O12=0,0,IF($L12>0,1,2)))) -> 0 | R12: =IF($C12="","",IF($O12=0,"All 5 days closed at target. Nothing to fix.",TRIM(IF(E12="",LEFT(INDEX(Config!$F$7:$F$11,1),3)&": no entry in BTabs. ",IF(ABS(E12-$T$2)>$T$3,LEFT(INDEX(Config!$F$7:$F$11,1),3)&": "&TEXT(E12,"0.##")&" h instead of "&TEXT($T$2,"0")&" h. ",""))&IF(F12="",LEFT(INDEX(Config!$F$7:$F$11,2),3)&": no entry in BTabs. ",IF(ABS(F12-$T$2)>$T$3,LEFT(INDEX(Config!$F$7:$F$11,2),3)&": "&TEXT(F12,"0.##")&" h instead of "&TEXT($T$2,"0")&" h. ",""))&IF(G12="",LEFT(INDEX(Config!$F$7:$F$11,3),3)&": no entry in BTabs. ",IF(ABS(G12-$T$2)>$T$3,LEFT(INDEX(Config!$F$7:$F$11,3),3)&": "&TEXT(G12,"0.##")&" h instead of "&TEXT($T$2,"0")&" h. ",""))&IF(H12="",LEFT(INDEX(Config!$F$7:$F$11,4),3)&": no entry in BTabs. ",IF(ABS(H12-$T$2)>$T$3,LEFT(INDEX(Config!$F$7:$F$11,4),3)&": "&TEXT(H12,"0.##")&" h instead of "&TEXT($T$2,"0")&" h. ",""))&IF(I12="",LEFT(INDEX(Config!$F$7:$F$11,5),3)&": no entry in BTabs. ",IF(ABS(I12-$T$2)>$T$3,LEFT(INDEX(Config!$F$7:$F$11,5),3)&": "&TEXT(I12,"0.##")&" h instead of "&TEXT($T$2,"0")&" h. ",""))))) -> All 5 days closed at target. Nothing to fix.
B13: =IF($C13="","",ROW()-9) -> 4 | C13: =IF(ROW()-9>Config!$C$14,"",INDEX(BPOworkers!$B$6:$B$105,ROW()-9)) -> C Mesa | D13: =IF($C13="","",IFERROR(INDEX(BPOworkers!$E$6:$E$105,MATCH($C13,BPOworkers!$B$6:$B$105,0)),"")) -> M Leon | E13: =IF($C13="","",IF(INDEX(Detail!$G$4:$G$303,(ROW()-10)*5+1)=0,"",INDEX(Detail!$J$4:$J$303,(ROW()-10)*5+1))) -> 8 | F13: =IF($C13="","",IF(INDEX(Detail!$G$4:$G$303,(ROW()-10)*5+2)=0,"",INDEX(Detail!$J$4:$J$303,(ROW()-10)*5+2))) -> 8 | G13: =IF($C13="","",IF(INDEX(Detail!$G$4:$G$303,(ROW()-10)*5+3)=0,"",INDEX(Detail!$J$4:$J$303,(ROW()-10)*5+3))) -> 8 | H13: =IF($C13="","",IF(INDEX(Detail!$G$4:$G$303,(ROW()-10)*5+4)=0,"",INDEX(Detail!$J$4:$J$303,(ROW()-10)*5+4))) -> 8 | I13: =IF($C13="","",IF(INDEX(Detail!$G$4:$G$303,(ROW()-10)*5+5)=0,"",INDEX(Detail!$J$4:$J$303,(ROW()-10)*5+5))) -> 8 | J13: =IF($C13="","",SUM($E13:$I13)) -> 40 | K13: =IF($C13="","",Config!$C$16) -> 40 | L13: =IF($C13="","",$J13-$K13) -> 0 | M13: =IF($C13="","",COUNT($E13:$I13)) -> 5 | N13: =IF($C13="","",COUNTIFS(Detail!$C$4:$C$303,$C13,Detail!$N$4:$N$303,0)) -> 5 | O13: =IF($C13="","",COUNTIFS(Detail!$C$4:$C$303,$C13,Detail!$N$4:$N$303,">0")) -> 0 | P13: =IF($C13="","",IF($M13=0,"⛔ BILLED NOTHING",IF($M13<5,"⛔ MISSING "&TEXT(5-$M13,"0")&" DAY(S) IN BTABS",IF($O13=0,"✅ PERFECT WEEK",IF($L13<0,"🔻 UNDER TARGET ("&TEXT($L13,"0.##")&" h)",IF($L13>0,"🔺 OVER TARGET (+"&TEXT($L13,"0.##")&" h)","⚠️ CHECK THE DAYS")))))) -> ✅ PERFECT WEEK | Q13: =IF($C13="","",IF($M13<5,3,IF($O13=0,0,IF($L13>0,1,2)))) -> 0 | R13: =IF($C13="","",IF($O13=0,"All 5 days closed at target. Nothing to fix.",TRIM(IF(E13="",LEFT(INDEX(Config!$F$7:$F$11,1),3)&": no entry in BTabs. ",IF(ABS(E13-$T$2)>$T$3,LEFT(INDEX(Config!$F$7:$F$11,1),3)&": "&TEXT(E13,"0.##")&" h instead of "&TEXT($T$2,"0")&" h. ",""))&IF(F13="",LEFT(INDEX(Config!$F$7:$F$11,2),3)&": no entry in BTabs. ",IF(ABS(F13-$T$2)>$T$3,LEFT(INDEX(Config!$F$7:$F$11,2),3)&": "&TEXT(F13,"0.##")&" h instead of "&TEXT($T$2,"0")&" h. ",""))&IF(G13="",LEFT(INDEX(Config!$F$7:$F$11,3),3)&": no entry in BTabs. ",IF(ABS(G13-$T$2)>$T$3,LEFT(INDEX(Config!$F$7:$F$11,3),3)&": "&TEXT(G13,"0.##")&" h instead of "&TEXT($T$2,"0")&" h. ",""))&IF(H13="",LEFT(INDEX(Config!$F$7:$F$11,4),3)&": no entry in BTabs. ",IF(ABS(H13-$T$2)>$T$3,LEFT(INDEX(Config!$F$7:$F$11,4),3)&": "&TEXT(H13,"0.##")&" h instead of "&TEXT($T$2,"0")&" h. ",""))&IF(I13="",LEFT(INDEX(Config!$F$7:$F$11,5),3)&": no entry in BTabs. ",IF(ABS(I13-$T$2)>$T$3,LEFT(INDEX(Config!$F$7:$F$11,5),3)&": "&TEXT(I13,"0.##")&" h instead of "&TEXT($T$2,"0")&" h. ",""))))) -> All 5 days closed at target. Nothing to fix.
B14: =IF($C14="","",ROW()-9) -> 5 | C14: =IF(ROW()-9>Config!$C$14,"",INDEX(BPOworkers!$B$6:$B$105,ROW()-9)) -> H Daza | D14: =IF($C14="","",IFERROR(INDEX(BPOworkers!$E$6:$E$105,MATCH($C14,BPOworkers!$B$6:$B$105,0)),"")) -> BPO Management | E14: =IF($C14="","",IF(INDEX(Detail!$G$4:$G$303,(ROW()-10)*5+1)=0,"",INDEX(Detail!$J$4:$J$303,(ROW()-10)*5+1))) -> 8 | F14: =IF($C14="","",IF(INDEX(Detail!$G$4:$G$303,(ROW()-10)*5+2)=0,"",INDEX(Detail!$J$4:$J$303,(ROW()-10)*5+2))) -> 8 | G14: =IF($C14="","",IF(INDEX(Detail!$G$4:$G$303,(ROW()-10)*5+3)=0,"",INDEX(Detail!$J$4:$J$303,(ROW()-10)*5+3))) -> 8 | H14: =IF($C14="","",IF(INDEX(Detail!$G$4:$G$303,(ROW()-10)*5+4)=0,"",INDEX(Detail!$J$4:$J$303,(ROW()-10)*5+4))) -> 8 | I14: =IF($C14="","",IF(INDEX(Detail!$G$4:$G$303,(ROW()-10)*5+5)=0,"",INDEX(Detail!$J$4:$J$303,(ROW()-10)*5+5))) -> 8 | J14: =IF($C14="","",SUM($E14:$I14)) -> 40 | K14: =IF($C14="","",Config!$C$16) -> 40 | L14: =IF($C14="","",$J14-$K14) -> 0 | M14: =IF($C14="","",COUNT($E14:$I14)) -> 5 | N14: =IF($C14="","",COUNTIFS(Detail!$C$4:$C$303,$C14,Detail!$N$4:$N$303,0)) -> 5 | O14: =IF($C14="","",COUNTIFS(Detail!$C$4:$C$303,$C14,Detail!$N$4:$N$303,">0")) -> 0 | P14: =IF($C14="","",IF($M14=0,"⛔ BILLED NOTHING",IF($M14<5,"⛔ MISSING "&TEXT(5-$M14,"0")&" DAY(S) IN BTABS",IF($O14=0,"✅ PERFECT WEEK",IF($L14<0,"🔻 UNDER TARGET ("&TEXT($L14,"0.##")&" h)",IF($L14>0,"🔺 OVER TARGET (+"&TEXT($L14,"0.##")&" h)","⚠️ CHECK THE DAYS")))))) -> ✅ PERFECT WEEK | Q14: =IF($C14="","",IF($M14<5,3,IF($O14=0,0,IF($L14>0,1,2)))) -> 0 | R14: =IF($C14="","",IF($O14=0,"All 5 days closed at target. Nothing to fix.",TRIM(IF(E14="",LEFT(INDEX(Config!$F$7:$F$11,1),3)&": no entry in BTabs. ",IF(ABS(E14-$T$2)>$T$3,LEFT(INDEX(Config!$F$7:$F$11,1),3)&": "&TEXT(E14,"0.##")&" h instead of "&TEXT($T$2,"0")&" h. ",""))&IF(F14="",LEFT(INDEX(Config!$F$7:$F$11,2),3)&": no entry in BTabs. ",IF(ABS(F14-$T$2)>$T$3,LEFT(INDEX(Config!$F$7:$F$11,2),3)&": "&TEXT(F14,"0.##")&" h instead of "&TEXT($T$2,"0")&" h. ",""))&IF(G14="",LEFT(INDEX(Config!$F$7:$F$11,3),3)&": no entry in BTabs. ",IF(ABS(G14-$T$2)>$T$3,LEFT(INDEX(Config!$F$7:$F$11,3),3)&": "&TEXT(G14,"0.##")&" h instead of "&TEXT($T$2,"0")&" h. ",""))&IF(H14="",LEFT(INDEX(Config!$F$7:$F$11,4),3)&": no entry in BTabs. ",IF(ABS(H14-$T$2)>$T$3,LEFT(INDEX(Config!$F$7:$F$11,4),3)&": "&TEXT(H14,"0.##")&" h instead of "&TEXT($T$2,"0")&" h. ",""))&IF(I14="",LEFT(INDEX(Config!$F$7:$F$11,5),3)&": no entry in BTabs. ",IF(ABS(I14-$T$2)>$T$3,LEFT(INDEX(Config!$F$7:$F$11,5),3)&": "&TEXT(I14,"0.##")&" h instead of "&TEXT($T$2,"0")&" h. ",""))))) -> All 5 days closed at target. Nothing to fix.
B15: =IF($C15="","",ROW()-9) -> 6 | C15: =IF(ROW()-9>Config!$C$14,"",INDEX(BPOworkers!$B$6:$B$105,ROW()-9)) -> I De La Parra | D15: =IF($C15="","",IFERROR(INDEX(BPOworkers!$E$6:$E$105,MATCH($C15,BPOworkers!$B$6:$B$105,0)),"")) -> A Lorenzo | E15: =IF($C15="","",IF(INDEX(Detail!$G$4:$G$303,(ROW()-10)*5+1)=0,"",INDEX(Detail!$J$4:$J$303,(ROW()-10)*5+1))) -> 8 | F15: =IF($C15="","",IF(INDEX(Detail!$G$4:$G$303,(ROW()-10)*5+2)=0,"",INDEX(Detail!$J$4:$J$303,(ROW()-10)*5+2))) -> 8 | G15: =IF($C15="","",IF(INDEX(Detail!$G$4:$G$303,(ROW()-10)*5+3)=0,"",INDEX(Detail!$J$4:$J$303,(ROW()-10)*5+3))) -> 8 | H15: =IF($C15="","",IF(INDEX(Detail!$G$4:$G$303,(ROW()-10)*5+4)=0,"",INDEX(Detail!$J$4:$J$303,(ROW()-10)*5+4))) -> 8 | I15: =IF($C15="","",IF(INDEX(Detail!$G$4:$G$303,(ROW()-10)*5+5)=0,"",INDEX(Detail!$J$4:$J$303,(ROW()-10)*5+5))) -> 8 | J15: =IF($C15="","",SUM($E15:$I15)) -> 40 | K15: =IF($C15="","",Config!$C$16) -> 40 | L15: =IF($C15="","",$J15-$K15) -> 0 | M15: =IF($C15="","",COUNT($E15:$I15)) -> 5 | N15: =IF($C15="","",COUNTIFS(Detail!$C$4:$C$303,$C15,Detail!$N$4:$N$303,0)) -> 5 | O15: =IF($C15="","",COUNTIFS(Detail!$C$4:$C$303,$C15,Detail!$N$4:$N$303,">0")) -> 0 | P15: =IF($C15="","",IF($M15=0,"⛔ BILLED NOTHING",IF($M15<5,"⛔ MISSING "&TEXT(5-$M15,"0")&" DAY(S) IN BTABS",IF($O15=0,"✅ PERFECT WEEK",IF($L15<0,"🔻 UNDER TARGET ("&TEXT($L15,"0.##")&" h)",IF($L15>0,"🔺 OVER TARGET (+"&TEXT($L15,"0.##")&" h)","⚠️ CHECK THE DAYS")))))) -> ✅ PERFECT WEEK | Q15: =IF($C15="","",IF($M15<5,3,IF($O15=0,0,IF($L15>0,1,2)))) -> 0 | R15: =IF($C15="","",IF($O15=0,"All 5 days closed at target. Nothing to fix.",TRIM(IF(E15="",LEFT(INDEX(Config!$F$7:$F$11,1),3)&": no entry in BTabs. ",IF(ABS(E15-$T$2)>$T$3,LEFT(INDEX(Config!$F$7:$F$11,1),3)&": "&TEXT(E15,"0.##")&" h instead of "&TEXT($T$2,"0")&" h. ",""))&IF(F15="",LEFT(INDEX(Config!$F$7:$F$11,2),3)&": no entry in BTabs. ",IF(ABS(F15-$T$2)>$T$3,LEFT(INDEX(Config!$F$7:$F$11,2),3)&": "&TEXT(F15,"0.##")&" h instead of "&TEXT($T$2,"0")&" h. ",""))&IF(G15="",LEFT(INDEX(Config!$F$7:$F$11,3),3)&": no entry in BTabs. ",IF(ABS(G15-$T$2)>$T$3,LEFT(INDEX(Config!$F$7:$F$11,3),3)&": "&TEXT(G15,"0.##")&" h instead of "&TEXT($T$2,"0")&" h. ",""))&IF(H15="",LEFT(INDEX(Config!$F$7:$F$11,4),3)&": no entry in BTabs. ",IF(ABS(H15-$T$2)>$T$3,LEFT(INDEX(Config!$F$7:$F$11,4),3)&": "&TEXT(H15,"0.##")&" h instead of "&TEXT($T$2,"0")&" h. ",""))&IF(I15="",LEFT(INDEX(Config!$F$7:$F$11,5),3)&": no entry in BTabs. ",IF(ABS(I15-$T$2)>$T$3,LEFT(INDEX(Config!$F$7:$F$11,5),3)&": "&TEXT(I15,"0.##")&" h instead of "&TEXT($T$2,"0")&" h. ",""))))) -> All 5 days closed at target. Nothing to fix.
B16: =IF($C16="","",ROW()-9) -> 7 | C16: =IF(ROW()-9>Config!$C$14,"",INDEX(BPOworkers!$B$6:$B$105,ROW()-9)) -> J Castillo | D16: =IF($C16="","",IFERROR(INDEX(BPOworkers!$E$6:$E$105,MATCH($C16,BPOworkers!$B$6:$B$105,0)),"")) -> J S Bermudez | E16: =IF($C16="","",IF(INDEX(Detail!$G$4:$G$303,(ROW()-10)*5+1)=0,"",INDEX(Detail!$J$4:$J$303,(ROW()-10)*5+1))) | F16: =IF($C16="","",IF(INDEX(Detail!$G$4:$G$303,(ROW()-10)*5+2)=0,"",INDEX(Detail!$J$4:$J$303,(ROW()-10)*5+2))) -> 8 | G16: =IF($C16="","",IF(INDEX(Detail!$G$4:$G$303,(ROW()-10)*5+3)=0,"",INDEX(Detail!$J$4:$J$303,(ROW()-10)*5+3))) -> 8 | H16: =IF($C16="","",IF(INDEX(Detail!$G$4:$G$303,(ROW()-10)*5+4)=0,"",INDEX(Detail!$J$4:$J$303,(ROW()-10)*5+4))) -> 8 | I16: =IF($C16="","",IF(INDEX(Detail!$G$4:$G$303,(ROW()-10)*5+5)=0,"",INDEX(Detail!$J$4:$J$303,(ROW()-10)*5+5))) -> 8 | J16: =IF($C16="","",SUM($E16:$I16)) -> 32 | K16: =IF($C16="","",Config!$C$16) -> 40 | L16: =IF($C16="","",$J16-$K16) -> -8 | M16: =IF($C16="","",COUNT($E16:$I16)) -> 4 | N16: =IF($C16="","",COUNTIFS(Detail!$C$4:$C$303,$C16,Detail!$N$4:$N$303,0)) -> 4 | O16: =IF($C16="","",COUNTIFS(Detail!$C$4:$C$303,$C16,Detail!$N$4:$N$303,">0")) -> 1 | P16: =IF($C16="","",IF($M16=0,"⛔ BILLED NOTHING",IF($M16<5,"⛔ MISSING "&TEXT(5-$M16,"0")&" DAY(S) IN BTABS",IF($O16=0,"✅ PERFECT WEEK",IF($L16<0,"🔻 UNDER TARGET ("&TEXT($L16,"0.##")&" h)",IF($L16>0,"🔺 OVER TARGET (+"&TEXT($L16,"0.##")&" h)","⚠️ CHECK THE DAYS")))))) -> ⛔ MISSING 1 DAY(S) IN BTABS | Q16: =IF($C16="","",IF($M16<5,3,IF($O16=0,0,IF($L16>0,1,2)))) -> 3 | R16: =IF($C16="","",IF($O16=0,"All 5 days closed at target. Nothing to fix.",TRIM(IF(E16="",LEFT(INDEX(Config!$F$7:$F$11,1),3)&": no entry in BTabs. ",IF(ABS(E16-$T$2)>$T$3,LEFT(INDEX(Config!$F$7:$F$11,1),3)&": "&TEXT(E16,"0.##")&" h instead of "&TEXT($T$2,"0")&" h. ",""))&IF(F16="",LEFT(INDEX(Config!$F$7:$F$11,2),3)&": no entry in BTabs. ",IF(ABS(F16-$T$2)>$T$3,LEFT(INDEX(Config!$F$7:$F$11,2),3)&": "&TEXT(F16,"0.##")&" h instead of "&TEXT($T$2,"0")&" h. ",""))&IF(G16="",LEFT(INDEX(Config!$F$7:$F$11,3),3)&": no entry in BTabs. ",IF(ABS(G16-$T$2)>$T$3,LEFT(INDEX(Config!$F$7:$F$11,3),3)&": "&TEXT(G16,"0.##")&" h instead of "&TEXT($T$2,"0")&" h. ",""))&IF(H16="",LEFT(INDEX(Config!$F$7:$F$11,4),3)&": no entry in BTabs. ",IF(ABS(H16-$T$2)>$T$3,LEFT(INDEX(Config!$F$7:$F$11,4),3)&": "&TEXT(H16,"0.##")&" h instead of "&TEXT($T$2,"0")&" h. ",""))&IF(I16="",LEFT(INDEX(Config!$F$7:$F$11,5),3)&": no entry in BTabs. ",IF(ABS(I16-$T$2)>$T$3,LEFT(INDEX(Config!$F$7:$F$11,5),3)&": "&TEXT(I16,"0.##")&" h instead of "&TEXT($T$2,"0")&" h. ",""))))) -> Mon: no entry in BTabs.
B17: =IF($C17="","",ROW()-9) -> 8 | C17: =IF(ROW()-9>Config!$C$14,"",INDEX(BPOworkers!$B$6:$B$105,ROW()-9)) -> J Valbuena | D17: =IF($C17="","",IFERROR(INDEX(BPOworkers!$E$6:$E$105,MATCH($C17,BPOworkers!$B$6:$B$105,0)),"")) -> H Daza | E17: =IF($C17="","",IF(INDEX(Detail!$G$4:$G$303,(ROW()-10)*5+1)=0,"",INDEX(Detail!$J$4:$J$303,(ROW()-10)*5+1))) -> 8 | F17: =IF($C17="","",IF(INDEX(Detail!$G$4:$G$303,(ROW()-10)*5+2)=0,"",INDEX(Detail!$J$4:$J$303,(ROW()-10)*5+2))) -> 8 | G17: =IF($C17="","",IF(INDEX(Detail!$G$4:$G$303,(ROW()-10)*5+3)=0,"",INDEX(Detail!$J$4:$J$303,(ROW()-10)*5+3))) -> 8 | H17: =IF($C17="","",IF(INDEX(Detail!$G$4:$G$303,(ROW()-10)*5+4)=0,"",INDEX(Detail!$J$4:$J$303,(ROW()-10)*5+4))) -> 8 | I17: =IF($C17="","",IF(INDEX(Detail!$G$4:$G$303,(ROW()-10)*5+5)=0,"",INDEX(Detail!$J$4:$J$303,(ROW()-10)*5+5))) -> 8 | J17: =IF($C17="","",SUM($E17:$I17)) -> 40 | K17: =IF($C17="","",Config!$C$16) -> 40 | L17: =IF($C17="","",$J17-$K17) -> 0 | M17: =IF($C17="","",COUNT($E17:$I17)) -> 5 | N17: =IF($C17="","",COUNTIFS(Detail!$C$4:$C$303,$C17,Detail!$N$4:$N$303,0)) -> 5 | O17: =IF($C17="","",COUNTIFS(Detail!$C$4:$C$303,$C17,Detail!$N$4:$N$303,">0")) -> 0 | P17: =IF($C17="","",IF($M17=0,"⛔ BILLED NOTHING",IF($M17<5,"⛔ MISSING "&TEXT(5-$M17,"0")&" DAY(S) IN BTABS",IF($O17=0,"✅ PERFECT WEEK",IF($L17<0,"🔻 UNDER TARGET ("&TEXT($L17,"0.##")&" h)",IF($L17>0,"🔺 OVER TARGET (+"&TEXT($L17,"0.##")&" h)","⚠️ CHECK THE DAYS")))))) -> ✅ PERFECT WEEK | Q17: =IF($C17="","",IF($M17<5,3,IF($O17=0,0,IF($L17>0,1,2)))) -> 0 | R17: =IF($C17="","",IF($O17=0,"All 5 days closed at target. Nothing to fix.",TRIM(IF(E17="",LEFT(INDEX(Config!$F$7:$F$11,1),3)&": no entry in BTabs. ",IF(ABS(E17-$T$2)>$T$3,LEFT(INDEX(Config!$F$7:$F$11,1),3)&": "&TEXT(E17,"0.##")&" h instead of "&TEXT($T$2,"0")&" h. ",""))&IF(F17="",LEFT(INDEX(Config!$F$7:$F$11,2),3)&": no entry in BTabs. ",IF(ABS(F17-$T$2)>$T$3,LEFT(INDEX(Config!$F$7:$F$11,2),3)&": "&TEXT(F17,"0.##")&" h instead of "&TEXT($T$2,"0")&" h. ",""))&IF(G17="",LEFT(INDEX(Config!$F$7:$F$11,3),3)&": no entry in BTabs. ",IF(ABS(G17-$T$2)>$T$3,LEFT(INDEX(Config!$F$7:$F$11,3),3)&": "&TEXT(G17,"0.##")&" h instead of "&TEXT($T$2,"0")&" h. ",""))&IF(H17="",LEFT(INDEX(Config!$F$7:$F$11,4),3)&": no entry in BTabs. ",IF(ABS(H17-$T$2)>$T$3,LEFT(INDEX(Config!$F$7:$F$11,4),3)&": "&TEXT(H17,"0.##")&" h instead of "&TEXT($T$2,"0")&" h. ",""))&IF(I17="",LEFT(INDEX(Config!$F$7:$F$11,5),3)&": no entry in BTabs. ",IF(ABS(I17-$T$2)>$T$3,LEFT(INDEX(Config!$F$7:$F$11,5),3)&": "&TEXT(I17,"0.##")&" h instead of "&TEXT($T$2,"0")&" h. ",""))))) -> All 5 days closed at target. Nothing to fix.
B18: =IF($C18="","",ROW()-9) -> 9 | C18: =IF(ROW()-9>Config!$C$14,"",INDEX(BPOworkers!$B$6:$B$105,ROW()-9)) -> J Gonzalez | D18: =IF($C18="","",IFERROR(INDEX(BPOworkers!$E$6:$E$105,MATCH($C18,BPOworkers!$B$6:$B$105,0)),"")) -> R Sanchez | E18: =IF($C18="","",IF(INDEX(Detail!$G$4:$G$303,(ROW()-10)*5+1)=0,"",INDEX(Detail!$J$4:$J$303,(ROW()-10)*5+1))) -> 8 | F18: =IF($C18="","",IF(INDEX(Detail!$G$4:$G$303,(ROW()-10)*5+2)=0,"",INDEX(Detail!$J$4:$J$303,(ROW()-10)*5+2))) -> 8 | G18: =IF($C18="","",IF(INDEX(Detail!$G$4:$G$303,(ROW()-10)*5+3)=0,"",INDEX(Detail!$J$4:$J$303,(ROW()-10)*5+3))) -> 8 | H18: =IF($C18="","",IF(INDEX(Detail!$G$4:$G$303,(ROW()-10)*5+4)=0,"",INDEX(Detail!$J$4:$J$303,(ROW()-10)*5+4))) -> 8 | I18: =IF($C18="","",IF(INDEX(Detail!$G$4:$G$303,(ROW()-10)*5+5)=0,"",INDEX(Detail!$J$4:$J$303,(ROW()-10)*5+5))) -> 8 | J18: =IF($C18="","",SUM($E18:$I18)) -> 40 | K18: =IF($C18="","",Config!$C$16) -> 40 | L18: =IF($C18="","",$J18-$K18) -> 0 | M18: =IF($C18="","",COUNT($E18:$I18)) -> 5 | N18: =IF($C18="","",COUNTIFS(Detail!$C$4:$C$303,$C18,Detail!$N$4:$N$303,0)) -> 5 | O18: =IF($C18="","",COUNTIFS(Detail!$C$4:$C$303,$C18,Detail!$N$4:$N$303,">0")) -> 0 | P18: =IF($C18="","",IF($M18=0,"⛔ BILLED NOTHING",IF($M18<5,"⛔ MISSING "&TEXT(5-$M18,"0")&" DAY(S) IN BTABS",IF($O18=0,"✅ PERFECT WEEK",IF($L18<0,"🔻 UNDER TARGET ("&TEXT($L18,"0.##")&" h)",IF($L18>0,"🔺 OVER TARGET (+"&TEXT($L18,"0.##")&" h)","⚠️ CHECK THE DAYS")))))) -> ✅ PERFECT WEEK | Q18: =IF($C18="","",IF($M18<5,3,IF($O18=0,0,IF($L18>0,1,2)))) -> 0 | R18: =IF($C18="","",IF($O18=0,"All 5 days closed at target. Nothing to fix.",TRIM(IF(E18="",LEFT(INDEX(Config!$F$7:$F$11,1),3)&": no entry in BTabs. ",IF(ABS(E18-$T$2)>$T$3,LEFT(INDEX(Config!$F$7:$F$11,1),3)&": "&TEXT(E18,"0.##")&" h instead of "&TEXT($T$2,"0")&" h. ",""))&IF(F18="",LEFT(INDEX(Config!$F$7:$F$11,2),3)&": no entry in BTabs. ",IF(ABS(F18-$T$2)>$T$3,LEFT(INDEX(Config!$F$7:$F$11,2),3)&": "&TEXT(F18,"0.##")&" h instead of "&TEXT($T$2,"0")&" h. ",""))&IF(G18="",LEFT(INDEX(Config!$F$7:$F$11,3),3)&": no entry in BTabs. ",IF(ABS(G18-$T$2)>$T$3,LEFT(INDEX(Config!$F$7:$F$11,3),3)&": "&TEXT(G18,"0.##")&" h instead of "&TEXT($T$2,"0")&" h. ",""))&IF(H18="",LEFT(INDEX(Config!$F$7:$F$11,4),3)&": no entry in BTabs. ",IF(ABS(H18-$T$2)>$T$3,LEFT(INDEX(Config!$F$7:$F$11,4),3)&": "&TEXT(H18,"0.##")&" h instead of "&TEXT($T$2,"0")&" h. ",""))&IF(I18="",LEFT(INDEX(Config!$F$7:$F$11,5),3)&": no entry in BTabs. ",IF(ABS(I18-$T$2)>$T$3,LEFT(INDEX(Config!$F$7:$F$11,5),3)&": "&TEXT(I18,"0.##")&" h instead of "&TEXT($T$2,"0")&" h. ",""))))) -> All 5 days closed at target. Nothing to fix.
B19: =IF($C19="","",ROW()-9) -> 10 | C19: =IF(ROW()-9>Config!$C$14,"",INDEX(BPOworkers!$B$6:$B$105,ROW()-9)) -> J Rincon | D19: =IF($C19="","",IFERROR(INDEX(BPOworkers!$E$6:$E$105,MATCH($C19,BPOworkers!$B$6:$B$105,0)),"")) -> A Camargo | E19: =IF($C19="","",IF(INDEX(Detail!$G$4:$G$303,(ROW()-10)*5+1)=0,"",INDEX(Detail!$J$4:$J$303,(ROW()-10)*5+1))) -> 8 | F19: =IF($C19="","",IF(INDEX(Detail!$G$4:$G$303,(ROW()-10)*5+2)=0,"",INDEX(Detail!$J$4:$J$303,(ROW()-10)*5+2))) -> 8 | G19: =IF($C19="","",IF(INDEX(Detail!$G$4:$G$303,(ROW()-10)*5+3)=0,"",INDEX(Detail!$J$4:$J$303,(ROW()-10)*5+3))) -> 8 | H19: =IF($C19="","",IF(INDEX(Detail!$G$4:$G$303,(ROW()-10)*5+4)=0,"",INDEX(Detail!$J$4:$J$303,(ROW()-10)*5+4))) -> 8 | I19: =IF($C19="","",IF(INDEX(Detail!$G$4:$G$303,(ROW()-10)*5+5)=0,"",INDEX(Detail!$J$4:$J$303,(ROW()-10)*5+5))) -> 8 | J19: =IF($C19="","",SUM($E19:$I19)) -> 40 | K19: =IF($C19="","",Config!$C$16) -> 40 | L19: =IF($C19="","",$J19-$K19) -> 0 | M19: =IF($C19="","",COUNT($E19:$I19)) -> 5 | N19: =IF($C19="","",COUNTIFS(Detail!$C$4:$C$303,$C19,Detail!$N$4:$N$303,0)) -> 5 | O19: =IF($C19="","",COUNTIFS(Detail!$C$4:$C$303,$C19,Detail!$N$4:$N$303,">0")) -> 0 | P19: =IF($C19="","",IF($M19=0,"⛔ BILLED NOTHING",IF($M19<5,"⛔ MISSING "&TEXT(5-$M19,"0")&" DAY(S) IN BTABS",IF($O19=0,"✅ PERFECT WEEK",IF($L19<0,"🔻 UNDER TARGET ("&TEXT($L19,"0.##")&" h)",IF($L19>0,"🔺 OVER TARGET (+"&TEXT($L19,"0.##")&" h)","⚠️ CHECK THE DAYS")))))) -> ✅ PERFECT WEEK | Q19: =IF($C19="","",IF($M19<5,3,IF($O19=0,0,IF($L19>0,1,2)))) -> 0 | R19: =IF($C19="","",IF($O19=0,"All 5 days closed at target. Nothing to fix.",TRIM(IF(E19="",LEFT(INDEX(Config!$F$7:$F$11,1),3)&": no entry in BTabs. ",IF(ABS(E19-$T$2)>$T$3,LEFT(INDEX(Config!$F$7:$F$11,1),3)&": "&TEXT(E19,"0.##")&" h instead of "&TEXT($T$2,"0")&" h. ",""))&IF(F19="",LEFT(INDEX(Config!$F$7:$F$11,2),3)&": no entry in BTabs. ",IF(ABS(F19-$T$2)>$T$3,LEFT(INDEX(Config!$F$7:$F$11,2),3)&": "&TEXT(F19,"0.##")&" h instead of "&TEXT($T$2,"0")&" h. ",""))&IF(G19="",LEFT(INDEX(Config!$F$7:$F$11,3),3)&": no entry in BTabs. ",IF(ABS(G19-$T$2)>$T$3,LEFT(INDEX(Config!$F$7:$F$11,3),3)&": "&TEXT(G19,"0.##")&" h instead of "&TEXT($T$2,"0")&" h. ",""))&IF(H19="",LEFT(INDEX(Config!$F$7:$F$11,4),3)&": no entry in BTabs. ",IF(ABS(H19-$T$2)>$T$3,LEFT(INDEX(Config!$F$7:$F$11,4),3)&": "&TEXT(H19,"0.##")&" h instead of "&TEXT($T$2,"0")&" h. ",""))&IF(I19="",LEFT(INDEX(Config!$F$7:$F$11,5),3)&": no entry in BTabs. ",IF(ABS(I19-$T$2)>$T$3,LEFT(INDEX(Config!$F$7:$F$11,5),3)&": "&TEXT(I19,"0.##")&" h instead of "&TEXT($T$2,"0")&" h. ",""))))) -> All 5 days closed at target. Nothing to fix.
B20: =IF($C20="","",ROW()-9) -> 11 | C20: =IF(ROW()-9>Config!$C$14,"",INDEX(BPOworkers!$B$6:$B$105,ROW()-9)) -> L Silva | D20: =IF($C20="","",IFERROR(INDEX(BPOworkers!$E$6:$E$105,MATCH($C20,BPOworkers!$B$6:$B$105,0)),"")) -> BPO Management | E20: =IF($C20="","",IF(INDEX(Detail!$G$4:$G$303,(ROW()-10)*5+1)=0,"",INDEX(Detail!$J$4:$J$303,(ROW()-10)*5+1))) -> 8 | F20: =IF($C20="","",IF(INDEX(Detail!$G$4:$G$303,(ROW()-10)*5+2)=0,"",INDEX(Detail!$J$4:$J$303,(ROW()-10)*5+2))) -> 8 | G20: =IF($C20="","",IF(INDEX(Detail!$G$4:$G$303,(ROW()-10)*5+3)=0,"",INDEX(Detail!$J$4:$J$303,(ROW()-10)*5+3))) -> 8 | H20: =IF($C20="","",IF(INDEX(Detail!$G$4:$G$303,(ROW()-10)*5+4)=0,"",INDEX(Detail!$J$4:$J$303,(ROW()-10)*5+4))) -> 8 | I20: =IF($C20="","",IF(INDEX(Detail!$G$4:$G$303,(ROW()-10)*5+5)=0,"",INDEX(Detail!$J$4:$J$303,(ROW()-10)*5+5))) -> 8 | J20: =IF($C20="","",SUM($E20:$I20)) -> 40 | K20: =IF($C20="","",Config!$C$16) -> 40 | L20: =IF($C20="","",$J20-$K20) -> 0 | M20: =IF($C20="","",COUNT($E20:$I20)) -> 5 | N20: =IF($C20="","",COUNTIFS(Detail!$C$4:$C$303,$C20,Detail!$N$4:$N$303,0)) -> 5 | O20: =IF($C20="","",COUNTIFS(Detail!$C$4:$C$303,$C20,Detail!$N$4:$N$303,">0")) -> 0 | P20: =IF($C20="","",IF($M20=0,"⛔ BILLED NOTHING",IF($M20<5,"⛔ MISSING "&TEXT(5-$M20,"0")&" DAY(S) IN BTABS",IF($O20=0,"✅ PERFECT WEEK",IF($L20<0,"🔻 UNDER TARGET ("&TEXT($L20,"0.##")&" h)",IF($L20>0,"🔺 OVER TARGET (+"&TEXT($L20,"0.##")&" h)","⚠️ CHECK THE DAYS")))))) -> ✅ PERFECT WEEK | Q20: =IF($C20="","",IF($M20<5,3,IF($O20=0,0,IF($L20>0,1,2)))) -> 0 | R20: =IF($C20="","",IF($O20=0,"All 5 days closed at target. Nothing to fix.",TRIM(IF(E20="",LEFT(INDEX(Config!$F$7:$F$11,1),3)&": no entry in BTabs. ",IF(ABS(E20-$T$2)>$T$3,LEFT(INDEX(Config!$F$7:$F$11,1),3)&": "&TEXT(E20,"0.##")&" h instead of "&TEXT($T$2,"0")&" h. ",""))&IF(F20="",LEFT(INDEX(Config!$F$7:$F$11,2),3)&": no entry in BTabs. ",IF(ABS(F20-$T$2)>$T$3,LEFT(INDEX(Config!$F$7:$F$11,2),3)&": "&TEXT(F20,"0.##")&" h instead of "&TEXT($T$2,"0")&" h. ",""))&IF(G20="",LEFT(INDEX(Config!$F$7:$F$11,3),3)&": no entry in BTabs. ",IF(ABS(G20-$T$2)>$T$3,LEFT(INDEX(Config!$F$7:$F$11,3),3)&": "&TEXT(G20,"0.##")&" h instead of "&TEXT($T$2,"0")&" h. ",""))&IF(H20="",LEFT(INDEX(Config!$F$7:$F$11,4),3)&": no entry in BTabs. ",IF(ABS(H20-$T$2)>$T$3,LEFT(INDEX(Config!$F$7:$F$11,4),3)&": "&TEXT(H20,"0.##")&" h instead of "&TEXT($T$2,"0")&" h. ",""))&IF(I20="",LEFT(INDEX(Config!$F$7:$F$11,5),3)&": no entry in BTabs. ",IF(ABS(I20-$T$2)>$T$3,LEFT(INDEX(Config!$F$7:$F$11,5),3)&": "&TEXT(I20,"0.##")&" h instead of "&TEXT($T$2,"0")&" h. ",""))))) -> All 5 days closed at target. Nothing to fix.
B21: =IF($C21="","",ROW()-9) -> 12 | C21: =IF(ROW()-9>Config!$C$14,"",INDEX(BPOworkers!$B$6:$B$105,ROW()-9)) -> M Grazziani | D21: =IF($C21="","",IFERROR(INDEX(BPOworkers!$E$6:$E$105,MATCH($C21,BPOworkers!$B$6:$B$105,0)),"")) -> J S Bermudez | E21: =IF($C21="","",IF(INDEX(Detail!$G$4:$G$303,(ROW()-10)*5+1)=0,"",INDEX(Detail!$J$4:$J$303,(ROW()-10)*5+1))) -> 8 | F21: =IF($C21="","",IF(INDEX(Detail!$G$4:$G$303,(ROW()-10)*5+2)=0,"",INDEX(Detail!$J$4:$J$303,(ROW()-10)*5+2))) -> 8 | G21: =IF($C21="","",IF(INDEX(Detail!$G$4:$G$303,(ROW()-10)*5+3)=0,"",INDEX(Detail!$J$4:$J$303,(ROW()-10)*5+3))) -> 8 | H21: =IF($C21="","",IF(INDEX(Detail!$G$4:$G$303,(ROW()-10)*5+4)=0,"",INDEX(Detail!$J$4:$J$303,(ROW()-10)*5+4))) -> 8 | I21: =IF($C21="","",IF(INDEX(Detail!$G$4:$G$303,(ROW()-10)*5+5)=0,"",INDEX(Detail!$J$4:$J$303,(ROW()-10)*5+5))) -> 8 | J21: =IF($C21="","",SUM($E21:$I21)) -> 40 | K21: =IF($C21="","",Config!$C$16) -> 40 | L21: =IF($C21="","",$J21-$K21) -> 0 | M21: =IF($C21="","",COUNT($E21:$I21)) -> 5 | N21: =IF($C21="","",COUNTIFS(Detail!$C$4:$C$303,$C21,Detail!$N$4:$N$303,0)) -> 5 | O21: =IF($C21="","",COUNTIFS(Detail!$C$4:$C$303,$C21,Detail!$N$4:$N$303,">0")) -> 0 | P21: =IF($C21="","",IF($M21=0,"⛔ BILLED NOTHING",IF($M21<5,"⛔ MISSING "&TEXT(5-$M21,"0")&" DAY(S) IN BTABS",IF($O21=0,"✅ PERFECT WEEK",IF($L21<0,"🔻 UNDER TARGET ("&TEXT($L21,"0.##")&" h)",IF($L21>0,"🔺 OVER TARGET (+"&TEXT($L21,"0.##")&" h)","⚠️ CHECK THE DAYS")))))) -> ✅ PERFECT WEEK | Q21: =IF($C21="","",IF($M21<5,3,IF($O21=0,0,IF($L21>0,1,2)))) -> 0 | R21: =IF($C21="","",IF($O21=0,"All 5 days closed at target. Nothing to fix.",TRIM(IF(E21="",LEFT(INDEX(Config!$F$7:$F$11,1),3)&": no entry in BTabs. ",IF(ABS(E21-$T$2)>$T$3,LEFT(INDEX(Config!$F$7:$F$11,1),3)&": "&TEXT(E21,"0.##")&" h instead of "&TEXT($T$2,"0")&" h. ",""))&IF(F21="",LEFT(INDEX(Config!$F$7:$F$11,2),3)&": no entry in BTabs. ",IF(ABS(F21-$T$2)>$T$3,LEFT(INDEX(Config!$F$7:$F$11,2),3)&": "&TEXT(F21,"0.##")&" h instead of "&TEXT($T$2,"0")&" h. ",""))&IF(G21="",LEFT(INDEX(Config!$F$7:$F$11,3),3)&": no entry in BTabs. ",IF(ABS(G21-$T$2)>$T$3,LEFT(INDEX(Config!$F$7:$F$11,3),3)&": "&TEXT(G21,"0.##")&" h instead of "&TEXT($T$2,"0")&" h. ",""))&IF(H21="",LEFT(INDEX(Config!$F$7:$F$11,4),3)&": no entry in BTabs. ",IF(ABS(H21-$T$2)>$T$3,LEFT(INDEX(Config!$F$7:$F$11,4),3)&": "&TEXT(H21,"0.##")&" h instead of "&TEXT($T$2,"0")&" h. ",""))&IF(I21="",LEFT(INDEX(Config!$F$7:$F$11,5),3)&": no entry in BTabs. ",IF(ABS(I21-$T$2)>$T$3,LEFT(INDEX(Config!$F$7:$F$11,5),3)&": "&TEXT(I21,"0.##")&" h instead of "&TEXT($T$2,"0")&" h. ",""))))) -> All 5 days closed at target. Nothing to fix.
... B69: =IF($C69="","",ROW()-9) | C69: =IF(ROW()-9>Config!$C$14,"",INDEX(BPOworkers!$B$6:$B$105,ROW()-9)) | D69: =IF($C69="","",IFERROR(INDEX(BPOworkers!$E$6:$E$105,MATCH($C69,BPOworkers!$B$6:$B$105,0)),"")) | E69: =IF($C69="","",IF(INDEX(Detail!$G$4:$G$303,(ROW()-10)*5+1)=0,"",INDEX(Detail!$J$4:$J$303,(ROW()-10)*5+1))) | F69: =IF($C69="","",IF(INDEX(Detail!$G$4:$G$303,(ROW()-10)*5+2)=0,"",INDEX(Detail!$J$4:$J$303,(ROW()-10)*5+2))) | G69: =IF($C69="","",IF(INDEX(Detail!$G$4:$G$303,(ROW()-10)*5+3)=0,"",INDEX(Detail!$J$4:$J$303,(ROW()-10)*5+3))) | H69: =IF($C69="","",IF(INDEX(Detail!$G$4:$G$303,(ROW()-10)*5+4)=0,"",INDEX(Detail!$J$4:$J$303,(ROW()-10)*5+4))) | I69: =IF($C69="","",IF(INDEX(Detail!$G$4:$G$303,(ROW()-10)*5+5)=0,"",INDEX(Detail!$J$4:$J$303,(ROW()-10)*5+5))) | J69: =IF($C69="","",SUM($E69:$I69)) | K69: =IF($C69="","",Config!$C$16) | L69: =IF($C69="","",$J69-$K69) | M69: =IF($C69="","",COUNT($E69:$I69)) | N69: =IF($C69="","",COUNTIFS(Detail!$C$4:$C$303,$C69,Detail!$N$4:$N$303,0)) | O69: =IF($C69="","",COUNTIFS(Detail!$C$4:$C$303,$C69,Detail!$N$4:$N$303,">0")) | P69: =IF($C69="","",IF($M69=0,"⛔ BILLED NOTHING",IF($M69<5,"⛔ MISSING "&TEXT(5-$M69,"0")&" DAY(S) IN BTABS",IF($O69=0,"✅ PERFECT WEEK",IF($L69<0,"🔻 UNDER TARGET ("&TEXT($L69,"0.##")&" h)",IF($L69>0,"🔺 OVER TARGET (+"&TEXT($L69,"0.##")&" h)","⚠️ CHECK THE DAYS")))))) | Q69: =IF($C69="","",IF($M69<5,3,IF($O69=0,0,IF($L69>0,1,2)))) | R69: =IF($C69="","",IF($O69=0,"All 5 days closed at target. Nothing to fix.",TRIM(IF(E69="",LEFT(INDEX(Config!$F$7:$F$11,1),3)&": no entry in BTabs. ",IF(ABS(E69-$T$2)>$T$3,LEFT(INDEX(Config!$F$7:$F$11,1),3)&": "&TEXT(E69,"0.##")&" h instead of "&TEXT($T$2,"0")&" h. ",""))&IF(F69="",LEFT(INDEX(Config!$F$7:$F$11,2),3)&": no entry in BTabs. ",IF(ABS(F69-$T$2)>$T$3,LEFT(INDEX(Config!$F$7:$F$11,2),3)&": "&TEXT(F69,"0.##")&" h instead of "&TEXT($T$2,"0")&" h. ",""))&IF(G69="",LEFT(INDEX(Config!$F$7:$F$11,3),3)&": no entry in BTabs. ",IF(ABS(G69-$T$2)>$T$3,LEFT(INDEX(Config!$F$7:$F$11,3),3)&": "&TEXT(G69,"0.##")&" h instead of "&TEXT($T$2,"0")&" h. ",""))&IF(H69="",LEFT(INDEX(Config!$F$7:$F$11,4),3)&": no entry in BTabs. ",IF(ABS(H69-$T$2)>$T$3,LEFT(INDEX(Config!$F$7:$F$11,4),3)&": "&TEXT(H69,"0.##")&" h instead of "&TEXT($T$2,"0")&" h. ",""))&IF(I69="",LEFT(INDEX(Config!$F$7:$F$11,5),3)&": no entry in BTabs. ",IF(ABS(I69-$T$2)>$T$3,LEFT(INDEX(Config!$F$7:$F$11,5),3)&": "&TEXT(I69,"0.##")&" h instead of "&TEXT($T$2,"0")&" h. ","")))))
B71: HOW TO READ THIS DASHBOARD
B72: GREEN cell | D72: The landman closed exactly the daily target (8 h = 1.0 unit).
B73: LIGHT RED cell | D73: UNDER 8 h that day: there is billing being lost.
B74: BLUE cell | D74: Over 8 h that day. Check for a duplicate entry.
B75: DARK RED cell | D75: NO entry at all in BTabs that day. This is the most serious case.

Sheet Alerts
B2: WEEKLY ALERTS - ACTION LIST
B3: Only the days with a problem. If the table comes out empty, the week closed clean.
B5: TOTAL ALERTS: | E5: =COUNTIFS(Detail!$N$4:$N$303,">0") -> 6 | F5: =IF($E$5=0,"✅ Excellent: no landman missed the target this week.","Go through each row and talk to the landman or their Team Lead.") -> Go through each row and talk to the landman or their Team Lead.
B6: # | C6: Landman | D6: Team Lead | E6: Date | F6: Day | G6: BTabs entries | H6: Billed hours | I6: Time off hours | J6: TOTAL for the day | K6: Diff. vs target | L6: What happened | M6: Sev. | N6: WHAT TO DO
B7: =IF($R7="","",ROW()-6) -> 1 | C7: =IF($R7="","",INDEX(Detail!$C$4:$C$303,$R7)) -> J Castillo | D7: =IF($R7="","",INDEX(Detail!$D$4:$D$303,$R7)) -> J S Bermudez | E7: =IF($R7="","",INDEX(Detail!$E$4:$E$303,$R7)) -> 46265 | F7: =IF($R7="","",INDEX(Detail!$F$4:$F$303,$R7)) -> Monday | G7: =IF($R7="","",INDEX(Detail!$G$4:$G$303,$R7)) -> 0 | H7: =IF($R7="","",INDEX(Detail!$H$4:$H$303,$R7)) -> 0 | I7: =IF($R7="","",INDEX(Detail!$I$4:$I$303,$R7)) -> 0 | J7: =IF($R7="","",INDEX(Detail!$J$4:$J$303,$R7)) -> 0 | K7: =IF($R7="","",INDEX(Detail!$L$4:$L$303,$R7)) -> -8 | L7: =IF($R7="","",INDEX(Detail!$M$4:$M$303,$R7)) -> ⛔ NO ENTRY IN BTABS | M7: =IF($R7="","",INDEX(Detail!$N$4:$N$303,$R7)) -> 3 | N7: =IF($C7="","",IF($G7=0,"Ask the landman to log this day in BTabs: there is no entry at all.",IF($K7<0,"Missing "&TEXT(-$K7,"0.##")&" h. Confirm whether they worked and did not bill, or whether they need to log Time Off / BPO Vacation with the hours in the detail.","Over by "&TEXT($K7,"0.##")&" h. Check for a duplicate entry or a typo."))) -> Ask the landman to log this day in BTabs: there is no entry at all. | R7: =IFERROR(MATCH(ROW()-6,Detail!$O$4:$O$303,0),"") -> 31
B8: =IF($R8="","",ROW()-6) -> 2 | C8: =IF($R8="","",INDEX(Detail!$C$4:$C$303,$R8)) -> C Castellanos | D8: =IF($R8="","",INDEX(Detail!$D$4:$D$303,$R8)) -> J S Bermudez | E8: =IF($R8="","",INDEX(Detail!$E$4:$E$303,$R8)) -> 46265 | F8: =IF($R8="","",INDEX(Detail!$F$4:$F$303,$R8)) -> Monday | G8: =IF($R8="","",INDEX(Detail!$G$4:$G$303,$R8)) -> 2 | H8: =IF($R8="","",INDEX(Detail!$H$4:$H$303,$R8)) -> 16 | I8: =IF($R8="","",INDEX(Detail!$I$4:$I$303,$R8)) -> 0 | J8: =IF($R8="","",INDEX(Detail!$J$4:$J$303,$R8)) -> 16 | K8: =IF($R8="","",INDEX(Detail!$L$4:$L$303,$R8)) -> 8 | L8: =IF($R8="","",INDEX(Detail!$M$4:$M$303,$R8)) -> 🔺 OVER BY 8. h | M8: =IF($R8="","",INDEX(Detail!$N$4:$N$303,$R8)) -> 1 | N8: =IF($C8="","",IF($G8=0,"Ask the landman to log this day in BTabs: there is no entry at all.",IF($K8<0,"Missing "&TEXT(-$K8,"0.##")&" h. Confirm whether they worked and did not bill, or whether they need to log Time Off / BPO Vacation with the hours in the detail.","Over by "&TEXT($K8,"0.##")&" h. Check for a duplicate entry or a typo."))) -> Over by 8. h. Check for a duplicate entry or a typo. | R8: =IFERROR(MATCH(ROW()-6,Detail!$O$4:$O$303,0),"") -> 76
B9: =IF($R9="","",ROW()-6) -> 3 | C9: =IF($R9="","",INDEX(Detail!$C$4:$C$303,$R9)) -> F Montañez | D9: =IF($R9="","",INDEX(Detail!$D$4:$D$303,$R9)) -> H Daza | E9: =IF($R9="","",INDEX(Detail!$E$4:$E$303,$R9)) -> 46265 | F9: =IF($R9="","",INDEX(Detail!$F$4:$F$303,$R9)) -> Monday | G9: =IF($R9="","",INDEX(Detail!$G$4:$G$303,$R9)) -> 2 | H9: =IF($R9="","",INDEX(Detail!$H$4:$H$303,$R9)) -> 16 | I9: =IF($R9="","",INDEX(Detail!$I$4:$I$303,$R9)) -> 0 | J9: =IF($R9="","",INDEX(Detail!$J$4:$J$303,$R9)) -> 16 | K9: =IF($R9="","",INDEX(Detail!$L$4:$L$303,$R9)) -> 8 | L9: =IF($R9="","",INDEX(Detail!$M$4:$M$303,$R9)) -> 🔺 OVER BY 8. h | M9: =IF($R9="","",INDEX(Detail!$N$4:$N$303,$R9)) -> 1 | N9: =IF($C9="","",IF($G9=0,"Ask the landman to log this day in BTabs: there is no entry at all.",IF($K9<0,"Missing "&TEXT(-$K9,"0.##")&" h. Confirm whether they worked and did not bill, or whether they need to log Time Off / BPO Vacation with the hours in the detail.","Over by "&TEXT($K9,"0.##")&" h. Check for a duplicate entry or a typo."))) -> Over by 8. h. Check for a duplicate entry or a typo. | R9: =IFERROR(MATCH(ROW()-6,Detail!$O$4:$O$303,0),"") -> 131
B10: =IF($R10="","",ROW()-6) -> 4 | C10: =IF($R10="","",INDEX(Detail!$C$4:$C$303,$R10)) -> N Espitia | D10: =IF($R10="","",INDEX(Detail!$D$4:$D$303,$R10)) -> A Camargo | E10: =IF($R10="","",INDEX(Detail!$E$4:$E$303,$R10)) -> 46265 | F10: =IF($R10="","",INDEX(Detail!$F$4:$F$303,$R10)) -> Monday | G10: =IF($R10="","",INDEX(Detail!$G$4:$G$303,$R10)) -> 2 | H10: =IF($R10="","",INDEX(Detail!$H$4:$H$303,$R10)) -> 12 | I10: =IF($R10="","",INDEX(Detail!$I$4:$I$303,$R10)) -> 0 | J10: =IF($R10="","",INDEX(Detail!$J$4:$J$303,$R10)) -> 12 | K10: =IF($R10="","",INDEX(Detail!$L$4:$L$303,$R10)) -> 4 | L10: =IF($R10="","",INDEX(Detail!$M$4:$M$303,$R10)) -> 🔺 OVER BY 4. h | M10: =IF($R10="","",INDEX(Detail!$N$4:$N$303,$R10)) -> 1 | N10: =IF($C10="","",IF($G10=0,"Ask the landman to log this day in BTabs: there is no entry at all.",IF($K10<0,"Missing "&TEXT(-$K10,"0.##")&" h. Confirm whether they worked and did not bill, or whether they need to log Time Off / BPO Vacation with the hours in the detail.","Over by "&TEXT($K10,"0.##")&" h. Check for a duplicate entry or a typo."))) -> Over by 4. h. Check for a duplicate entry or a typo. | R10: =IFERROR(MATCH(ROW()-6,Detail!$O$4:$O$303,0),"") -> 146
B11: =IF($R11="","",ROW()-6) -> 5 | C11: =IF($R11="","",INDEX(Detail!$C$4:$C$303,$R11)) -> N Espitia | D11: =IF($R11="","",INDEX(Detail!$D$4:$D$303,$R11)) -> A Camargo | E11: =IF($R11="","",INDEX(Detail!$E$4:$E$303,$R11)) -> 46266 | F11: =IF($R11="","",INDEX(Detail!$F$4:$F$303,$R11)) -> Tuesday | G11: =IF($R11="","",INDEX(Detail!$G$4:$G$303,$R11)) -> 3 | H11: =IF($R11="","",INDEX(Detail!$H$4:$H$303,$R11)) -> 12 | I11: =IF($R11="","",INDEX(Detail!$I$4:$I$303,$R11)) -> 0 | J11: =IF($R11="","",INDEX(Detail!$J$4:$J$303,$R11)) -> 12 | K11: =IF($R11="","",INDEX(Detail!$L$4:$L$303,$R11)) -> 4 | L11: =IF($R11="","",INDEX(Detail!$M$4:$M$303,$R11)) -> 🔺 OVER BY 4. h | M11: =IF($R11="","",INDEX(Detail!$N$4:$N$303,$R11)) -> 1 | N11: =IF($C11="","",IF($G11=0,"Ask the landman to log this day in BTabs: there is no entry at all.",IF($K11<0,"Missing "&TEXT(-$K11,"0.##")&" h. Confirm whether they worked and did not bill, or whether they need to log Time Off / BPO Vacation with the hours in the detail.","Over by "&TEXT($K11,"0.##")&" h. Check for a duplicate entry or a typo."))) -> Over by 4. h. Check for a duplicate entry or a typo. | R11: =IFERROR(MATCH(ROW()-6,Detail!$O$4:$O$303,0),"") -> 147
B12: =IF($R12="","",ROW()-6) -> 6 | C12: =IF($R12="","",INDEX(Detail!$C$4:$C$303,$R12)) -> K Martínez | D12: =IF($R12="","",INDEX(Detail!$D$4:$D$303,$R12)) -> A Camargo | E12: =IF($R12="","",INDEX(Detail!$E$4:$E$303,$R12)) -> 46265 | F12: =IF($R12="","",INDEX(Detail!$F$4:$F$303,$R12)) -> Monday | G12: =IF($R12="","",INDEX(Detail!$G$4:$G$303,$R12)) -> 0 | H12: =IF($R12="","",INDEX(Detail!$H$4:$H$303,$R12)) -> 0 | I12: =IF($R12="","",INDEX(Detail!$I$4:$I$303,$R12)) -> 0 | J12: =IF($R12="","",INDEX(Detail!$J$4:$J$303,$R12)) -> 0 | K12: =IF($R12="","",INDEX(Detail!$L$4:$L$303,$R12)) -> -8 | L12: =IF($R12="","",INDEX(Detail!$M$4:$M$303,$R12)) -> ⛔ NO ENTRY IN BTABS | M12: =IF($R12="","",INDEX(Detail!$N$4:$N$303,$R12)) -> 3 | N12: =IF($C12="","",IF($G12=0,"Ask the landman to log this day in BTabs: there is no entry at all.",IF($K12<0,"Missing "&TEXT(-$K12,"0.##")&" h. Confirm whether they worked and did not bill, or whether they need to log Time Off / BPO Vacation with the hours in the detail.","Over by "&TEXT($K12,"0.##")&" h. Check for a duplicate entry or a typo."))) -> Ask the landman to log this day in BTabs: there is no entry at all. | R12: =IFERROR(MATCH(ROW()-6,Detail!$O$4:$O$303,0),"") -> 161
B13: =IF($R13="","",ROW()-6) | C13: =IF($R13="","",INDEX(Detail!$C$4:$C$303,$R13)) | D13: =IF($R13="","",INDEX(Detail!$D$4:$D$303,$R13)) | E13: =IF($R13="","",INDEX(Detail!$E$4:$E$303,$R13)) | F13: =IF($R13="","",INDEX(Detail!$F$4:$F$303,$R13)) | G13: =IF($R13="","",INDEX(Detail!$G$4:$G$303,$R13)) | H13: =IF($R13="","",INDEX(Detail!$H$4:$H$303,$R13)) | I13: =IF($R13="","",INDEX(Detail!$I$4:$I$303,$R13)) | J13: =IF($R13="","",INDEX(Detail!$J$4:$J$303,$R13)) | K13: =IF($R13="","",INDEX(Detail!$L$4:$L$303,$R13)) | L13: =IF($R13="","",INDEX(Detail!$M$4:$M$303,$R13)) | M13: =IF($R13="","",INDEX(Detail!$N$4:$N$303,$R13)) | N13: =IF($C13="","",IF($G13=0,"Ask the landman to log this day in BTabs: there is no entry at all.",IF($K13<0,"Missing "&TEXT(-$K13,"0.##")&" h. Confirm whether they worked and did not bill, or whether they need to log Time Off / BPO Vacation with the hours in the detail.","Over by "&TEXT($K13,"0.##")&" h. Check for a duplicate entry or a typo."))) | R13: =IFERROR(MATCH(ROW()-6,Detail!$O$4:$O$303,0),"")
B14: =IF($R14="","",ROW()-6) | C14: =IF($R14="","",INDEX(Detail!$C$4:$C$303,$R14)) | D14: =IF($R14="","",INDEX(Detail!$D$4:$D$303,$R14)) | E14: =IF($R14="","",INDEX(Detail!$E$4:$E$303,$R14)) | F14: =IF($R14="","",INDEX(Detail!$F$4:$F$303,$R14)) | G14: =IF($R14="","",INDEX(Detail!$G$4:$G$303,$R14)) | H14: =IF($R14="","",INDEX(Detail!$H$4:$H$303,$R14)) | I14: =IF($R14="","",INDEX(Detail!$I$4:$I$303,$R14)) | J14: =IF($R14="","",INDEX(Detail!$J$4:$J$303,$R14)) | K14: =IF($R14="","",INDEX(Detail!$L$4:$L$303,$R14)) | L14: =IF($R14="","",INDEX(Detail!$M$4:$M$303,$R14)) | M14: =IF($R14="","",INDEX(Detail!$N$4:$N$303,$R14)) | N14: =IF($C14="","",IF($G14=0,"Ask the landman to log this day in BTabs: there is no entry at all.",IF($K14<0,"Missing "&TEXT(-$K14,"0.##")&" h. Confirm whether they worked and did not bill, or whether they need to log Time Off / BPO Vacation with the hours in the detail.","Over by "&TEXT($K14,"0.##")&" h. Check for a duplicate entry or a typo."))) | R14: =IFERROR(MATCH(ROW()-6,Detail!$O$4:$O$303,0),"")
B15: =IF($R15="","",ROW()-6) | C15: =IF($R15="","",INDEX(Detail!$C$4:$C$303,$R15)) | D15: =IF($R15="","",INDEX(Detail!$D$4:$D$303,$R15)) | E15: =IF($R15="","",INDEX(Detail!$E$4:$E$303,$R15)) | F15: =IF($R15="","",INDEX(Detail!$F$4:$F$303,$R15)) | G15: =IF($R15="","",INDEX(Detail!$G$4:$G$303,$R15)) | H15: =IF($R15="","",INDEX(Detail!$H$4:$H$303,$R15)) | I15: =IF($R15="","",INDEX(Detail!$I$4:$I$303,$R15)) | J15: =IF($R15="","",INDEX(Detail!$J$4:$J$303,$R15)) | K15: =IF($R15="","",INDEX(Detail!$L$4:$L$303,$R15)) | L15: =IF($R15="","",INDEX(Detail!$M$4:$M$303,$R15)) | M15: =IF($R15="","",INDEX(Detail!$N$4:$N$303,$R15)) | N15: =IF($C15="","",IF($G15=0,"Ask the landman to log this day in BTabs: there is no entry at all.",IF($K15<0,"Missing "&TEXT(-$K15,"0.##")&" h. Confirm whether they worked and did not bill, or whether they need to log Time Off / BPO Vacation with the hours in the detail.","Over by "&TEXT($K15,"0.##")&" h. Check for a duplicate entry or a typo."))) | R15: =IFERROR(MATCH(ROW()-6,Detail!$O$4:$O$303,0),"")
B16: =IF($R16="","",ROW()-6) | C16: =IF($R16="","",INDEX(Detail!$C$4:$C$303,$R16)) | D16: =IF($R16="","",INDEX(Detail!$D$4:$D$303,$R16)) | E16: =IF($R16="","",INDEX(Detail!$E$4:$E$303,$R16)) | F16: =IF($R16="","",INDEX(Detail!$F$4:$F$303,$R16)) | G16: =IF($R16="","",INDEX(Detail!$G$4:$G$303,$R16)) | H16: =IF($R16="","",INDEX(Detail!$H$4:$H$303,$R16)) | I16: =IF($R16="","",INDEX(Detail!$I$4:$I$303,$R16)) | J16: =IF($R16="","",INDEX(Detail!$J$4:$J$303,$R16)) | K16: =IF($R16="","",INDEX(Detail!$L$4:$L$303,$R16)) | L16: =IF($R16="","",INDEX(Detail!$M$4:$M$303,$R16)) | M16: =IF($R16="","",INDEX(Detail!$N$4:$N$303,$R16)) | N16: =IF($C16="","",IF($G16=0,"Ask the landman to log this day in BTabs: there is no entry at all.",IF($K16<0,"Missing "&TEXT(-$K16,"0.##")&" h. Confirm whether they worked and did not bill, or whether they need to log Time Off / BPO Vacation with the hours in the detail.","Over by "&TEXT($K16,"0.##")&" h. Check for a duplicate entry or a typo."))) | R16: =IFERROR(MATCH(ROW()-6,Detail!$O$4:$O$303,0),"")
B17: =IF($R17="","",ROW()-6) | C17: =IF($R17="","",INDEX(Detail!$C$4:$C$303,$R17)) | D17: =IF($R17="","",INDEX(Detail!$D$4:$D$303,$R17)) | E17: =IF($R17="","",INDEX(Detail!$E$4:$E$303,$R17)) | F17: =IF($R17="","",INDEX(Detail!$F$4:$F$303,$R17)) | G17: =IF($R17="","",INDEX(Detail!$G$4:$G$303,$R17)) | H17: =IF($R17="","",INDEX(Detail!$H$4:$H$303,$R17)) | I17: =IF($R17="","",INDEX(Detail!$I$4:$I$303,$R17)) | J17: =IF($R17="","",INDEX(Detail!$J$4:$J$303,$R17)) | K17: =IF($R17="","",INDEX(Detail!$L$4:$L$303,$R17)) | L17: =IF($R17="","",INDEX(Detail!$M$4:$M$303,$R17)) | M17: =IF($R17="","",INDEX(Detail!$N$4:$N$303,$R17)) | N17: =IF($C17="","",IF($G17=0,"Ask the landman to log this day in BTabs: there is no entry at all.",IF($K17<0,"Missing "&TEXT(-$K17,"0.##")&" h. Confirm whether they worked and did not bill, or whether they need to log Time Off / BPO Vacation with the hours in the detail.","Over by "&TEXT($K17,"0.##")&" h. Check for a duplicate entry or a typo."))) | R17: =IFERROR(MATCH(ROW()-6,Detail!$O$4:$O$303,0),"")
B18: =IF($R18="","",ROW()-6) | C18: =IF($R18="","",INDEX(Detail!$C$4:$C$303,$R18)) | D18: =IF($R18="","",INDEX(Detail!$D$4:$D$303,$R18)) | E18: =IF($R18="","",INDEX(Detail!$E$4:$E$303,$R18)) | F18: =IF($R18="","",INDEX(Detail!$F$4:$F$303,$R18)) | G18: =IF($R18="","",INDEX(Detail!$G$4:$G$303,$R18)) | H18: =IF($R18="","",INDEX(Detail!$H$4:$H$303,$R18)) | I18: =IF($R18="","",INDEX(Detail!$I$4:$I$303,$R18)) | J18: =IF($R18="","",INDEX(Detail!$J$4:$J$303,$R18)) | K18: =IF($R18="","",INDEX(Detail!$L$4:$L$303,$R18)) | L18: =IF($R18="","",INDEX(Detail!$M$4:$M$303,$R18)) | M18: =IF($R18="","",INDEX(Detail!$N$4:$N$303,$R18)) | N18: =IF($C18="","",IF($G18=0,"Ask the landman to log this day in BTabs: there is no entry at all.",IF($K18<0,"Missing "&TEXT(-$K18,"0.##")&" h. Confirm whether they worked and did not bill, or whether they need to log Time Off / BPO Vacation with the hours in the detail.","Over by "&TEXT($K18,"0.##")&" h. Check for a duplicate entry or a typo."))) | R18: =IFERROR(MATCH(ROW()-6,Detail!$O$4:$O$303,0),"")
... B96: =IF($R96="","",ROW()-6) | C96: =IF($R96="","",INDEX(Detail!$C$4:$C$303,$R96)) | D96: =IF($R96="","",INDEX(Detail!$D$4:$D$303,$R96)) | E96: =IF($R96="","",INDEX(Detail!$E$4:$E$303,$R96)) | F96: =IF($R96="","",INDEX(Detail!$F$4:$F$303,$R96)) | G96: =IF($R96="","",INDEX(Detail!$G$4:$G$303,$R96)) | H96: =IF($R96="","",INDEX(Detail!$H$4:$H$303,$R96)) | I96: =IF($R96="","",INDEX(Detail!$I$4:$I$303,$R96)) | J96: =IF($R96="","",INDEX(Detail!$J$4:$J$303,$R96)) | K96: =IF($R96="","",INDEX(Detail!$L$4:$L$303,$R96)) | L96: =IF($R96="","",INDEX(Detail!$M$4:$M$303,$R96)) | M96: =IF($R96="","",INDEX(Detail!$N$4:$N$303,$R96)) | N96: =IF($C96="","",IF($G96=0,"Ask the landman to log this day in BTabs: there is no entry at all.",IF($K96<0,"Missing "&TEXT(-$K96,"0.##")&" h. Confirm whether they worked and did not bill, or whether they need to log Time Off / BPO Vacation with the hours in the detail.","Over by "&TEXT($K96,"0.##")&" h. Check for a duplicate entry or a typo."))) | R96: =IFERROR(MATCH(ROW()-6,Detail!$O$4:$O$303,0),"")

Sheet TimeOff
B2: WEEKLY TIME OFF (Time Off / Vacation / Medical Leave) | S2: =Config!$C$9 -> 8
B3: People who logged in BTabs but did NOT work billable hours. Here we validate that the day still closes at 8 h. | S3: =Config!$C$10 -> 0
B5: TIME OFF HOURS | D5: TIME OFF ENTRIES | F5: TIME OFF (entries) | H5: BPO VACATION (entries) | J5: HOLIDAY (entries) | L5: NO HOURS IN THE DETAIL
B6: =SUMPRODUCT(RawBtabs!$U$2:$U$1500,RawBtabs!$W$2:$W$1500,RawBtabs!$S$2:$S$1500) -> 159 | D6: =SUMPRODUCT(RawBtabs!$X$2:$X$1500,RawBtabs!$W$2:$W$1500,RawBtabs!$S$2:$S$1500) -> 24 | F6: =SUMPRODUCT(--(RawBtabs!$H$2:$H$1500=Config!$C$21),RawBtabs!$W$2:$W$1500,RawBtabs!$S$2:$S$1500) -> 14 | H6: =SUMPRODUCT(--(RawBtabs!$H$2:$H$1500=Config!$C$22),RawBtabs!$W$2:$W$1500,RawBtabs!$S$2:$S$1500) -> 10 | J6: =SUMPRODUCT(--(RawBtabs!$H$2:$H$1500=Config!$C$23),RawBtabs!$W$2:$W$1500,RawBtabs!$S$2:$S$1500) -> 0 | L6: =SUMPRODUCT(RawBtabs!$X$2:$X$1500,RawBtabs!$W$2:$W$1500,RawBtabs!$S$2:$S$1500,--(RawBtabs!$U$2:$U$1500=0)) -> 0
B8: # | C8: Landman | D8: Team Lead | E8: Date | F8: Day | G8: Time off type | H8: BTabs status | I8: Hours declared | J8: Billed units | K8: TOTAL for the day | L8: DAY VALIDATION | M8: Detail written in BTabs
B9: =IF($R9="","",ROW()-8) -> 1 | C9: =IF($R9="","",INDEX(RawBtabs!$A$2:$A$1500,$R9)) -> J Castillo | D9: =IF($C9="","",IFERROR(INDEX(BPOworkers!$E$6:$E$105,MATCH($C9,BPOworkers!$B$6:$B$105,0)),"")) -> J S Bermudez | E9: =IF($R9="","",INDEX(RawBtabs!$C$2:$C$1500,$R9)) -> 46269 | F9: =IF($C9="","",IFERROR(INDEX(Config!$F$7:$F$11,$E9-Config!$C$7+1),"")) -> Friday | G9: =IF($R9="","",INDEX(RawBtabs!$H$2:$H$1500,$R9)) -> Time Off | H9: =IF($R9="","",INDEX(RawBtabs!$B$2:$B$1500,$R9)) -> Approved | I9: =IF($R9="","",INDEX(RawBtabs!$U$2:$U$1500,$R9)) -> 8 | J9: =IF($R9="","",INDEX(RawBtabs!$K$2:$K$1500,$R9)) -> 0 | K9: =IF($C9="","",SUMIFS(RawBtabs!$V$2:$V$1500,RawBtabs!$A$2:$A$1500,$C9,RawBtabs!$C$2:$C$1500,$E9)) -> 8 | L9: =IF($C9="","",IF($I9=0,"⚠️ The detail does not state the hours",IF(ABS($K9-Config!$C$9)<=Config!$C$10,"✅ Full day ("&TEXT($K9,"0.##")&" h)",IF($K9<Config!$C$9,"🔻 Incomplete day: "&TEXT($K9,"0.##")&" h of "&TEXT(Config!$C$9,"0")&" h","🔺 Day exceeded: "&TEXT($K9,"0.##")&" h")))) -> ✅ Full day (8. h) | M9: =IF($R9="","",INDEX(RawBtabs!$Q$2:$Q$1500,$R9)) -> 8 hours not worked medical leave. 8 Hours not billed | R9: =IFERROR(MATCH(ROW()-8,RawBtabs!$Z$2:$Z$1500,0),"") -> 167
B10: =IF($R10="","",ROW()-8) -> 2 | C10: =IF($R10="","",INDEX(RawBtabs!$A$2:$A$1500,$R10)) -> A Lopez | D10: =IF($C10="","",IFERROR(INDEX(BPOworkers!$E$6:$E$105,MATCH($C10,BPOworkers!$B$6:$B$105,0)),"")) -> S Romero | E10: =IF($R10="","",INDEX(RawBtabs!$C$2:$C$1500,$R10)) -> 46269 | F10: =IF($C10="","",IFERROR(INDEX(Config!$F$7:$F$11,$E10-Config!$C$7+1),"")) -> Friday | G10: =IF($R10="","",INDEX(RawBtabs!$H$2:$H$1500,$R10)) -> Time Off | H10: =IF($R10="","",INDEX(RawBtabs!$B$2:$B$1500,$R10)) -> Approved | I10: =IF($R10="","",INDEX(RawBtabs!$U$2:$U$1500,$R10)) -> 2 | J10: =IF($R10="","",INDEX(RawBtabs!$K$2:$K$1500,$R10)) -> 0 | K10: =IF($C10="","",SUMIFS(RawBtabs!$V$2:$V$1500,RawBtabs!$A$2:$A$1500,$C10,RawBtabs!$C$2:$C$1500,$E10)) -> 8 | L10: =IF($C10="","",IF($I10=0,"⚠️ The detail does not state the hours",IF(ABS($K10-Config!$C$9)<=Config!$C$10,"✅ Full day ("&TEXT($K10,"0.##")&" h)",IF($K10<Config!$C$9,"🔻 Incomplete day: "&TEXT($K10,"0.##")&" h of "&TEXT(Config!$C$9,"0")&" h","🔺 Day exceeded: "&TEXT($K10,"0.##")&" h")))) -> ✅ Full day (8. h) | M10: =IF($R10="","",INDEX(RawBtabs!$Q$2:$Q$1500,$R10)) -> 2 hours | R10: =IFERROR(MATCH(ROW()-8,RawBtabs!$Z$2:$Z$1500,0),"") -> 177
B11: =IF($R11="","",ROW()-8) -> 3 | C11: =IF($R11="","",INDEX(RawBtabs!$A$2:$A$1500,$R11)) -> C Mesa | D11: =IF($C11="","",IFERROR(INDEX(BPOworkers!$E$6:$E$105,MATCH($C11,BPOworkers!$B$6:$B$105,0)),"")) -> M Leon | E11: =IF($R11="","",INDEX(RawBtabs!$C$2:$C$1500,$R11)) -> 46269 | F11: =IF($C11="","",IFERROR(INDEX(Config!$F$7:$F$11,$E11-Config!$C$7+1),"")) -> Friday | G11: =IF($R11="","",INDEX(RawBtabs!$H$2:$H$1500,$R11)) -> BPO Vacation | H11: =IF($R11="","",INDEX(RawBtabs!$B$2:$B$1500,$R11)) -> Approved | I11: =IF($R11="","",INDEX(RawBtabs!$U$2:$U$1500,$R11)) -> 8 | J11: =IF($R11="","",INDEX(RawBtabs!$K$2:$K$1500,$R11)) -> 0 | K11: =IF($C11="","",SUMIFS(RawBtabs!$V$2:$V$1500,RawBtabs!$A$2:$A$1500,$C11,RawBtabs!$C$2:$C$1500,$E11)) -> 8 | L11: =IF($C11="","",IF($I11=0,"⚠️ The detail does not state the hours",IF(ABS($K11-Config!$C$9)<=Config!$C$10,"✅ Full day ("&TEXT($K11,"0.##")&" h)",IF($K11<Config!$C$9,"🔻 Incomplete day: "&TEXT($K11,"0.##")&" h of "&TEXT(Config!$C$9,"0")&" h","🔺 Day exceeded: "&TEXT($K11,"0.##")&" h")))) -> ✅ Full day (8. h) | M11: =IF($R11="","",INDEX(RawBtabs!$Q$2:$Q$1500,$R11)) -> 8 hours of paid vacations | R11: =IFERROR(MATCH(ROW()-8,RawBtabs!$Z$2:$Z$1500,0),"") -> 181
B12: =IF($R12="","",ROW()-8) -> 4 | C12: =IF($R12="","",INDEX(RawBtabs!$A$2:$A$1500,$R12)) -> O Moreno | D12: =IF($C12="","",IFERROR(INDEX(BPOworkers!$E$6:$E$105,MATCH($C12,BPOworkers!$B$6:$B$105,0)),"")) -> R Sanchez | E12: =IF($R12="","",INDEX(RawBtabs!$C$2:$C$1500,$R12)) -> 46269 | F12: =IF($C12="","",IFERROR(INDEX(Config!$F$7:$F$11,$E12-Config!$C$7+1),"")) -> Friday | G12: =IF($R12="","",INDEX(RawBtabs!$H$2:$H$1500,$R12)) -> Time Off | H12: =IF($R12="","",INDEX(RawBtabs!$B$2:$B$1500,$R12)) -> Approved | I12: =IF($R12="","",INDEX(RawBtabs!$U$2:$U$1500,$R12)) -> 8 | J12: =IF($R12="","",INDEX(RawBtabs!$K$2:$K$1500,$R12)) -> 0 | K12: =IF($C12="","",SUMIFS(RawBtabs!$V$2:$V$1500,RawBtabs!$A$2:$A$1500,$C12,RawBtabs!$C$2:$C$1500,$E12)) -> 8 | L12: =IF($C12="","",IF($I12=0,"⚠️ The detail does not state the hours",IF(ABS($K12-Config!$C$9)<=Config!$C$10,"✅ Full day ("&TEXT($K12,"0.##")&" h)",IF($K12<Config!$C$9,"🔻 Incomplete day: "&TEXT($K12,"0.##")&" h of "&TEXT(Config!$C$9,"0")&" h","🔺 Day exceeded: "&TEXT($K12,"0.##")&" h")))) -> ✅ Full day (8. h) | M12: =IF($R12="","",INDEX(RawBtabs!$Q$2:$Q$1500,$R12)) -> 8 hours nor billed for medical leave. | R12: =IFERROR(MATCH(ROW()-8,RawBtabs!$Z$2:$Z$1500,0),"") -> 214
