Workbook

Sheet Roster
A1: ROSTER — PROJECT 1
C2: ← Name corto como aparece facturado en BTBS. Autogenerado; corrige a mano si no coincide.
A3: Full name | B3: Email | C3: BTBS name | D3: Active
A4: Laura Silva | B4: lsilva@tractsbpo.com | C4: =IF($A4="","",LEFT($A4,1)&" "&TRIM(RIGHT(SUBSTITUTE($A4," ",REPT(" ",50)),50))) -> L Silva | D4: Yes
A5: Leonidas Villamil | B5: lvillamil@tractsbpo.com | C5: =IF($A5="","",LEFT($A5,1)&" "&TRIM(RIGHT(SUBSTITUTE($A5," ",REPT(" ",50)),50))) -> L Villamil | D5: Yes
A6: Sebastian Romero | B6: sromero@tractsbpo.com | C6: =IF($A6="","",LEFT($A6,1)&" "&TRIM(RIGHT(SUBSTITUTE($A6," ",REPT(" ",50)),50))) -> S Romero | D6: Yes
A7: Hugo Daza | B7: hdaza@tractsbpo.com | C7: =IF($A7="","",LEFT($A7,1)&" "&TRIM(RIGHT(SUBSTITUTE($A7," ",REPT(" ",50)),50))) -> H Daza | D7: Yes
A8: Roberto Sanchez | B8: rsanchez@tractsbpo.com | C8: =IF($A8="","",LEFT($A8,1)&" "&TRIM(RIGHT(SUBSTITUTE($A8," ",REPT(" ",50)),50))) -> R Sanchez | D8: Yes
A9: Alejandra Lorenzo | B9: alorenzo@tractsbpo.com | C9: =IF($A9="","",LEFT($A9,1)&" "&TRIM(RIGHT(SUBSTITUTE($A9," ",REPT(" ",50)),50))) -> A Lorenzo | D9: Yes
A10: Andrea Camargo | B10: acamargo@tractsbpo.com | C10: =IF($A10="","",LEFT($A10,1)&" "&TRIM(RIGHT(SUBSTITUTE($A10," ",REPT(" ",50)),50))) -> A Camargo | D10: Yes
A11: Maria Camila Leon | B11: mcleon@tractsbpo.com | C11: =IF($A11="","",LEFT($A11,1)&" "&TRIM(RIGHT(SUBSTITUTE($A11," ",REPT(" ",50)),50))) -> M Leon | D11: Yes
A12: Juan David Castillo | B12: jdcastillo@tractsbpo.com | C12: =IF($A12="","",LEFT($A12,1)&" "&TRIM(RIGHT(SUBSTITUTE($A12," ",REPT(" ",50)),50))) -> J Castillo | D12: Yes
A13: Jeronimo Rincon | B13: jrincon@tractsbpo.com | C13: =IF($A13="","",LEFT($A13,1)&" "&TRIM(RIGHT(SUBSTITUTE($A13," ",REPT(" ",50)),50))) -> J Rincon | D13: Yes
A14: Jose David Valbuena | B14: jdvalbuena@tractsbpo.com | C14: =IF($A14="","",LEFT($A14,1)&" "&TRIM(RIGHT(SUBSTITUTE($A14," ",REPT(" ",50)),50))) -> J Valbuena | D14: Yes
A15: Angie Lopez | B15: alopez@tractsbpo.com | C15: =IF($A15="","",LEFT($A15,1)&" "&TRIM(RIGHT(SUBSTITUTE($A15," ",REPT(" ",50)),50))) -> A Lopez | D15: Yes
... A43: Sara Calderon | B43: scalderon@tractsbpo.com | C43: =IF($A43="","",LEFT($A43,1)&" "&TRIM(RIGHT(SUBSTITUTE($A43," ",REPT(" ",50)),50))) -> S Calderon | D43: Yes

Sheet Proposed Hours
A1: PROPOSED HOURS — Overtime declared by each person
A2: Each person writes their overtime per day on the row with their name. Thes fechas salen solas del periodo.
A3: From: | B3: 46253 | C3: To: | D3: 46264 | F3: ← Week loaded from 'Tentative Extra Hours' (Aug 19-23). Days align themselves with the headers.
F4: =IF($D$3<$B$3,"⚠ 'To' is earlier than 'From'",IF($D$3-$B$3>13,"⚠ The period exceeds 14 days: only the first 14 are validated",""))
A5: Name | B5: =IF($B$3="","",$B$3) -> 46253 | C5: =IF(OR(B5="",B5>=$D$3),"",B5+1) -> 46254 | D5: =IF(OR(C5="",C5>=$D$3),"",C5+1) -> 46255 | E5: =IF(OR(D5="",D5>=$D$3),"",D5+1) -> 46256 | F5: =IF(OR(E5="",E5>=$D$3),"",E5+1) -> 46257 | G5: =IF(OR(F5="",F5>=$D$3),"",F5+1) -> 46258 | H5: =IF(OR(G5="",G5>=$D$3),"",G5+1) -> 46259 | I5: =IF(OR(H5="",H5>=$D$3),"",H5+1) -> 46260 | J5: =IF(OR(I5="",I5>=$D$3),"",I5+1) -> 46261 | ... O5: =IF(OR(N5="",N5>=$D$3),"",N5+1) | P5: Total (h) | Q5: Warning
A6: =IF(Roster!A4="","",Roster!A4) -> Laura Silva | B6: 0 | C6: 0 | D6: 0 | E6: 0 | F6: 0 | P6: =IF($A6="","",SUMIF($B$5:$O$5,">0",B6:O6)) -> 0 | Q6: =IF($A6="","",IF(SUM(B6:O6)<>P6,"⚠ There are horas en columnas fuera del periodo",IF(COUNTIF(B6:O6,"<0")>0,"⚠ Negative values",IF(COUNTIF(B6:O6,">24")>0,"⚠ More than 24 h in one day",""))))
A7: =IF(Roster!A5="","",Roster!A5) -> Leonidas Villamil | P7: =IF($A7="","",SUMIF($B$5:$O$5,">0",B7:O7)) -> 0 | Q7: =IF($A7="","",IF(SUM(B7:O7)<>P7,"⚠ There are horas en columnas fuera del periodo",IF(COUNTIF(B7:O7,"<0")>0,"⚠ Negative values",IF(COUNTIF(B7:O7,">24")>0,"⚠ More than 24 h in one day",""))))
A8: =IF(Roster!A6="","",Roster!A6) -> Sebastian Romero | P8: =IF($A8="","",SUMIF($B$5:$O$5,">0",B8:O8)) -> 0 | Q8: =IF($A8="","",IF(SUM(B8:O8)<>P8,"⚠ There are horas en columnas fuera del periodo",IF(COUNTIF(B8:O8,"<0")>0,"⚠ Negative values",IF(COUNTIF(B8:O8,">24")>0,"⚠ More than 24 h in one day",""))))
A9: =IF(Roster!A7="","",Roster!A7) -> Hugo Daza | P9: =IF($A9="","",SUMIF($B$5:$O$5,">0",B9:O9)) -> 0 | Q9: =IF($A9="","",IF(SUM(B9:O9)<>P9,"⚠ There are horas en columnas fuera del periodo",IF(COUNTIF(B9:O9,"<0")>0,"⚠ Negative values",IF(COUNTIF(B9:O9,">24")>0,"⚠ More than 24 h in one day",""))))
A10: =IF(Roster!A8="","",Roster!A8) -> Roberto Sanchez | P10: =IF($A10="","",SUMIF($B$5:$O$5,">0",B10:O10)) -> 0 | Q10: =IF($A10="","",IF(SUM(B10:O10)<>P10,"⚠ There are horas en columnas fuera del periodo",IF(COUNTIF(B10:O10,"<0")>0,"⚠ Negative values",IF(COUNTIF(B10:O10,">24")>0,"⚠ More than 24 h in one day",""))))
A11: =IF(Roster!A9="","",Roster!A9) -> Alejandra Lorenzo | P11: =IF($A11="","",SUMIF($B$5:$O$5,">0",B11:O11)) -> 0 | Q11: =IF($A11="","",IF(SUM(B11:O11)<>P11,"⚠ There are horas en columnas fuera del periodo",IF(COUNTIF(B11:O11,"<0")>0,"⚠ Negative values",IF(COUNTIF(B11:O11,">24")>0,"⚠ More than 24 h in one day",""))))
A12: =IF(Roster!A10="","",Roster!A10) -> Andrea Camargo | P12: =IF($A12="","",SUMIF($B$5:$O$5,">0",B12:O12)) -> 0 | Q12: =IF($A12="","",IF(SUM(B12:O12)<>P12,"⚠ There are horas en columnas fuera del periodo",IF(COUNTIF(B12:O12,"<0")>0,"⚠ Negative values",IF(COUNTIF(B12:O12,">24")>0,"⚠ More than 24 h in one day",""))))
A13: =IF(Roster!A11="","",Roster!A11) -> Maria Camila Leon | P13: =IF($A13="","",SUMIF($B$5:$O$5,">0",B13:O13)) -> 0 | Q13: =IF($A13="","",IF(SUM(B13:O13)<>P13,"⚠ There are horas en columnas fuera del periodo",IF(COUNTIF(B13:O13,"<0")>0,"⚠ Negative values",IF(COUNTIF(B13:O13,">24")>0,"⚠ More than 24 h in one day",""))))
A14: =IF(Roster!A12="","",Roster!A12) -> Juan David Castillo | B14: 0 | C14: 2 | D14: 4 | E14: 12 | F14: 12 | P14: =IF($A14="","",SUMIF($B$5:$O$5,">0",B14:O14)) -> 30 | Q14: =IF($A14="","",IF(SUM(B14:O14)<>P14,"⚠ There are horas en columnas fuera del periodo",IF(COUNTIF(B14:O14,"<0")>0,"⚠ Negative values",IF(COUNTIF(B14:O14,">24")>0,"⚠ More than 24 h in one day",""))))
A15: =IF(Roster!A13="","",Roster!A13) -> Jeronimo Rincon | B15: 4 | C15: 4 | D15: 4 | E15: 12 | F15: 12 | P15: =IF($A15="","",SUMIF($B$5:$O$5,">0",B15:O15)) -> 36 | Q15: =IF($A15="","",IF(SUM(B15:O15)<>P15,"⚠ There are horas en columnas fuera del periodo",IF(COUNTIF(B15:O15,"<0")>0,"⚠ Negative values",IF(COUNTIF(B15:O15,">24")>0,"⚠ More than 24 h in one day",""))))
A16: =IF(Roster!A14="","",Roster!A14) -> Jose David Valbuena | B16: 2 | C16: 4 | D16: 4 | E16: 12 | F16: 12 | P16: =IF($A16="","",SUMIF($B$5:$O$5,">0",B16:O16)) -> 34 | Q16: =IF($A16="","",IF(SUM(B16:O16)<>P16,"⚠ There are horas en columnas fuera del periodo",IF(COUNTIF(B16:O16,"<0")>0,"⚠ Negative values",IF(COUNTIF(B16:O16,">24")>0,"⚠ More than 24 h in one day",""))))
A17: =IF(Roster!A15="","",Roster!A15) -> Angie Lopez | P17: =IF($A17="","",SUMIF($B$5:$O$5,">0",B17:O17)) -> 0 | Q17: =IF($A17="","",IF(SUM(B17:O17)<>P17,"⚠ There are horas en columnas fuera del periodo",IF(COUNTIF(B17:O17,"<0")>0,"⚠ Negative values",IF(COUNTIF(B17:O17,">24")>0,"⚠ More than 24 h in one day",""))))
A18: =IF(Roster!A16="","",Roster!A16) -> Carlos Mesa | B18: 0 | C18: 0 | D18: 0 | E18: 0 | F18: 0 | P18: =IF($A18="","",SUMIF($B$5:$O$5,">0",B18:O18)) -> 0 | Q18: =IF($A18="","",IF(SUM(B18:O18)<>P18,"⚠ There are horas en columnas fuera del periodo",IF(COUNTIF(B18:O18,"<0")>0,"⚠ Negative values",IF(COUNTIF(B18:O18,">24")>0,"⚠ More than 24 h in one day",""))))
A19: =IF(Roster!A17="","",Roster!A17) -> Isabella de la Parra | P19: =IF($A19="","",SUMIF($B$5:$O$5,">0",B19:O19)) -> 0 | Q19: =IF($A19="","",IF(SUM(B19:O19)<>P19,"⚠ There are horas en columnas fuera del periodo",IF(COUNTIF(B19:O19,"<0")>0,"⚠ Negative values",IF(COUNTIF(B19:O19,">24")>0,"⚠ More than 24 h in one day",""))))
A20: =IF(Roster!A18="","",Roster!A18) -> Juan Pablo Gonzalez | P20: =IF($A20="","",SUMIF($B$5:$O$5,">0",B20:O20)) -> 0 | Q20: =IF($A20="","",IF(SUM(B20:O20)<>P20,"⚠ There are horas en columnas fuera del periodo",IF(COUNTIF(B20:O20,"<0")>0,"⚠ Negative values",IF(COUNTIF(B20:O20,">24")>0,"⚠ More than 24 h in one day",""))))
A21: =IF(Roster!A19="","",Roster!A19) -> Maria Camila Grazziani | P21: =IF($A21="","",SUMIF($B$5:$O$5,">0",B21:O21)) -> 0 | Q21: =IF($A21="","",IF(SUM(B21:O21)<>P21,"⚠ There are horas en columnas fuera del periodo",IF(COUNTIF(B21:O21,"<0")>0,"⚠ Negative values",IF(COUNTIF(B21:O21,">24")>0,"⚠ More than 24 h in one day",""))))
A22: =IF(Roster!A20="","",Roster!A20) -> Carlos Castellanos | P22: =IF($A22="","",SUMIF($B$5:$O$5,">0",B22:O22)) -> 0 | Q22: =IF($A22="","",IF(SUM(B22:O22)<>P22,"⚠ There are horas en columnas fuera del periodo",IF(COUNTIF(B22:O22,"<0")>0,"⚠ Negative values",IF(COUNTIF(B22:O22,">24")>0,"⚠ More than 24 h in one day",""))))
A23: =IF(Roster!A21="","",Roster!A21) -> Catalina Lara | B23: 4 | C23: 4 | D23: 4 | E23: 12 | F23: 12 | P23: =IF($A23="","",SUMIF($B$5:$O$5,">0",B23:O23)) -> 36 | Q23: =IF($A23="","",IF(SUM(B23:O23)<>P23,"⚠ There are horas en columnas fuera del periodo",IF(COUNTIF(B23:O23,"<0")>0,"⚠ Negative values",IF(COUNTIF(B23:O23,">24")>0,"⚠ More than 24 h in one day",""))))
A24: =IF(Roster!A22="","",Roster!A22) -> Daniel Trujillo | P24: =IF($A24="","",SUMIF($B$5:$O$5,">0",B24:O24)) -> 0 | Q24: =IF($A24="","",IF(SUM(B24:O24)<>P24,"⚠ There are horas en columnas fuera del periodo",IF(COUNTIF(B24:O24,"<0")>0,"⚠ Negative values",IF(COUNTIF(B24:O24,">24")>0,"⚠ More than 24 h in one day",""))))
A25: =IF(Roster!A23="","",Roster!A23) -> Fernanda Montañez | B25: 3 | C25: 2 | D25: 4 | E25: 12 | F25: 8 | P25: =IF($A25="","",SUMIF($B$5:$O$5,">0",B25:O25)) -> 29 | Q25: =IF($A25="","",IF(SUM(B25:O25)<>P25,"⚠ There are horas en columnas fuera del periodo",IF(COUNTIF(B25:O25,"<0")>0,"⚠ Negative values",IF(COUNTIF(B25:O25,">24")>0,"⚠ More than 24 h in one day",""))))
A26: =IF(Roster!A24="","",Roster!A24) -> Juan Esteban Abay | B26: 4 | C26: 4 | D26: 4 | E26: 12 | F26: 12 | P26: =IF($A26="","",SUMIF($B$5:$O$5,">0",B26:O26)) -> 36 | Q26: =IF($A26="","",IF(SUM(B26:O26)<>P26,"⚠ There are horas en columnas fuera del periodo",IF(COUNTIF(B26:O26,"<0")>0,"⚠ Negative values",IF(COUNTIF(B26:O26,">24")>0,"⚠ More than 24 h in one day",""))))
A27: =IF(Roster!A25="","",Roster!A25) -> Juan José Reyes | P27: =IF($A27="","",SUMIF($B$5:$O$5,">0",B27:O27)) -> 0 | Q27: =IF($A27="","",IF(SUM(B27:O27)<>P27,"⚠ There are horas en columnas fuera del periodo",IF(COUNTIF(B27:O27,"<0")>0,"⚠ Negative values",IF(COUNTIF(B27:O27,">24")>0,"⚠ More than 24 h in one day",""))))
A28: =IF(Roster!A26="","",Roster!A26) -> Maria Isabella Verdooren | B28: 0 | C28: 0 | D28: 0 | E28: 0 | F28: 0 | P28: =IF($A28="","",SUMIF($B$5:$O$5,">0",B28:O28)) -> 0 | Q28: =IF($A28="","",IF(SUM(B28:O28)<>P28,"⚠ There are horas en columnas fuera del periodo",IF(COUNTIF(B28:O28,"<0")>0,"⚠ Negative values",IF(COUNTIF(B28:O28,">24")>0,"⚠ More than 24 h in one day",""))))
A29: =IF(Roster!A27="","",Roster!A27) -> Juan Sebastian Bermudez | P29: =IF($A29="","",SUMIF($B$5:$O$5,">0",B29:O29)) -> 0 | Q29: =IF($A29="","",IF(SUM(B29:O29)<>P29,"⚠ There are horas en columnas fuera del periodo",IF(COUNTIF(B29:O29,"<0")>0,"⚠ Negative values",IF(COUNTIF(B29:O29,">24")>0,"⚠ More than 24 h in one day",""))))
A30: =IF(Roster!A28="","",Roster!A28) -> Laura Alfonso | P30: =IF($A30="","",SUMIF($B$5:$O$5,">0",B30:O30)) -> 0 | Q30: =IF($A30="","",IF(SUM(B30:O30)<>P30,"⚠ There are horas en columnas fuera del periodo",IF(COUNTIF(B30:O30,"<0")>0,"⚠ Negative values",IF(COUNTIF(B30:O30,">24")>0,"⚠ More than 24 h in one day",""))))
A31: =IF(Roster!A29="","",Roster!A29) -> Laura Escobar | P31: =IF($A31="","",SUMIF($B$5:$O$5,">0",B31:O31)) -> 0 | Q31: =IF($A31="","",IF(SUM(B31:O31)<>P31,"⚠ There are horas en columnas fuera del periodo",IF(COUNTIF(B31:O31,"<0")>0,"⚠ Negative values",IF(COUNTIF(B31:O31,">24")>0,"⚠ More than 24 h in one day",""))))
A32: =IF(Roster!A30="","",Roster!A30) -> Maria Fernanda López | P32: =IF($A32="","",SUMIF($B$5:$O$5,">0",B32:O32)) -> 0 | Q32: =IF($A32="","",IF(SUM(B32:O32)<>P32,"⚠ There are horas en columnas fuera del periodo",IF(COUNTIF(B32:O32,"<0")>0,"⚠ Negative values",IF(COUNTIF(B32:O32,">24")>0,"⚠ More than 24 h in one day",""))))
A33: =IF(Roster!A31="","",Roster!A31) -> Martin Fernandez Fernandez | P33: =IF($A33="","",SUMIF($B$5:$O$5,">0",B33:O33)) -> 0 | Q33: =IF($A33="","",IF(SUM(B33:O33)<>P33,"⚠ There are horas en columnas fuera del periodo",IF(COUNTIF(B33:O33,"<0")>0,"⚠ Negative values",IF(COUNTIF(B33:O33,">24")>0,"⚠ More than 24 h in one day",""))))
A34: =IF(Roster!A32="","",Roster!A32) -> Andrés Guerra | P34: =IF($A34="","",SUMIF($B$5:$O$5,">0",B34:O34)) -> 0 | Q34: =IF($A34="","",IF(SUM(B34:O34)<>P34,"⚠ There are horas en columnas fuera del periodo",IF(COUNTIF(B34:O34,"<0")>0,"⚠ Negative values",IF(COUNTIF(B34:O34,">24")>0,"⚠ More than 24 h in one day",""))))
A35: =IF(Roster!A33="","",Roster!A33) -> David Santiago Chinchilla | P35: =IF($A35="","",SUMIF($B$5:$O$5,">0",B35:O35)) -> 0 | Q35: =IF($A35="","",IF(SUM(B35:O35)<>P35,"⚠ There are horas en columnas fuera del periodo",IF(COUNTIF(B35:O35,"<0")>0,"⚠ Negative values",IF(COUNTIF(B35:O35,">24")>0,"⚠ More than 24 h in one day",""))))
A36: =IF(Roster!A34="","",Roster!A34) -> Isabella Salamanca | P36: =IF($A36="","",SUMIF($B$5:$O$5,">0",B36:O36)) -> 0 | Q36: =IF($A36="","",IF(SUM(B36:O36)<>P36,"⚠ There are horas en columnas fuera del periodo",IF(COUNTIF(B36:O36,"<0")>0,"⚠ Negative values",IF(COUNTIF(B36:O36,">24")>0,"⚠ More than 24 h in one day",""))))
A37: =IF(Roster!A35="","",Roster!A35) -> Gianny Nicolás Pereira | B37: 0 | C37: 4 | D37: 4 | E37: 12 | F37: 12 | P37: =IF($A37="","",SUMIF($B$5:$O$5,">0",B37:O37)) -> 32 | Q37: =IF($A37="","",IF(SUM(B37:O37)<>P37,"⚠ There are horas en columnas fuera del periodo",IF(COUNTIF(B37:O37,"<0")>0,"⚠ Negative values",IF(COUNTIF(B37:O37,">24")>0,"⚠ More than 24 h in one day",""))))
A38: =IF(Roster!A36="","",Roster!A36) -> Juan Sebastian Ramos | P38: =IF($A38="","",SUMIF($B$5:$O$5,">0",B38:O38)) -> 0 | Q38: =IF($A38="","",IF(SUM(B38:O38)<>P38,"⚠ There are horas en columnas fuera del periodo",IF(COUNTIF(B38:O38,"<0")>0,"⚠ Negative values",IF(COUNTIF(B38:O38,">24")>0,"⚠ More than 24 h in one day",""))))
A39: =IF(Roster!A37="","",Roster!A37) -> Karen Sofía Martínez | P39: =IF($A39="","",SUMIF($B$5:$O$5,">0",B39:O39)) -> 0 | Q39: =IF($A39="","",IF(SUM(B39:O39)<>P39,"⚠ There are horas en columnas fuera del periodo",IF(COUNTIF(B39:O39,"<0")>0,"⚠ Negative values",IF(COUNTIF(B39:O39,">24")>0,"⚠ More than 24 h in one day",""))))
A40: =IF(Roster!A38="","",Roster!A38) -> Jaime Macias | P40: =IF($A40="","",SUMIF($B$5:$O$5,">0",B40:O40)) -> 0 | Q40: =IF($A40="","",IF(SUM(B40:O40)<>P40,"⚠ There are horas en columnas fuera del periodo",IF(COUNTIF(B40:O40,"<0")>0,"⚠ Negative values",IF(COUNTIF(B40:O40,">24")>0,"⚠ More than 24 h in one day",""))))
...

Sheet RAW BTBS
A1: Time | B1: Status | C1: Approved / Rejected By | D1: Approved / Rejected Date | E1: Invoice Number | F1: Date | G1: Client | H1: Prospect | I1: County | J1: Legal Description | K1: Work Type | L1: Project | M1: Well Name | N1: Time Worked | O1: Date Time Entry Created | P1: Invoice Date | Q1: Client Landman | R1: Created By | S1: Modified By | T1: Modified Date | U1: Work Performed Detail | W1: Date (norm) | X1: Hours | Y1: Name norm. | Z1: Match key | AA1: In Roster? | AB1: In period? | AC1: Fingerprint (dup.) | AD1: Duplicate? | AE1: Entry | AF1: Final key | AG1: Record status | AH1: Location | AI1: Surname | AJ1: How it matched | AK1: #Project | AL1: #Client | AM1: #Prospect | AN1: #County | AO1: #Landman
A2: C Lara | B2: Approved | C2: L. Carollo | D2: 8/19/2026 | F2: 8/19/2026 | G2: Rocking WW Minerals, LLC | H2: RWW PRB Asset VDR | I2: Campbell, WY | J2: 05-41N-71W | K2: Title | M2: W2, Lots 7, 8, 9, 10, 15, 16, 17, 18 | N2: 0.25 | O2: 8/19/2026 1:26:56 PM | Q2: Whitney Wicks | R2: C Lara | S2: C Lara | T2: 8/19/2026 | U2: Pruned interest for 45 notecards. Reviewed notecard by notecard and selected subject land for those who didn't have it selected. | W2: =IF($F2="",0,IFERROR(IF(ISNUMBER($F2),INT($F2),DATE(VALUE(MID(SUBSTITUTE(LEFT($F2,FIND(" ",$F2&" ")-1),"/",REPT(" ",20)),41,20)),VALUE(LEFT(SUBSTITUTE(LEFT($F2,FIND(" ",$F2&" ")-1),"/",REPT(" ",20)),20)),VALUE(MID(SUBSTITUTE(LEFT($F2,FIND(" ",$F2&" ")-1),"/",REPT(" ",20)),21,20)))),0)) -> 46253 | X2: =IF(ISNUMBER($N2),$N2*Validation!$B$5,"") -> 2 | Y2: =IF($A2="","",SUBSTITUTE(SUBSTITUTE(SUBSTITUTE(SUBSTITUTE(SUBSTITUTE(SUBSTITUTE(SUBSTITUTE(UPPER(TRIM($A2)),"Á","A"),"É","E"),"Í","I"),"Ó","O"),"Ú","U"),"Ñ","N"),"Ü","U")) -> C LARA | Z2: =IF($Y2="","",LEFT($Y2,1)&" "&TRIM(RIGHT(SUBSTITUTE($Y2," ",REPT(" ",50)),50))) -> C LARA | AA2: =IF($AF2="","",IF(COUNTIF(Validation!$U$19:$U$178,$AF2)>0,"OK","NO MATCH")) -> OK | AB2: =IF($W2=0,"",IF(AND($W2>=Validation!$B$3,$W2<=Validation!$C$3),"Yes","No")) -> Yes | AC2: =IF($A2="","",$AF2&"|"&TEXT($W2,"yyyy-mm-dd")&"|"&$J2&"|"&$N2) -> C LARA|2026-08-19|05-41N-71W|0.25 | AD2: =IF($AC2="","",IF(COUNTIF($AC$2:$AC$3000,$AC2)>1,"REVIEW","OK")) -> OK | AE2: =IF(OR($W2=0,$O2=""),"",IF(IFERROR(IF(ISNUMBER($O2),INT($O2),DATE(VALUE(MID(SUBSTITUTE(LEFT($O2,FIND(" ",$O2&" ")-1),"/",REPT(" ",20)),41,20)),VALUE(LEFT(SUBSTITUTE(LEFT($O2,FIND(" ",$O2&" ")-1),"/",REPT(" ",20)),20)),VALUE(MID(SUBSTITUTE(LEFT($O2,FIND(" ",$O2&" ")-1),"/",REPT(" ",20)),21,20)))),0)>$W2,"Late","Same day")) -> Same day | AF2: =IF($A2="","",IFERROR(INDEX(Validation!$C$193:$C$217,MATCH($A2,Validation!$A$193:$A$217,0)),IF(COUNTIF(Validation!$U$19:$U$178,$Z2)>0,$Z2,IF(COUNTIF(Validation!$S$19:$S$178,$AI2)=1,INDEX(Validation!$U$19:$U$178,MATCH($AI2,Validation!$S$19:$S$178,0)),$Z2)))) -> C LARA | AG2: =IF(COUNTA($A2:$U2)=0,"",IF($A2="","No name",IF($F2="","No date",IF($W2=0,"Date ilegible",IF(NOT(ISNUMBER($N2)),"Hours no numéricas",IF($AA2="NO MATCH","Person no identificada","OK")))))) -> OK | AH2: =IF($W2=0,"No date",IF($W2<Validation!$B$3,"Before period",IF($W2>Validation!$C$3,"After period","In period"))) -> In period | AI2: =IF($Y2="","",TRIM(RIGHT(SUBSTITUTE($Y2," ",REPT(" ",50)),50))) -> LARA | AJ2: =IF($A2="","",IF(NOT(ISERROR(MATCH($A2,Validation!$A$193:$A$217,0))),"Manual mapping",IF(COUNTIF(Validation!$U$19:$U$178,$Z2)>0,"Direct",IF(COUNTIF(Validation!$S$19:$S$178,$AI2)=1,"By surname","Unresolved")))) -> Direct | AK2: =IF($L2="","",IF(MATCH($L2,$L$2:$L$3000,0)<>ROW()-1,"",COUNT($AK$1:$AK1)+1)) | AL2: =IF($G2="","",IF(MATCH($G2,$G$2:$G$3000,0)<>ROW()-1,"",COUNT($AL$1:$AL1)+1)) -> 1 | AM2: =IF($H2="","",IF(MATCH($H2,$H$2:$H$3000,0)<>ROW()-1,"",COUNT($AM$1:$AM1)+1)) -> 1 | AN2: =IF($I2="","",IF(MATCH($I2,$I$2:$I$3000,0)<>ROW()-1,"",COUNT($AN$1:$AN1)+1)) -> 1 | AO2: =IF($Q2="","",IF(MATCH($Q2,$Q$2:$Q$3000,0)<>ROW()-1,"",COUNT($AO$1:$AO1)+1)) -> 1
A3: C Lara | B3: Approved | C3: L. Carollo | D3: 8/19/2026 | F3: 8/19/2026 | G3: Rocking WW Minerals, LLC | H3: RWW PRB Asset VDR | I3: Converse, WY | J3: 12-35N-70W | K3: Title | M3: NESE | N3: 0.125 | O3: 8/19/2026 1:42:49 PM | Q3: Whitney Wicks | R3: C Lara | S3: C Lara | T3: 8/19/2026 | U3: Pruned interest for 2 notecards. Selected subject land for notecards that didn't have it selected. Downloaded from iDoc and uploaded to AOI document where RWW received interest. | W3: =IF($F3="",0,IFERROR(IF(ISNUMBER($F3),INT($F3),DATE(VALUE(MID(SUBSTITUTE(LEFT($F3,FIND(" ",$F3&" ")-1),"/",REPT(" ",20)),41,20)),VALUE(LEFT(SUBSTITUTE(LEFT($F3,FIND(" ",$F3&" ")-1),"/",REPT(" ",20)),20)),VALUE(MID(SUBSTITUTE(LEFT($F3,FIND(" ",$F3&" ")-1),"/",REPT(" ",20)),21,20)))),0)) -> 46253 | X3: =IF(ISNUMBER($N3),$N3*Validation!$B$5,"") -> 1 | Y3: =IF($A3="","",SUBSTITUTE(SUBSTITUTE(SUBSTITUTE(SUBSTITUTE(SUBSTITUTE(SUBSTITUTE(SUBSTITUTE(UPPER(TRIM($A3)),"Á","A"),"É","E"),"Í","I"),"Ó","O"),"Ú","U"),"Ñ","N"),"Ü","U")) -> C LARA | Z3: =IF($Y3="","",LEFT($Y3,1)&" "&TRIM(RIGHT(SUBSTITUTE($Y3," ",REPT(" ",50)),50))) -> C LARA | AA3: =IF($AF3="","",IF(COUNTIF(Validation!$U$19:$U$178,$AF3)>0,"OK","NO MATCH")) -> OK | AB3: =IF($W3=0,"",IF(AND($W3>=Validation!$B$3,$W3<=Validation!$C$3),"Yes","No")) -> Yes | AC3: =IF($A3="","",$AF3&"|"&TEXT($W3,"yyyy-mm-dd")&"|"&$J3&"|"&$N3) -> C LARA|2026-08-19|12-35N-70W|0.125 | AD3: =IF($AC3="","",IF(COUNTIF($AC$2:$AC$3000,$AC3)>1,"REVIEW","OK")) -> OK | AE3: =IF(OR($W3=0,$O3=""),"",IF(IFERROR(IF(ISNUMBER($O3),INT($O3),DATE(VALUE(MID(SUBSTITUTE(LEFT($O3,FIND(" ",$O3&" ")-1),"/",REPT(" ",20)),41,20)),VALUE(LEFT(SUBSTITUTE(LEFT($O3,FIND(" ",$O3&" ")-1),"/",REPT(" ",20)),20)),VALUE(MID(SUBSTITUTE(LEFT($O3,FIND(" ",$O3&" ")-1),"/",REPT(" ",20)),21,20)))),0)>$W3,"Late","Same day")) -> Same day | AF3: =IF($A3="","",IFERROR(INDEX(Validation!$C$193:$C$217,MATCH($A3,Validation!$A$193:$A$217,0)),IF(COUNTIF(Validation!$U$19:$U$178,$Z3)>0,$Z3,IF(COUNTIF(Validation!$S$19:$S$178,$AI3)=1,INDEX(Validation!$U$19:$U$178,MATCH($AI3,Validation!$S$19:$S$178,0)),$Z3)))) -> C LARA | AG3: =IF(COUNTA($A3:$U3)=0,"",IF($A3="","No name",IF($F3="","No date",IF($W3=0,"Date ilegible",IF(NOT(ISNUMBER($N3)),"Hours no numéricas",IF($AA3="NO MATCH","Person no identificada","OK")))))) -> OK | AH3: =IF($W3=0,"No date",IF($W3<Validation!$B$3,"Before period",IF($W3>Validation!$C$3,"After period","In period"))) -> In period | AI3: =IF($Y3="","",TRIM(RIGHT(SUBSTITUTE($Y3," ",REPT(" ",50)),50))) -> LARA | AJ3: =IF($A3="","",IF(NOT(ISERROR(MATCH($A3,Validation!$A$193:$A$217,0))),"Manual mapping",IF(COUNTIF(Validation!$U$19:$U$178,$Z3)>0,"Direct",IF(COUNTIF(Validation!$S$19:$S$178,$AI3)=1,"By surname","Unresolved")))) -> Direct | AK3: =IF($L3="","",IF(MATCH($L3,$L$2:$L$3000,0)<>ROW()-1,"",COUNT($AK$1:$AK2)+1)) | AL3: =IF($G3="","",IF(MATCH($G3,$G$2:$G$3000,0)<>ROW()-1,"",COUNT($AL$1:$AL2)+1)) | AM3: =IF($H3="","",IF(MATCH($H3,$H$2:$H$3000,0)<>ROW()-1,"",COUNT($AM$1:$AM2)+1)) | AN3: =IF($I3="","",IF(MATCH($I3,$I$2:$I$3000,0)<>ROW()-1,"",COUNT($AN$1:$AN2)+1)) -> 2 | AO3: =IF($Q3="","",IF(MATCH($Q3,$Q$2:$Q$3000,0)<>ROW()-1,"",COUNT($AO$1:$AO2)+1))
A4: C Lara | B4: Approved | C4: L. Carollo | D4: 8/19/2026 | F4: 8/19/2026 | G4: Rocking WW Minerals, LLC | H4: RWW PRB Asset VDR | I4: Converse, WY | J4: 09-35N-69W | K4: Title | M4: NWNW, NENE, SW, SE | N4: 0.25 | O4: 8/20/2026 12:15:12 AM | Q4: Whitney Wicks | R4: C Lara | S4: C Lara | T4: 8/20/2026 | U4: Pruned interest for 2 notecards. Reviewed notecard by notecard and selected subject land for those who didn't have it selected. Created SW and SW polygons. Downloaded from iDoc and uploaded to AOI document where RWW received interest. Multiple notecards don't light-up in chain, issue starting at clients AOI. | W4: =IF($F4="",0,IFERROR(IF(ISNUMBER($F4),INT($F4),DATE(VALUE(MID(SUBSTITUTE(LEFT($F4,FIND(" ",$F4&" ")-1),"/",REPT(" ",20)),41,20)),VALUE(LEFT(SUBSTITUTE(LEFT($F4,FIND(" ",$F4&" ")-1),"/",REPT(" ",20)),20)),VALUE(MID(SUBSTITUTE(LEFT($F4,FIND(" ",$F4&" ")-1),"/",REPT(" ",20)),21,20)))),0)) -> 46253 | X4: =IF(ISNUMBER($N4),$N4*Validation!$B$5,"") -> 2 | Y4: =IF($A4="","",SUBSTITUTE(SUBSTITUTE(SUBSTITUTE(SUBSTITUTE(SUBSTITUTE(SUBSTITUTE(SUBSTITUTE(UPPER(TRIM($A4)),"Á","A"),"É","E"),"Í","I"),"Ó","O"),"Ú","U"),"Ñ","N"),"Ü","U")) -> C LARA | Z4: =IF($Y4="","",LEFT($Y4,1)&" "&TRIM(RIGHT(SUBSTITUTE($Y4," ",REPT(" ",50)),50))) -> C LARA | AA4: =IF($AF4="","",IF(COUNTIF(Validation!$U$19:$U$178,$AF4)>0,"OK","NO MATCH")) -> OK | AB4: =IF($W4=0,"",IF(AND($W4>=Validation!$B$3,$W4<=Validation!$C$3),"Yes","No")) -> Yes | AC4: =IF($A4="","",$AF4&"|"&TEXT($W4,"yyyy-mm-dd")&"|"&$J4&"|"&$N4) -> C LARA|2026-08-19|09-35N-69W|0.25 | AD4: =IF($AC4="","",IF(COUNTIF($AC$2:$AC$3000,$AC4)>1,"REVIEW","OK")) -> OK | AE4: =IF(OR($W4=0,$O4=""),"",IF(IFERROR(IF(ISNUMBER($O4),INT($O4),DATE(VALUE(MID(SUBSTITUTE(LEFT($O4,FIND(" ",$O4&" ")-1),"/",REPT(" ",20)),41,20)),VALUE(LEFT(SUBSTITUTE(LEFT($O4,FIND(" ",$O4&" ")-1),"/",REPT(" ",20)),20)),VALUE(MID(SUBSTITUTE(LEFT($O4,FIND(" ",$O4&" ")-1),"/",REPT(" ",20)),21,20)))),0)>$W4,"Late","Same day")) -> Late | AF4: =IF($A4="","",IFERROR(INDEX(Validation!$C$193:$C$217,MATCH($A4,Validation!$A$193:$A$217,0)),IF(COUNTIF(Validation!$U$19:$U$178,$Z4)>0,$Z4,IF(COUNTIF(Validation!$S$19:$S$178,$AI4)=1,INDEX(Validation!$U$19:$U$178,MATCH($AI4,Validation!$S$19:$S$178,0)),$Z4)))) -> C LARA | AG4: =IF(COUNTA($A4:$U4)=0,"",IF($A4="","No name",IF($F4="","No date",IF($W4=0,"Date ilegible",IF(NOT(ISNUMBER($N4)),"Hours no numéricas",IF($AA4="NO MATCH","Person no identificada","OK")))))) -> OK | AH4: =IF($W4=0,"No date",IF($W4<Validation!$B$3,"Before period",IF($W4>Validation!$C$3,"After period","In period"))) -> In period | AI4: =IF($Y4="","",TRIM(RIGHT(SUBSTITUTE($Y4," ",REPT(" ",50)),50))) -> LARA | AJ4: =IF($A4="","",IF(NOT(ISERROR(MATCH($A4,Validation!$A$193:$A$217,0))),"Manual mapping",IF(COUNTIF(Validation!$U$19:$U$178,$Z4)>0,"Direct",IF(COUNTIF(Validation!$S$19:$S$178,$AI4)=1,"By surname","Unresolved")))) -> Direct | AK4: =IF($L4="","",IF(MATCH($L4,$L$2:$L$3000,0)<>ROW()-1,"",COUNT($AK$1:$AK3)+1)) | AL4: =IF($G4="","",IF(MATCH($G4,$G$2:$G$3000,0)<>ROW()-1,"",COUNT($AL$1:$AL3)+1)) | AM4: =IF($H4="","",IF(MATCH($H4,$H$2:$H$3000,0)<>ROW()-1,"",COUNT($AM$1:$AM3)+1)) | AN4: =IF($I4="","",IF(MATCH($I4,$I$2:$I$3000,0)<>ROW()-1,"",COUNT($AN$1:$AN3)+1)) | AO4: =IF($Q4="","",IF(MATCH($Q4,$Q$2:$Q$3000,0)<>ROW()-1,"",COUNT($AO$1:$AO3)+1))
A5: C Lara | B5: Approved | C5: L. Carollo | D5: 8/19/2026 | F5: 8/19/2026 | G5: Rocking WW Minerals, LLC | H5: RWW PRB Asset VDR | I5: Campbell, WY | J5: 06-41N-73W | K5: Title | M5: NESE | N5: 0.125 | O5: 8/20/2026 12:17:58 AM | Q5: Whitney Wicks | R5: C Lara | S5: C Lara | T5: 8/20/2026 | U5: No need to prune interest. Selected subject land for notecards that didn't have it selected. Downloaded from iDoc and uploaded to AOI document where RWW received interest. | W5: =IF($F5="",0,IFERROR(IF(ISNUMBER($F5),INT($F5),DATE(VALUE(MID(SUBSTITUTE(LEFT($F5,FIND(" ",$F5&" ")-1),"/",REPT(" ",20)),41,20)),VALUE(LEFT(SUBSTITUTE(LEFT($F5,FIND(" ",$F5&" ")-1),"/",REPT(" ",20)),20)),VALUE(MID(SUBSTITUTE(LEFT($F5,FIND(" ",$F5&" ")-1),"/",REPT(" ",20)),21,20)))),0)) -> 46253 | X5: =IF(ISNUMBER($N5),$N5*Validation!$B$5,"") -> 1 | Y5: =IF($A5="","",SUBSTITUTE(SUBSTITUTE(SUBSTITUTE(SUBSTITUTE(SUBSTITUTE(SUBSTITUTE(SUBSTITUTE(UPPER(TRIM($A5)),"Á","A"),"É","E"),"Í","I"),"Ó","O"),"Ú","U"),"Ñ","N"),"Ü","U")) -> C LARA | Z5: =IF($Y5="","",LEFT($Y5,1)&" "&TRIM(RIGHT(SUBSTITUTE($Y5," ",REPT(" ",50)),50))) -> C LARA | AA5: =IF($AF5="","",IF(COUNTIF(Validation!$U$19:$U$178,$AF5)>0,"OK","NO MATCH")) -> OK | AB5: =IF($W5=0,"",IF(AND($W5>=Validation!$B$3,$W5<=Validation!$C$3),"Yes","No")) -> Yes | AC5: =IF($A5="","",$AF5&"|"&TEXT($W5,"yyyy-mm-dd")&"|"&$J5&"|"&$N5) -> C LARA|2026-08-19|06-41N-73W|0.125 | AD5: =IF($AC5="","",IF(COUNTIF($AC$2:$AC$3000,$AC5)>1,"REVIEW","OK")) -> OK | AE5: =IF(OR($W5=0,$O5=""),"",IF(IFERROR(IF(ISNUMBER($O5),INT($O5),DATE(VALUE(MID(SUBSTITUTE(LEFT($O5,FIND(" ",$O5&" ")-1),"/",REPT(" ",20)),41,20)),VALUE(LEFT(SUBSTITUTE(LEFT($O5,FIND(" ",$O5&" ")-1),"/",REPT(" ",20)),20)),VALUE(MID(SUBSTITUTE(LEFT($O5,FIND(" ",$O5&" ")-1),"/",REPT(" ",20)),21,20)))),0)>$W5,"Late","Same day")) -> Late | AF5: =IF($A5="","",IFERROR(INDEX(Validation!$C$193:$C$217,MATCH($A5,Validation!$A$193:$A$217,0)),IF(COUNTIF(Validation!$U$19:$U$178,$Z5)>0,$Z5,IF(COUNTIF(Validation!$S$19:$S$178,$AI5)=1,INDEX(Validation!$U$19:$U$178,MATCH($AI5,Validation!$S$19:$S$178,0)),$Z5)))) -> C LARA | AG5: =IF(COUNTA($A5:$U5)=0,"",IF($A5="","No name",IF($F5="","No date",IF($W5=0,"Date ilegible",IF(NOT(ISNUMBER($N5)),"Hours no numéricas",IF($AA5="NO MATCH","Person no identificada","OK")))))) -> OK | AH5: =IF($W5=0,"No date",IF($W5<Validation!$B$3,"Before period",IF($W5>Validation!$C$3,"After period","In period"))) -> In period | AI5: =IF($Y5="","",TRIM(RIGHT(SUBSTITUTE($Y5," ",REPT(" ",50)),50))) -> LARA | AJ5: =IF($A5="","",IF(NOT(ISERROR(MATCH($A5,Validation!$A$193:$A$217,0))),"Manual mapping",IF(COUNTIF(Validation!$U$19:$U$178,$Z5)>0,"Direct",IF(COUNTIF(Validation!$S$19:$S$178,$AI5)=1,"By surname","Unresolved")))) -> Direct | AK5: =IF($L5="","",IF(MATCH($L5,$L$2:$L$3000,0)<>ROW()-1,"",COUNT($AK$1:$AK4)+1)) | AL5: =IF($G5="","",IF(MATCH($G5,$G$2:$G$3000,0)<>ROW()-1,"",COUNT($AL$1:$AL4)+1)) | AM5: =IF($H5="","",IF(MATCH($H5,$H$2:$H$3000,0)<>ROW()-1,"",COUNT($AM$1:$AM4)+1)) | AN5: =IF($I5="","",IF(MATCH($I5,$I$2:$I$3000,0)<>ROW()-1,"",COUNT($AN$1:$AN4)+1)) | AO5: =IF($Q5="","",IF(MATCH($Q5,$Q$2:$Q$3000,0)<>ROW()-1,"",COUNT($AO$1:$AO4)+1))
A6: C Lara | B6: Approved | C6: L. Carollo | D6: 8/19/2026 | F6: 8/19/2026 | G6: Rocking WW Minerals, LLC | H6: RWW PRB Asset VDR | I6: Converse, WY | J6: 09-36N-71W | K6: Title | M6: SW | N6: 0.25 | O6: 8/20/2026 1:17:35 AM | Q6: Whitney Wicks | R6: C Lara | S6: C Lara | T6: 8/20/2026 | U6: Pruned interest for 6 notecards. Reviewed notecard by notecard and selected subject land for those who didn't have it selected. Downloaded from iDoc and uploaded to AOI document where RWW received interest. A couple notecards don't light-up in chain, issue starting at clients AOI. | W6: =IF($F6="",0,IFERROR(IF(ISNUMBER($F6),INT($F6),DATE(VALUE(MID(SUBSTITUTE(LEFT($F6,FIND(" ",$F6&" ")-1),"/",REPT(" ",20)),41,20)),VALUE(LEFT(SUBSTITUTE(LEFT($F6,FIND(" ",$F6&" ")-1),"/",REPT(" ",20)),20)),VALUE(MID(SUBSTITUTE(LEFT($F6,FIND(" ",$F6&" ")-1),"/",REPT(" ",20)),21,20)))),0)) -> 46253 | X6: =IF(ISNUMBER($N6),$N6*Validation!$B$5,"") -> 2 | Y6: =IF($A6="","",SUBSTITUTE(SUBSTITUTE(SUBSTITUTE(SUBSTITUTE(SUBSTITUTE(SUBSTITUTE(SUBSTITUTE(UPPER(TRIM($A6)),"Á","A"),"É","E"),"Í","I"),"Ó","O"),"Ú","U"),"Ñ","N"),"Ü","U")) -> C LARA | Z6: =IF($Y6="","",LEFT($Y6,1)&" "&TRIM(RIGHT(SUBSTITUTE($Y6," ",REPT(" ",50)),50))) -> C LARA | AA6: =IF($AF6="","",IF(COUNTIF(Validation!$U$19:$U$178,$AF6)>0,"OK","NO MATCH")) -> OK | AB6: =IF($W6=0,"",IF(AND($W6>=Validation!$B$3,$W6<=Validation!$C$3),"Yes","No")) -> Yes | AC6: =IF($A6="","",$AF6&"|"&TEXT($W6,"yyyy-mm-dd")&"|"&$J6&"|"&$N6) -> C LARA|2026-08-19|09-36N-71W|0.25 | AD6: =IF($AC6="","",IF(COUNTIF($AC$2:$AC$3000,$AC6)>1,"REVIEW","OK")) -> OK | AE6: =IF(OR($W6=0,$O6=""),"",IF(IFERROR(IF(ISNUMBER($O6),INT($O6),DATE(VALUE(MID(SUBSTITUTE(LEFT($O6,FIND(" ",$O6&" ")-1),"/",REPT(" ",20)),41,20)),VALUE(LEFT(SUBSTITUTE(LEFT($O6,FIND(" ",$O6&" ")-1),"/",REPT(" ",20)),20)),VALUE(MID(SUBSTITUTE(LEFT($O6,FIND(" ",$O6&" ")-1),"/",REPT(" ",20)),21,20)))),0)>$W6,"Late","Same day")) -> Late | AF6: =IF($A6="","",IFERROR(INDEX(Validation!$C$193:$C$217,MATCH($A6,Validation!$A$193:$A$217,0)),IF(COUNTIF(Validation!$U$19:$U$178,$Z6)>0,$Z6,IF(COUNTIF(Validation!$S$19:$S$178,$AI6)=1,INDEX(Validation!$U$19:$U$178,MATCH($AI6,Validation!$S$19:$S$178,0)),$Z6)))) -> C LARA | AG6: =IF(COUNTA($A6:$U6)=0,"",IF($A6="","No name",IF($F6="","No date",IF($W6=0,"Date ilegible",IF(NOT(ISNUMBER($N6)),"Hours no numéricas",IF($AA6="NO MATCH","Person no identificada","OK")))))) -> OK | AH6: =IF($W6=0,"No date",IF($W6<Validation!$B$3,"Before period",IF($W6>Validation!$C$3,"After period","In period"))) -> In period | AI6: =IF($Y6="","",TRIM(RIGHT(SUBSTITUTE($Y6," ",REPT(" ",50)),50))) -> LARA | AJ6: =IF($A6="","",IF(NOT(ISERROR(MATCH($A6,Validation!$A$193:$A$217,0))),"Manual mapping",IF(COUNTIF(Validation!$U$19:$U$178,$Z6)>0,"Direct",IF(COUNTIF(Validation!$S$19:$S$178,$AI6)=1,"By surname","Unresolved")))) -> Direct | AK6: =IF($L6="","",IF(MATCH($L6,$L$2:$L$3000,0)<>ROW()-1,"",COUNT($AK$1:$AK5)+1)) | AL6: =IF($G6="","",IF(MATCH($G6,$G$2:$G$3000,0)<>ROW()-1,"",COUNT($AL$1:$AL5)+1)) | AM6: =IF($H6="","",IF(MATCH($H6,$H$2:$H$3000,0)<>ROW()-1,"",COUNT($AM$1:$AM5)+1)) | AN6: =IF($I6="","",IF(MATCH($I6,$I$2:$I$3000,0)<>ROW()-1,"",COUNT($AN$1:$AN5)+1)) | AO6: =IF($Q6="","",IF(MATCH($Q6,$Q$2:$Q$3000,0)<>ROW()-1,"",COUNT($AO$1:$AO5)+1))
A7: C Lara | B7: Approved | C7: L. Carollo | D7: 8/19/2026 | F7: 8/19/2026 | G7: Rocking WW Minerals, LLC | H7: RWW PRB Asset VDR | I7: Converse, WY | J7: 01-34N-69W | K7: Title | M7: SWSW, Lot 4, SWNW, NWSW | N7: 0.25 | O7: 8/20/2026 2:27:00 AM | Q7: Whitney Wicks | R7: C Lara | S7: C Lara | T7: 8/20/2026 | U7: Pruned interest for 33 notecards. Reviewed notecard by notecard and selected subject land for those who didn't have it selected. Created polygons for Lot 4, SWNW, NWSW. Most notecards don't light-up in chain. Assignment set on hold. | W7: =IF($F7="",0,IFERROR(IF(ISNUMBER($F7),INT($F7),DATE(VALUE(MID(SUBSTITUTE(LEFT($F7,FIND(" ",$F7&" ")-1),"/",REPT(" ",20)),41,20)),VALUE(LEFT(SUBSTITUTE(LEFT($F7,FIND(" ",$F7&" ")-1),"/",REPT(" ",20)),20)),VALUE(MID(SUBSTITUTE(LEFT($F7,FIND(" ",$F7&" ")-1),"/",REPT(" ",20)),21,20)))),0)) -> 46253 | X7: =IF(ISNUMBER($N7),$N7*Validation!$B$5,"") -> 2 | Y7: =IF($A7="","",SUBSTITUTE(SUBSTITUTE(SUBSTITUTE(SUBSTITUTE(SUBSTITUTE(SUBSTITUTE(SUBSTITUTE(UPPER(TRIM($A7)),"Á","A"),"É","E"),"Í","I"),"Ó","O"),"Ú","U"),"Ñ","N"),"Ü","U")) -> C LARA | Z7: =IF($Y7="","",LEFT($Y7,1)&" "&TRIM(RIGHT(SUBSTITUTE($Y7," ",REPT(" ",50)),50))) -> C LARA | AA7: =IF($AF7="","",IF(COUNTIF(Validation!$U$19:$U$178,$AF7)>0,"OK","NO MATCH")) -> OK | AB7: =IF($W7=0,"",IF(AND($W7>=Validation!$B$3,$W7<=Validation!$C$3),"Yes","No")) -> Yes | AC7: =IF($A7="","",$AF7&"|"&TEXT($W7,"yyyy-mm-dd")&"|"&$J7&"|"&$N7) -> C LARA|2026-08-19|01-34N-69W|0.25 | AD7: =IF($AC7="","",IF(COUNTIF($AC$2:$AC$3000,$AC7)>1,"REVIEW","OK")) -> OK | AE7: =IF(OR($W7=0,$O7=""),"",IF(IFERROR(IF(ISNUMBER($O7),INT($O7),DATE(VALUE(MID(SUBSTITUTE(LEFT($O7,FIND(" ",$O7&" ")-1),"/",REPT(" ",20)),41,20)),VALUE(LEFT(SUBSTITUTE(LEFT($O7,FIND(" ",$O7&" ")-1),"/",REPT(" ",20)),20)),VALUE(MID(SUBSTITUTE(LEFT($O7,FIND(" ",$O7&" ")-1),"/",REPT(" ",20)),21,20)))),0)>$W7,"Late","Same day")) -> Late | AF7: =IF($A7="","",IFERROR(INDEX(Validation!$C$193:$C$217,MATCH($A7,Validation!$A$193:$A$217,0)),IF(COUNTIF(Validation!$U$19:$U$178,$Z7)>0,$Z7,IF(COUNTIF(Validation!$S$19:$S$178,$AI7)=1,INDEX(Validation!$U$19:$U$178,MATCH($AI7,Validation!$S$19:$S$178,0)),$Z7)))) -> C LARA | AG7: =IF(COUNTA($A7:$U7)=0,"",IF($A7="","No name",IF($F7="","No date",IF($W7=0,"Date ilegible",IF(NOT(ISNUMBER($N7)),"Hours no numéricas",IF($AA7="NO MATCH","Person no identificada","OK")))))) -> OK | AH7: =IF($W7=0,"No date",IF($W7<Validation!$B$3,"Before period",IF($W7>Validation!$C$3,"After period","In period"))) -> In period | AI7: =IF($Y7="","",TRIM(RIGHT(SUBSTITUTE($Y7," ",REPT(" ",50)),50))) -> LARA | AJ7: =IF($A7="","",IF(NOT(ISERROR(MATCH($A7,Validation!$A$193:$A$217,0))),"Manual mapping",IF(COUNTIF(Validation!$U$19:$U$178,$Z7)>0,"Direct",IF(COUNTIF(Validation!$S$19:$S$178,$AI7)=1,"By surname","Unresolved")))) -> Direct | AK7: =IF($L7="","",IF(MATCH($L7,$L$2:$L$3000,0)<>ROW()-1,"",COUNT($AK$1:$AK6)+1)) | AL7: =IF($G7="","",IF(MATCH($G7,$G$2:$G$3000,0)<>ROW()-1,"",COUNT($AL$1:$AL6)+1)) | AM7: =IF($H7="","",IF(MATCH($H7,$H$2:$H$3000,0)<>ROW()-1,"",COUNT($AM$1:$AM6)+1)) | AN7: =IF($I7="","",IF(MATCH($I7,$I$2:$I$3000,0)<>ROW()-1,"",COUNT($AN$1:$AN6)+1)) | AO7: =IF($Q7="","",IF(MATCH($Q7,$Q$2:$Q$3000,0)<>ROW()-1,"",COUNT($AO$1:$AO6)+1))
A8: C Lara | B8: Unapproved | F8: 8/19/2026 | G8: Rocking WW Minerals, LLC | H8: RWW PRB Asset VDR | I8: Campbell, WY | J8: 09-41N-73W | K8: Title | M8: SE, S2NE, NESW, NENE, SENW | N8: 0.25 | O8: 8/20/2026 3:21:09 AM | Q8: Whitney Wicks | R8: C Lara | S8: C Lara | T8: 8/20/2026 | U8: Pruned interest for 71 notecards. Reviewed notecard by notecard and selected subject land for those who didn't have it selected. Included missing documents from second AOI from clients. Other documents were already included, therefore, no need to clone second AOI on first. | W8: =IF($F8="",0,IFERROR(IF(ISNUMBER($F8),INT($F8),DATE(VALUE(MID(SUBSTITUTE(LEFT($F8,FIND(" ",$F8&" ")-1),"/",REPT(" ",20)),41,20)),VALUE(LEFT(SUBSTITUTE(LEFT($F8,FIND(" ",$F8&" ")-1),"/",REPT(" ",20)),20)),VALUE(MID(SUBSTITUTE(LEFT($F8,FIND(" ",$F8&" ")-1),"/",REPT(" ",20)),21,20)))),0)) -> 46253 | X8: =IF(ISNUMBER($N8),$N8*Validation!$B$5,"") -> 2 | Y8: =IF($A8="","",SUBSTITUTE(SUBSTITUTE(SUBSTITUTE(SUBSTITUTE(SUBSTITUTE(SUBSTITUTE(SUBSTITUTE(UPPER(TRIM($A8)),"Á","A"),"É","E"),"Í","I"),"Ó","O"),"Ú","U"),"Ñ","N"),"Ü","U")) -> C LARA | Z8: =IF($Y8="","",LEFT($Y8,1)&" "&TRIM(RIGHT(SUBSTITUTE($Y8," ",REPT(" ",50)),50))) -> C LARA | AA8: =IF($AF8="","",IF(COUNTIF(Validation!$U$19:$U$178,$AF8)>0,"OK","NO MATCH")) -> OK | AB8: =IF($W8=0,"",IF(AND($W8>=Validation!$B$3,$W8<=Validation!$C$3),"Yes","No")) -> Yes | AC8: =IF($A8="","",$AF8&"|"&TEXT($W8,"yyyy-mm-dd")&"|"&$J8&"|"&$N8) -> C LARA|2026-08-19|09-41N-73W|0.25 | AD8: =IF($AC8="","",IF(COUNTIF($AC$2:$AC$3000,$AC8)>1,"REVIEW","OK")) -> OK | AE8: =IF(OR($W8=0,$O8=""),"",IF(IFERROR(IF(ISNUMBER($O8),INT($O8),DATE(VALUE(MID(SUBSTITUTE(LEFT($O8,FIND(" ",$O8&" ")-1),"/",REPT(" ",20)),41,20)),VALUE(LEFT(SUBSTITUTE(LEFT($O8,FIND(" ",$O8&" ")-1),"/",REPT(" ",20)),20)),VALUE(MID(SUBSTITUTE(LEFT($O8,FIND(" ",$O8&" ")-1),"/",REPT(" ",20)),21,20)))),0)>$W8,"Late","Same day")) -> Late | AF8: =IF($A8="","",IFERROR(INDEX(Validation!$C$193:$C$217,MATCH($A8,Validation!$A$193:$A$217,0)),IF(COUNTIF(Validation!$U$19:$U$178,$Z8)>0,$Z8,IF(COUNTIF(Validation!$S$19:$S$178,$AI8)=1,INDEX(Validation!$U$19:$U$178,MATCH($AI8,Validation!$S$19:$S$178,0)),$Z8)))) -> C LARA | AG8: =IF(COUNTA($A8:$U8)=0,"",IF($A8="","No name",IF($F8="","No date",IF($W8=0,"Date ilegible",IF(NOT(ISNUMBER($N8)),"Hours no numéricas",IF($AA8="NO MATCH","Person no identificada","OK")))))) -> OK | AH8: =IF($W8=0,"No date",IF($W8<Validation!$B$3,"Before period",IF($W8>Validation!$C$3,"After period","In period"))) -> In period | AI8: =IF($Y8="","",TRIM(RIGHT(SUBSTITUTE($Y8," ",REPT(" ",50)),50))) -> LARA | AJ8: =IF($A8="","",IF(NOT(ISERROR(MATCH($A8,Validation!$A$193:$A$217,0))),"Manual mapping",IF(COUNTIF(Validation!$U$19:$U$178,$Z8)>0,"Direct",IF(COUNTIF(Validation!$S$19:$S$178,$AI8)=1,"By surname","Unresolved")))) -> Direct | AK8: =IF($L8="","",IF(MATCH($L8,$L$2:$L$3000,0)<>ROW()-1,"",COUNT($AK$1:$AK7)+1)) | AL8: =IF($G8="","",IF(MATCH($G8,$G$2:$G$3000,0)<>ROW()-1,"",COUNT($AL$1:$AL7)+1)) | AM8: =IF($H8="","",IF(MATCH($H8,$H$2:$H$3000,0)<>ROW()-1,"",COUNT($AM$1:$AM7)+1)) | AN8: =IF($I8="","",IF(MATCH($I8,$I$2:$I$3000,0)<>ROW()-1,"",COUNT($AN$1:$AN7)+1)) | AO8: =IF($Q8="","",IF(MATCH($Q8,$Q$2:$Q$3000,0)<>ROW()-1,"",COUNT($AO$1:$AO7)+1))
A9: C Mesa | B9: Approved | C9: L. Carollo | D9: 8/19/2026 | F9: 8/19/2026 | G9: Rocking WW Minerals, LLC | H9: RWW PRB Asset VDR | I9: Converse, WY | J9: 18-36N-70W | K9: Title | M9: Lot 3, S2NE, NESW | N9: 0.25 | O9: 8/19/2026 8:05:17 PM | Q9: Whitney Wicks | R9: C Mesa | S9: C Mesa | T9: 8/19/2026 | U9: Pruned the AOI from RWW Minerals to the source deed | W9: =IF($F9="",0,IFERROR(IF(ISNUMBER($F9),INT($F9),DATE(VALUE(MID(SUBSTITUTE(LEFT($F9,FIND(" ",$F9&" ")-1),"/",REPT(" ",20)),41,20)),VALUE(LEFT(SUBSTITUTE(LEFT($F9,FIND(" ",$F9&" ")-1),"/",REPT(" ",20)),20)),VALUE(MID(SUBSTITUTE(LEFT($F9,FIND(" ",$F9&" ")-1),"/",REPT(" ",20)),21,20)))),0)) -> 46253 | X9: =IF(ISNUMBER($N9),$N9*Validation!$B$5,"") -> 2 | Y9: =IF($A9="","",SUBSTITUTE(SUBSTITUTE(SUBSTITUTE(SUBSTITUTE(SUBSTITUTE(SUBSTITUTE(SUBSTITUTE(UPPER(TRIM($A9)),"Á","A"),"É","E"),"Í","I"),"Ó","O"),"Ú","U"),"Ñ","N"),"Ü","U")) -> C MESA | Z9: =IF($Y9="","",LEFT($Y9,1)&" "&TRIM(RIGHT(SUBSTITUTE($Y9," ",REPT(" ",50)),50))) -> C MESA | AA9: =IF($AF9="","",IF(COUNTIF(Validation!$U$19:$U$178,$AF9)>0,"OK","NO MATCH")) -> OK | AB9: =IF($W9=0,"",IF(AND($W9>=Validation!$B$3,$W9<=Validation!$C$3),"Yes","No")) -> Yes | AC9: =IF($A9="","",$AF9&"|"&TEXT($W9,"yyyy-mm-dd")&"|"&$J9&"|"&$N9) -> C MESA|2026-08-19|18-36N-70W|0.25 | AD9: =IF($AC9="","",IF(COUNTIF($AC$2:$AC$3000,$AC9)>1,"REVIEW","OK")) -> OK | AE9: =IF(OR($W9=0,$O9=""),"",IF(IFERROR(IF(ISNUMBER($O9),INT($O9),DATE(VALUE(MID(SUBSTITUTE(LEFT($O9,FIND(" ",$O9&" ")-1),"/",REPT(" ",20)),41,20)),VALUE(LEFT(SUBSTITUTE(LEFT($O9,FIND(" ",$O9&" ")-1),"/",REPT(" ",20)),20)),VALUE(MID(SUBSTITUTE(LEFT($O9,FIND(" ",$O9&" ")-1),"/",REPT(" ",20)),21,20)))),0)>$W9,"Late","Same day")) -> Same day | AF9: =IF($A9="","",IFERROR(INDEX(Validation!$C$193:$C$217,MATCH($A9,Validation!$A$193:$A$217,0)),IF(COUNTIF(Validation!$U$19:$U$178,$Z9)>0,$Z9,IF(COUNTIF(Validation!$S$19:$S$178,$AI9)=1,INDEX(Validation!$U$19:$U$178,MATCH($AI9,Validation!$S$19:$S$178,0)),$Z9)))) -> C MESA | AG9: =IF(COUNTA($A9:$U9)=0,"",IF($A9="","No name",IF($F9="","No date",IF($W9=0,"Date ilegible",IF(NOT(ISNUMBER($N9)),"Hours no numéricas",IF($AA9="NO MATCH","Person no identificada","OK")))))) -> OK | AH9: =IF($W9=0,"No date",IF($W9<Validation!$B$3,"Before period",IF($W9>Validation!$C$3,"After period","In period"))) -> In period | AI9: =IF($Y9="","",TRIM(RIGHT(SUBSTITUTE($Y9," ",REPT(" ",50)),50))) -> MESA | AJ9: =IF($A9="","",IF(NOT(ISERROR(MATCH($A9,Validation!$A$193:$A$217,0))),"Manual mapping",IF(COUNTIF(Validation!$U$19:$U$178,$Z9)>0,"Direct",IF(COUNTIF(Validation!$S$19:$S$178,$AI9)=1,"By surname","Unresolved")))) -> Direct | AK9: =IF($L9="","",IF(MATCH($L9,$L$2:$L$3000,0)<>ROW()-1,"",COUNT($AK$1:$AK8)+1)) | AL9: =IF($G9="","",IF(MATCH($G9,$G$2:$G$3000,0)<>ROW()-1,"",COUNT($AL$1:$AL8)+1)) | AM9: =IF($H9="","",IF(MATCH($H9,$H$2:$H$3000,0)<>ROW()-1,"",COUNT($AM$1:$AM8)+1)) | AN9: =IF($I9="","",IF(MATCH($I9,$I$2:$I$3000,0)<>ROW()-1,"",COUNT($AN$1:$AN8)+1)) | AO9: =IF($Q9="","",IF(MATCH($Q9,$Q$2:$Q$3000,0)<>ROW()-1,"",COUNT($AO$1:$AO8)+1))
A10: C Mesa | B10: Approved | C10: L. Carollo | D10: 8/19/2026 | F10: 8/19/2026 | G10: Rocking WW Minerals, LLC | H10: RWW PRB Asset VDR | I10: Converse, WY | J10: 05-34N-68W | K10: Title | M10: Lots 1, 2, S2NE ; Lots 3, 4, S2NW, SW | N10: 0.5 | O10: 8/19/2026 8:06:40 PM | Q10: Whitney Wicks | R10: C Mesa | S10: C Mesa | T10: 8/19/2026 | U10: Pruned the AOI from RWW Minerals to the source deed | W10: =IF($F10="",0,IFERROR(IF(ISNUMBER($F10),INT($F10),DATE(VALUE(MID(SUBSTITUTE(LEFT($F10,FIND(" ",$F10&" ")-1),"/",REPT(" ",20)),41,20)),VALUE(LEFT(SUBSTITUTE(LEFT($F10,FIND(" ",$F10&" ")-1),"/",REPT(" ",20)),20)),VALUE(MID(SUBSTITUTE(LEFT($F10,FIND(" ",$F10&" ")-1),"/",REPT(" ",20)),21,20)))),0)) -> 46253 | X10: =IF(ISNUMBER($N10),$N10*Validation!$B$5,"") -> 4 | Y10: =IF($A10="","",SUBSTITUTE(SUBSTITUTE(SUBSTITUTE(SUBSTITUTE(SUBSTITUTE(SUBSTITUTE(SUBSTITUTE(UPPER(TRIM($A10)),"Á","A"),"É","E"),"Í","I"),"Ó","O"),"Ú","U"),"Ñ","N"),"Ü","U")) -> C MESA | Z10: =IF($Y10="","",LEFT($Y10,1)&" "&TRIM(RIGHT(SUBSTITUTE($Y10," ",REPT(" ",50)),50))) -> C MESA | AA10: =IF($AF10="","",IF(COUNTIF(Validation!$U$19:$U$178,$AF10)>0,"OK","NO MATCH")) -> OK | AB10: =IF($W10=0,"",IF(AND($W10>=Validation!$B$3,$W10<=Validation!$C$3),"Yes","No")) -> Yes | AC10: =IF($A10="","",$AF10&"|"&TEXT($W10,"yyyy-mm-dd")&"|"&$J10&"|"&$N10) -> C MESA|2026-08-19|05-34N-68W|0.5 | AD10: =IF($AC10="","",IF(COUNTIF($AC$2:$AC$3000,$AC10)>1,"REVIEW","OK")) -> OK | AE10: =IF(OR($W10=0,$O10=""),"",IF(IFERROR(IF(ISNUMBER($O10),INT($O10),DATE(VALUE(MID(SUBSTITUTE(LEFT($O10,FIND(" ",$O10&" ")-1),"/",REPT(" ",20)),41,20)),VALUE(LEFT(SUBSTITUTE(LEFT($O10,FIND(" ",$O10&" ")-1),"/",REPT(" ",20)),20)),VALUE(MID(SUBSTITUTE(LEFT($O10,FIND(" ",$O10&" ")-1),"/",REPT(" ",20)),21,20)))),0)>$W10,"Late","Same day")) -> Same day | AF10: =IF($A10="","",IFERROR(INDEX(Validation!$C$193:$C$217,MATCH($A10,Validation!$A$193:$A$217,0)),IF(COUNTIF(Validation!$U$19:$U$178,$Z10)>0,$Z10,IF(COUNTIF(Validation!$S$19:$S$178,$AI10)=1,INDEX(Validation!$U$19:$U$178,MATCH($AI10,Validation!$S$19:$S$178,0)),$Z10)))) -> C MESA | AG10: =IF(COUNTA($A10:$U10)=0,"",IF($A10="","No name",IF($F10="","No date",IF($W10=0,"Date ilegible",IF(NOT(ISNUMBER($N10)),"Hours no numéricas",IF($AA10="NO MATCH","Person no identificada","OK")))))) -> OK | AH10: =IF($W10=0,"No date",IF($W10<Validation!$B$3,"Before period",IF($W10>Validation!$C$3,"After period","In period"))) -> In period | AI10: =IF($Y10="","",TRIM(RIGHT(SUBSTITUTE($Y10," ",REPT(" ",50)),50))) -> MESA | AJ10: =IF($A10="","",IF(NOT(ISERROR(MATCH($A10,Validation!$A$193:$A$217,0))),"Manual mapping",IF(COUNTIF(Validation!$U$19:$U$178,$Z10)>0,"Direct",IF(COUNTIF(Validation!$S$19:$S$178,$AI10)=1,"By surname","Unresolved")))) -> Direct | AK10: =IF($L10="","",IF(MATCH($L10,$L$2:$L$3000,0)<>ROW()-1,"",COUNT($AK$1:$AK9)+1)) | AL10: =IF($G10="","",IF(MATCH($G10,$G$2:$G$3000,0)<>ROW()-1,"",COUNT($AL$1:$AL9)+1)) | AM10: =IF($H10="","",IF(MATCH($H10,$H$2:$H$3000,0)<>ROW()-1,"",COUNT($AM$1:$AM9)+1)) | AN10: =IF($I10="","",IF(MATCH($I10,$I$2:$I$3000,0)<>ROW()-1,"",COUNT($AN$1:$AN9)+1)) | AO10: =IF($Q10="","",IF(MATCH($Q10,$Q$2:$Q$3000,0)<>ROW()-1,"",COUNT($AO$1:$AO9)+1))
A11: C Mesa | B11: Approved | C11: L. Carollo | D11: 8/19/2026 | F11: 8/19/2026 | G11: Rocking WW Minerals, LLC | H11: RWW PRB Asset VDR | I11: Converse, WY | J11: 05-35N-68W | K11: Title | M11: S2SW, S2SE | N11: 0.25 | O11: 8/19/2026 8:07:23 PM | Q11: Whitney Wicks | R11: C Mesa | S11: C Mesa | T11: 8/19/2026 | U11: Pruned the AOI from RWW Minerals to the source deed | W11: =IF($F11="",0,IFERROR(IF(ISNUMBER($F11),INT($F11),DATE(VALUE(MID(SUBSTITUTE(LEFT($F11,FIND(" ",$F11&" ")-1),"/",REPT(" ",20)),41,20)),VALUE(LEFT(SUBSTITUTE(LEFT($F11,FIND(" ",$F11&" ")-1),"/",REPT(" ",20)),20)),VALUE(MID(SUBSTITUTE(LEFT($F11,FIND(" ",$F11&" ")-1),"/",REPT(" ",20)),21,20)))),0)) -> 46253 | X11: =IF(ISNUMBER($N11),$N11*Validation!$B$5,"") -> 2 | Y11: =IF($A11="","",SUBSTITUTE(SUBSTITUTE(SUBSTITUTE(SUBSTITUTE(SUBSTITUTE(SUBSTITUTE(SUBSTITUTE(UPPER(TRIM($A11)),"Á","A"),"É","E"),"Í","I"),"Ó","O"),"Ú","U"),"Ñ","N"),"Ü","U")) -> C MESA | Z11: =IF($Y11="","",LEFT($Y11,1)&" "&TRIM(RIGHT(SUBSTITUTE($Y11," ",REPT(" ",50)),50))) -> C MESA | AA11: =IF($AF11="","",IF(COUNTIF(Validation!$U$19:$U$178,$AF11)>0,"OK","NO MATCH")) -> OK | AB11: =IF($W11=0,"",IF(AND($W11>=Validation!$B$3,$W11<=Validation!$C$3),"Yes","No")) -> Yes | AC11: =IF($A11="","",$AF11&"|"&TEXT($W11,"yyyy-mm-dd")&"|"&$J11&"|"&$N11) -> C MESA|2026-08-19|05-35N-68W|0.25 | AD11: =IF($AC11="","",IF(COUNTIF($AC$2:$AC$3000,$AC11)>1,"REVIEW","OK")) -> OK | AE11: =IF(OR($W11=0,$O11=""),"",IF(IFERROR(IF(ISNUMBER($O11),INT($O11),DATE(VALUE(MID(SUBSTITUTE(LEFT($O11,FIND(" ",$O11&" ")-1),"/",REPT(" ",20)),41,20)),VALUE(LEFT(SUBSTITUTE(LEFT($O11,FIND(" ",$O11&" ")-1),"/",REPT(" ",20)),20)),VALUE(MID(SUBSTITUTE(LEFT($O11,FIND(" ",$O11&" ")-1),"/",REPT(" ",20)),21,20)))),0)>$W11,"Late","Same day")) -> Same day | AF11: =IF($A11="","",IFERROR(INDEX(Validation!$C$193:$C$217,MATCH($A11,Validation!$A$193:$A$217,0)),IF(COUNTIF(Validation!$U$19:$U$178,$Z11)>0,$Z11,IF(COUNTIF(Validation!$S$19:$S$178,$AI11)=1,INDEX(Validation!$U$19:$U$178,MATCH($AI11,Validation!$S$19:$S$178,0)),$Z11)))) -> C MESA | AG11: =IF(COUNTA($A11:$U11)=0,"",IF($A11="","No name",IF($F11="","No date",IF($W11=0,"Date ilegible",IF(NOT(ISNUMBER($N11)),"Hours no numéricas",IF($AA11="NO MATCH","Person no identificada","OK")))))) -> OK | AH11: =IF($W11=0,"No date",IF($W11<Validation!$B$3,"Before period",IF($W11>Validation!$C$3,"After period","In period"))) -> In period | AI11: =IF($Y11="","",TRIM(RIGHT(SUBSTITUTE($Y11," ",REPT(" ",50)),50))) -> MESA | AJ11: =IF($A11="","",IF(NOT(ISERROR(MATCH($A11,Validation!$A$193:$A$217,0))),"Manual mapping",IF(COUNTIF(Validation!$U$19:$U$178,$Z11)>0,"Direct",IF(COUNTIF(Validation!$S$19:$S$178,$AI11)=1,"By surname","Unresolved")))) -> Direct | AK11: =IF($L11="","",IF(MATCH($L11,$L$2:$L$3000,0)<>ROW()-1,"",COUNT($AK$1:$AK10)+1)) | AL11: =IF($G11="","",IF(MATCH($G11,$G$2:$G$3000,0)<>ROW()-1,"",COUNT($AL$1:$AL10)+1)) | AM11: =IF($H11="","",IF(MATCH($H11,$H$2:$H$3000,0)<>ROW()-1,"",COUNT($AM$1:$AM10)+1)) | AN11: =IF($I11="","",IF(MATCH($I11,$I$2:$I$3000,0)<>ROW()-1,"",COUNT($AN$1:$AN10)+1)) | AO11: =IF($Q11="","",IF(MATCH($Q11,$Q$2:$Q$3000,0)<>ROW()-1,"",COUNT($AO$1:$AO10)+1))
A12: F Montañez | B12: Approved | C12: L. Carollo | D12: 8/19/2026 | F12: 8/19/2026 | G12: Rocking WW Minerals, LLC | H12: RWW PRB Asset VDR | I12: Converse, WY | J12: 00-00S-00W | K12: Title | N12: 0.125 | O12: 8/19/2026 8:26:15 PM | Q12: Whitney Wicks | R12: F Montañez | S12: F Montañez | T12: 8/19/2026 | U12: Onboarding to RWW project. | W12: =IF($F12="",0,IFERROR(IF(ISNUMBER($F12),INT($F12),DATE(VALUE(MID(SUBSTITUTE(LEFT($F12,FIND(" ",$F12&" ")-1),"/",REPT(" ",20)),41,20)),VALUE(LEFT(SUBSTITUTE(LEFT($F12,FIND(" ",$F12&" ")-1),"/",REPT(" ",20)),20)),VALUE(MID(SUBSTITUTE(LEFT($F12,FIND(" ",$F12&" ")-1),"/",REPT(" ",20)),21,20)))),0)) -> 46253 | X12: =IF(ISNUMBER($N12),$N12*Validation!$B$5,"") -> 1 | Y12: =IF($A12="","",SUBSTITUTE(SUBSTITUTE(SUBSTITUTE(SUBSTITUTE(SUBSTITUTE(SUBSTITUTE(SUBSTITUTE(UPPER(TRIM($A12)),"Á","A"),"É","E"),"Í","I"),"Ó","O"),"Ú","U"),"Ñ","N"),"Ü","U")) -> F MONTANEZ | Z12: =IF($Y12="","",LEFT($Y12,1)&" "&TRIM(RIGHT(SUBSTITUTE($Y12," ",REPT(" ",50)),50))) -> F MONTANEZ | AA12: =IF($AF12="","",IF(COUNTIF(Validation!$U$19:$U$178,$AF12)>0,"OK","NO MATCH")) -> OK | AB12: =IF($W12=0,"",IF(AND($W12>=Validation!$B$3,$W12<=Validation!$C$3),"Yes","No")) -> Yes | AC12: =IF($A12="","",$AF12&"|"&TEXT($W12,"yyyy-mm-dd")&"|"&$J12&"|"&$N12) -> F MONTANEZ|2026-08-19|00-00S-00W|0.125 | AD12: =IF($AC12="","",IF(COUNTIF($AC$2:$AC$3000,$AC12)>1,"REVIEW","OK")) -> OK | AE12: =IF(OR($W12=0,$O12=""),"",IF(IFERROR(IF(ISNUMBER($O12),INT($O12),DATE(VALUE(MID(SUBSTITUTE(LEFT($O12,FIND(" ",$O12&" ")-1),"/",REPT(" ",20)),41,20)),VALUE(LEFT(SUBSTITUTE(LEFT($O12,FIND(" ",$O12&" ")-1),"/",REPT(" ",20)),20)),VALUE(MID(SUBSTITUTE(LEFT($O12,FIND(" ",$O12&" ")-1),"/",REPT(" ",20)),21,20)))),0)>$W12,"Late","Same day")) -> Same day | AF12: =IF($A12="","",IFERROR(INDEX(Validation!$C$193:$C$217,MATCH($A12,Validation!$A$193:$A$217,0)),IF(COUNTIF(Validation!$U$19:$U$178,$Z12)>0,$Z12,IF(COUNTIF(Validation!$S$19:$S$178,$AI12)=1,INDEX(Validation!$U$19:$U$178,MATCH($AI12,Validation!$S$19:$S$178,0)),$Z12)))) -> F MONTANEZ | AG12: =IF(COUNTA($A12:$U12)=0,"",IF($A12="","No name",IF($F12="","No date",IF($W12=0,"Date ilegible",IF(NOT(ISNUMBER($N12)),"Hours no numéricas",IF($AA12="NO MATCH","Person no identificada","OK")))))) -> OK | AH12: =IF($W12=0,"No date",IF($W12<Validation!$B$3,"Before period",IF($W12>Validation!$C$3,"After period","In period"))) -> In period | AI12: =IF($Y12="","",TRIM(RIGHT(SUBSTITUTE($Y12," ",REPT(" ",50)),50))) -> MONTANEZ | AJ12: =IF($A12="","",IF(NOT(ISERROR(MATCH($A12,Validation!$A$193:$A$217,0))),"Manual mapping",IF(COUNTIF(Validation!$U$19:$U$178,$Z12)>0,"Direct",IF(COUNTIF(Validation!$S$19:$S$178,$AI12)=1,"By surname","Unresolved")))) -> Direct | AK12: =IF($L12="","",IF(MATCH($L12,$L$2:$L$3000,0)<>ROW()-1,"",COUNT($AK$1:$AK11)+1)) | AL12: =IF($G12="","",IF(MATCH($G12,$G$2:$G$3000,0)<>ROW()-1,"",COUNT($AL$1:$AL11)+1)) | AM12: =IF($H12="","",IF(MATCH($H12,$H$2:$H$3000,0)<>ROW()-1,"",COUNT($AM$1:$AM11)+1)) | AN12: =IF($I12="","",IF(MATCH($I12,$I$2:$I$3000,0)<>ROW()-1,"",COUNT($AN$1:$AN11)+1)) | AO12: =IF($Q12="","",IF(MATCH($Q12,$Q$2:$Q$3000,0)<>ROW()-1,"",COUNT($AO$1:$AO11)+1))
A13: F Montañez | B13: Approved | C13: L. Carollo | D13: 8/19/2026 | F13: 8/19/2026 | G13: Rocking WW Minerals, LLC | H13: RWW PRB Asset VDR | I13: Converse, WY | J13: 08-36N-70W | K13: Title | M13: SENW, NESW, NWSW, SWSW | N13: 0.125 | O13: 8/19/2026 8:27:42 PM | Q13: Whitney Wicks | R13: F Montañez | S13: F Montañez | T13: 8/19/2026 | U13: Progress in prune of mentioned legal description | W13: =IF($F13="",0,IFERROR(IF(ISNUMBER($F13),INT($F13),DATE(VALUE(MID(SUBSTITUTE(LEFT($F13,FIND(" ",$F13&" ")-1),"/",REPT(" ",20)),41,20)),VALUE(LEFT(SUBSTITUTE(LEFT($F13,FIND(" ",$F13&" ")-1),"/",REPT(" ",20)),20)),VALUE(MID(SUBSTITUTE(LEFT($F13,FIND(" ",$F13&" ")-1),"/",REPT(" ",20)),21,20)))),0)) -> 46253 | X13: =IF(ISNUMBER($N13),$N13*Validation!$B$5,"") -> 1 | Y13: =IF($A13="","",SUBSTITUTE(SUBSTITUTE(SUBSTITUTE(SUBSTITUTE(SUBSTITUTE(SUBSTITUTE(SUBSTITUTE(UPPER(TRIM($A13)),"Á","A"),"É","E"),"Í","I"),"Ó","O"),"Ú","U"),"Ñ","N"),"Ü","U")) -> F MONTANEZ | Z13: =IF($Y13="","",LEFT($Y13,1)&" "&TRIM(RIGHT(SUBSTITUTE($Y13," ",REPT(" ",50)),50))) -> F MONTANEZ | AA13: =IF($AF13="","",IF(COUNTIF(Validation!$U$19:$U$178,$AF13)>0,"OK","NO MATCH")) -> OK | AB13: =IF($W13=0,"",IF(AND($W13>=Validation!$B$3,$W13<=Validation!$C$3),"Yes","No")) -> Yes | AC13: =IF($A13="","",$AF13&"|"&TEXT($W13,"yyyy-mm-dd")&"|"&$J13&"|"&$N13) -> F MONTANEZ|2026-08-19|08-36N-70W|0.125 | AD13: =IF($AC13="","",IF(COUNTIF($AC$2:$AC$3000,$AC13)>1,"REVIEW","OK")) -> REVIEW | AE13: =IF(OR($W13=0,$O13=""),"",IF(IFERROR(IF(ISNUMBER($O13),INT($O13),DATE(VALUE(MID(SUBSTITUTE(LEFT($O13,FIND(" ",$O13&" ")-1),"/",REPT(" ",20)),41,20)),VALUE(LEFT(SUBSTITUTE(LEFT($O13,FIND(" ",$O13&" ")-1),"/",REPT(" ",20)),20)),VALUE(MID(SUBSTITUTE(LEFT($O13,FIND(" ",$O13&" ")-1),"/",REPT(" ",20)),21,20)))),0)>$W13,"Late","Same day")) -> Same day | AF13: =IF($A13="","",IFERROR(INDEX(Validation!$C$193:$C$217,MATCH($A13,Validation!$A$193:$A$217,0)),IF(COUNTIF(Validation!$U$19:$U$178,$Z13)>0,$Z13,IF(COUNTIF(Validation!$S$19:$S$178,$AI13)=1,INDEX(Validation!$U$19:$U$178,MATCH($AI13,Validation!$S$19:$S$178,0)),$Z13)))) -> F MONTANEZ | AG13: =IF(COUNTA($A13:$U13)=0,"",IF($A13="","No name",IF($F13="","No date",IF($W13=0,"Date ilegible",IF(NOT(ISNUMBER($N13)),"Hours no numéricas",IF($AA13="NO MATCH","Person no identificada","OK")))))) -> OK | AH13: =IF($W13=0,"No date",IF($W13<Validation!$B$3,"Before period",IF($W13>Validation!$C$3,"After period","In period"))) -> In period | AI13: =IF($Y13="","",TRIM(RIGHT(SUBSTITUTE($Y13," ",REPT(" ",50)),50))) -> MONTANEZ | AJ13: =IF($A13="","",IF(NOT(ISERROR(MATCH($A13,Validation!$A$193:$A$217,0))),"Manual mapping",IF(COUNTIF(Validation!$U$19:$U$178,$Z13)>0,"Direct",IF(COUNTIF(Validation!$S$19:$S$178,$AI13)=1,"By surname","Unresolved")))) -> Direct | AK13: =IF($L13="","",IF(MATCH($L13,$L$2:$L$3000,0)<>ROW()-1,"",COUNT($AK$1:$AK12)+1)) | AL13: =IF($G13="","",IF(MATCH($G13,$G$2:$G$3000,0)<>ROW()-1,"",COUNT($AL$1:$AL12)+1)) | AM13: =IF($H13="","",IF(MATCH($H13,$H$2:$H$3000,0)<>ROW()-1,"",COUNT($AM$1:$AM12)+1)) | AN13: =IF($I13="","",IF(MATCH($I13,$I$2:$I$3000,0)<>ROW()-1,"",COUNT($AN$1:$AN12)+1)) | AO13: =IF($Q13="","",IF(MATCH($Q13,$Q$2:$Q$3000,0)<>ROW()-1,"",COUNT($AO$1:$AO12)+1))
A14: F Montañez | B14: Approved | C14: L. Carollo | D14: 8/19/2026 | F14: 8/19/2026 | G14: Rocking WW Minerals, LLC | H14: RWW PRB Asset VDR | I14: Converse, WY | J14: 08-36N-70W | K14: Title | M14: SENW, NESW, NWSW, SWSW | N14: 0.125 | O14: 8/20/2026 2:58:40 AM | Q14: Whitney Wicks | R14: F Montañez | S14: F Montañez | T14: 8/20/2026 | U14: Progress in prune of mentioned legal description | W14: =IF($F14="",0,IFERROR(IF(ISNUMBER($F14),INT($F14),DATE(VALUE(MID(SUBSTITUTE(LEFT($F14,FIND(" ",$F14&" ")-1),"/",REPT(" ",20)),41,20)),VALUE(LEFT(SUBSTITUTE(LEFT($F14,FIND(" ",$F14&" ")-1),"/",REPT(" ",20)),20)),VALUE(MID(SUBSTITUTE(LEFT($F14,FIND(" ",$F14&" ")-1),"/",REPT(" ",20)),21,20)))),0)) -> 46253 | X14: =IF(ISNUMBER($N14),$N14*Validation!$B$5,"") -> 1 | Y14: =IF($A14="","",SUBSTITUTE(SUBSTITUTE(SUBSTITUTE(SUBSTITUTE(SUBSTITUTE(SUBSTITUTE(SUBSTITUTE(UPPER(TRIM($A14)),"Á","A"),"É","E"),"Í","I"),"Ó","O"),"Ú","U"),"Ñ","N"),"Ü","U")) -> F MONTANEZ | Z14: =IF($Y14="","",LEFT($Y14,1)&" "&TRIM(RIGHT(SUBSTITUTE($Y14," ",REPT(" ",50)),50))) -> F MONTANEZ | AA14: =IF($AF14="","",IF(COUNTIF(Validation!$U$19:$U$178,$AF14)>0,"OK","NO MATCH")) -> OK | AB14: =IF($W14=0,"",IF(AND($W14>=Validation!$B$3,$W14<=Validation!$C$3),"Yes","No")) -> Yes | AC14: =IF($A14="","",$AF14&"|"&TEXT($W14,"yyyy-mm-dd")&"|"&$J14&"|"&$N14) -> F MONTANEZ|2026-08-19|08-36N-70W|0.125 | AD14: =IF($AC14="","",IF(COUNTIF($AC$2:$AC$3000,$AC14)>1,"REVIEW","OK")) -> REVIEW | AE14: =IF(OR($W14=0,$O14=""),"",IF(IFERROR(IF(ISNUMBER($O14),INT($O14),DATE(VALUE(MID(SUBSTITUTE(LEFT($O14,FIND(" ",$O14&" ")-1),"/",REPT(" ",20)),41,20)),VALUE(LEFT(SUBSTITUTE(LEFT($O14,FIND(" ",$O14&" ")-1),"/",REPT(" ",20)),20)),VALUE(MID(SUBSTITUTE(LEFT($O14,FIND(" ",$O14&" ")-1),"/",REPT(" ",20)),21,20)))),0)>$W14,"Late","Same day")) -> Late | AF14: =IF($A14="","",IFERROR(INDEX(Validation!$C$193:$C$217,MATCH($A14,Validation!$A$193:$A$217,0)),IF(COUNTIF(Validation!$U$19:$U$178,$Z14)>0,$Z14,IF(COUNTIF(Validation!$S$19:$S$178,$AI14)=1,INDEX(Validation!$U$19:$U$178,MATCH($AI14,Validation!$S$19:$S$178,0)),$Z14)))) -> F MONTANEZ | AG14: =IF(COUNTA($A14:$U14)=0,"",IF($A14="","No name",IF($F14="","No date",IF($W14=0,"Date ilegible",IF(NOT(ISNUMBER($N14)),"Hours no numéricas",IF($AA14="NO MATCH","Person no identificada","OK")))))) -> OK | AH14: =IF($W14=0,"No date",IF($W14<Validation!$B$3,"Before period",IF($W14>Validation!$C$3,"After period","In period"))) -> In period | AI14: =IF($Y14="","",TRIM(RIGHT(SUBSTITUTE($Y14," ",REPT(" ",50)),50))) -> MONTANEZ | AJ14: =IF($A14="","",IF(NOT(ISERROR(MATCH($A14,Validation!$A$193:$A$217,0))),"Manual mapping",IF(COUNTIF(Validation!$U$19:$U$178,$Z14)>0,"Direct",IF(COUNTIF(Validation!$S$19:$S$178,$AI14)=1,"By surname","Unresolved")))) -> Direct | AK14: =IF($L14="","",IF(MATCH($L14,$L$2:$L$3000,0)<>ROW()-1,"",COUNT($AK$1:$AK13)+1)) | AL14: =IF($G14="","",IF(MATCH($G14,$G$2:$G$3000,0)<>ROW()-1,"",COUNT($AL$1:$AL13)+1)) | AM14: =IF($H14="","",IF(MATCH($H14,$H$2:$H$3000,0)<>ROW()-1,"",COUNT($AM$1:$AM13)+1)) | AN14: =IF($I14="","",IF(MATCH($I14,$I$2:$I$3000,0)<>ROW()-1,"",COUNT($AN$1:$AN13)+1)) | AO14: =IF($Q14="","",IF(MATCH($Q14,$Q$2:$Q$3000,0)<>ROW()-1,"",COUNT($AO$1:$AO13)+1))
