Workbook

Sheet Inicio
B1: Feria Eva 2026 · Inventario y ventas
B2: Panel de control. Todos los números se actualizan solos.
B4: Inventario | E4: Cómo se usa
B5: Referencias en catálogo | C5: =COUNTIF(Inventario!$C$5:$C$100,"?*") -> 66 | E5: 1. Inventario — el catálogo completo, agrupado por colección y, dentro de cada producto, del tamaño más pequeño al más grande.
B6: Unidades en stock | C6: =SUM(Inventario!$L$5:$L$100) -> 513 | E6: 2. Ventas — una fila por venta: fecha, producto (lista desplegable), cantidad y método de pago. El stock se descuenta solo.
B7: Valor del inventario | C7: =SUM(Inventario!$M$5:$M$100) -> 48700000 | E7: 3. Entradas — una fila cada vez que produces o repones unidades. Solo cantidad, sin costos. El stock sube solo.
B8: Referencias agotadas | C8: =COUNTIF(Inventario!$O$5:$O$100,"AGOTADO") -> 0 | E8: 4. Resumen — totales por colección, por tamaño, por método de pago y por mes, más el top de más vendidos y la reposición sugerida.
B9: Referencias con stock bajo | C9: =COUNTIF(Inventario!$O$5:$O$100,"BAJO") -> 12 | E9: 5. Config — las listas desplegables (colecciones, tamaños, métodos de pago, motivos) y el umbral de stock bajo.
B10: Filas por revisar (stock negativo) | C10: =COUNTIF(Inventario!$O$5:$O$100,"REVISAR") -> 0
E11: AZUL = lo escribes tú. NEGRO = fórmula, no lo borres. AMARILLO = dato pendiente por confirmar.
B12: Ventas
B13: Ventas registradas | C13: =COUNTIF(Ventas!$C$5:$C$504,"?*") -> 0 | E13: No hay códigos ni SKU: en Ventas y en Entradas el producto se elige de una lista que dice, por ejemplo, "Jirafa · Pequeño · Selva".
B14: Unidades vendidas | C14: =SUM(Ventas!$F$5:$F$504) -> 0 | E14: Nunca borres filas del Inventario: si algo se agota queda en 0 y marcado como AGOTADO.
B15: Ingresos totales | C15: =SUM(Ventas!$I$5:$I$504) -> 0 | E15: Para una devolución, registra la cantidad en negativo en la hoja Ventas.
B16: Ticket promedio | C16: =IFERROR($C$15/$C$13,0) -> 0
B17: Recibido en efectivo | C17: =SUMIFS(Ventas!$I$5:$I$504,Ventas!$J$5:$J$504,"Efectivo") -> 0 | E17: Pendientes por confirmar
B18: Recibido en medios digitales | C18: =$C$15-$C$17 -> 0 | E18: • Falta el precio de las 4 referencias de "Corazón" y de las 4 "Cadena de corazones" (están en amarillo en el Inventario).
E19: • "Elefante · Grande · Selva": la cantidad decía 7 pero el detalle sumaba 9 (3 niño - 6 niña).
E20: • "Tilda · Grande · Muñecas" aparecía dos veces; quedaron separadas con la variante "vestido azul" y "navidad y country".
E21: • Las "Cadenas de corazón" se pasaron de la nota suelta del original: revisa cantidades y composición.

Sheet Inventario
B1: Inventario
B2: Escribe solo en las columnas azules. Todo lo negro se calcula solo: las ventas se restan y las entradas se suman al stock.
B4: Referencia (así aparece en Ventas) | C4: Producto | D4: Colección | E4: Tamaño | F4: Variante | G4: Detalle (niño / niña) | H4: Precio unitario | I4: Stock inicial | J4: Entradas | K4: Vendidas | L4: Stock actual | M4: Valor en stock | N4: Ingresos generados | O4: Estado | P4: Orden tamaño | Q4: aux ventas | R4: aux stock
B5: =IF($C5="","",$C5&" · "&$E5&IF($F5=""," "," "&$F5&" ")&"· "&$D5) -> Cebra · Único · Bebé | C5: Cebra | D5: Bebé | E5: Único | G5: 3 niño - 4 niña | H5: 115000 | I5: 7 | J5: =IF($C5="","",SUMIFS(Entradas!$D$5:$D$204,Entradas!$C$5:$C$204,$B5)) -> 0 | K5: =IF($C5="","",SUMIFS(Ventas!$F$5:$F$504,Ventas!$C$5:$C$504,$B5)) -> 0 | L5: =IF($C5="","",N($I5)+N($J5)-N($K5)) -> 7 | M5: =IF($C5="","",N($L5)*N($H5)) -> 805000 | N5: =IF($C5="","",SUMIFS(Ventas!$I$5:$I$504,Ventas!$C$5:$C$504,$B5)) -> 0 | O5: =IF($C5="","",IF($L5<0,"REVISAR",IF($L5=0,"AGOTADO",IF($L5<=Config!$M$6,"BAJO","OK")))) -> OK | P5: =IF($C5="","",IFERROR(INDEX(Config!$E$6:$E$18,MATCH($E5,Config!$D$6:$D$18,0)),"")) -> 5 | Q5: =IF($C5="","",N($K5)+ROW()/1000000) -> 5e-06 | R5: =IF($C5="","",N($L5)+ROW()/1000000) -> 7.000005
B6: =IF($C6="","",$C6&" · "&$E6&IF($F6=""," "," "&$F6&" ")&"· "&$D6) -> Conejo · Único · Bebé | C6: Conejo | D6: Bebé | E6: Único | G6: 6 niño - 6 niña | H6: 115000 | I6: 12 | J6: =IF($C6="","",SUMIFS(Entradas!$D$5:$D$204,Entradas!$C$5:$C$204,$B6)) -> 0 | K6: =IF($C6="","",SUMIFS(Ventas!$F$5:$F$504,Ventas!$C$5:$C$504,$B6)) -> 0 | L6: =IF($C6="","",N($I6)+N($J6)-N($K6)) -> 12 | M6: =IF($C6="","",N($L6)*N($H6)) -> 1380000 | N6: =IF($C6="","",SUMIFS(Ventas!$I$5:$I$504,Ventas!$C$5:$C$504,$B6)) -> 0 | O6: =IF($C6="","",IF($L6<0,"REVISAR",IF($L6=0,"AGOTADO",IF($L6<=Config!$M$6,"BAJO","OK")))) -> OK | P6: =IF($C6="","",IFERROR(INDEX(Config!$E$6:$E$18,MATCH($E6,Config!$D$6:$D$18,0)),"")) -> 5 | Q6: =IF($C6="","",N($K6)+ROW()/1000000) -> 6e-06 | R6: =IF($C6="","",N($L6)+ROW()/1000000) -> 12.000006
B7: =IF($C7="","",$C7&" · "&$E7&IF($F7=""," "," "&$F7&" ")&"· "&$D7) -> Elefante · Único · Bebé | C7: Elefante | D7: Bebé | E7: Único | G7: 6 niño - 6 niña | H7: 115000 | I7: 12 | J7: =IF($C7="","",SUMIFS(Entradas!$D$5:$D$204,Entradas!$C$5:$C$204,$B7)) -> 0 | K7: =IF($C7="","",SUMIFS(Ventas!$F$5:$F$504,Ventas!$C$5:$C$504,$B7)) -> 0 | L7: =IF($C7="","",N($I7)+N($J7)-N($K7)) -> 12 | M7: =IF($C7="","",N($L7)*N($H7)) -> 1380000 | N7: =IF($C7="","",SUMIFS(Ventas!$I$5:$I$504,Ventas!$C$5:$C$504,$B7)) -> 0 | O7: =IF($C7="","",IF($L7<0,"REVISAR",IF($L7=0,"AGOTADO",IF($L7<=Config!$M$6,"BAJO","OK")))) -> OK | P7: =IF($C7="","",IFERROR(INDEX(Config!$E$6:$E$18,MATCH($E7,Config!$D$6:$D$18,0)),"")) -> 5 | Q7: =IF($C7="","",N($K7)+ROW()/1000000) -> 7e-06 | R7: =IF($C7="","",N($L7)+ROW()/1000000) -> 12.000007
B8: =IF($C8="","",$C8&" · "&$E8&IF($F8=""," "," "&$F8&" ")&"· "&$D8) -> Ganso · Único · Bebé | C8: Ganso | D8: Bebé | E8: Único | G8: 6 niño - 6 niña | H8: 115000 | I8: 12 | J8: =IF($C8="","",SUMIFS(Entradas!$D$5:$D$204,Entradas!$C$5:$C$204,$B8)) -> 0 | K8: =IF($C8="","",SUMIFS(Ventas!$F$5:$F$504,Ventas!$C$5:$C$504,$B8)) -> 0 | L8: =IF($C8="","",N($I8)+N($J8)-N($K8)) -> 12 | M8: =IF($C8="","",N($L8)*N($H8)) -> 1380000 | N8: =IF($C8="","",SUMIFS(Ventas!$I$5:$I$504,Ventas!$C$5:$C$504,$B8)) -> 0 | O8: =IF($C8="","",IF($L8<0,"REVISAR",IF($L8=0,"AGOTADO",IF($L8<=Config!$M$6,"BAJO","OK")))) -> OK | P8: =IF($C8="","",IFERROR(INDEX(Config!$E$6:$E$18,MATCH($E8,Config!$D$6:$D$18,0)),"")) -> 5 | Q8: =IF($C8="","",N($K8)+ROW()/1000000) -> 8e-06 | R8: =IF($C8="","",N($L8)+ROW()/1000000) -> 12.000008
B9: =IF($C9="","",$C9&" · "&$E9&IF($F9=""," "," "&$F9&" ")&"· "&$D9) -> Gaviota · Pequeño · Bebé | C9: Gaviota | D9: Bebé | E9: Pequeño | G9: 6 niño/a | H9: 115000 | I9: 6 | J9: =IF($C9="","",SUMIFS(Entradas!$D$5:$D$204,Entradas!$C$5:$C$204,$B9)) -> 0 | K9: =IF($C9="","",SUMIFS(Ventas!$F$5:$F$504,Ventas!$C$5:$C$504,$B9)) -> 0 | L9: =IF($C9="","",N($I9)+N($J9)-N($K9)) -> 6 | M9: =IF($C9="","",N($L9)*N($H9)) -> 690000 | N9: =IF($C9="","",SUMIFS(Ventas!$I$5:$I$504,Ventas!$C$5:$C$504,$B9)) -> 0 | O9: =IF($C9="","",IF($L9<0,"REVISAR",IF($L9=0,"AGOTADO",IF($L9<=Config!$M$6,"BAJO","OK")))) -> OK | P9: =IF($C9="","",IFERROR(INDEX(Config!$E$6:$E$18,MATCH($E9,Config!$D$6:$D$18,0)),"")) -> 2 | Q9: =IF($C9="","",N($K9)+ROW()/1000000) -> 9e-06 | R9: =IF($C9="","",N($L9)+ROW()/1000000) -> 6.000009
B10: =IF($C10="","",$C10&" · "&$E10&IF($F10=""," "," "&$F10&" ")&"· "&$D10) -> Hipopotamo · Único · Bebé | C10: Hipopotamo | D10: Bebé | E10: Único | G10: 5 niño - 6 niña | H10: 115000 | I10: 11 | J10: =IF($C10="","",SUMIFS(Entradas!$D$5:$D$204,Entradas!$C$5:$C$204,$B10)) -> 0 | K10: =IF($C10="","",SUMIFS(Ventas!$F$5:$F$504,Ventas!$C$5:$C$504,$B10)) -> 0 | L10: =IF($C10="","",N($I10)+N($J10)-N($K10)) -> 11 | M10: =IF($C10="","",N($L10)*N($H10)) -> 1265000 | N10: =IF($C10="","",SUMIFS(Ventas!$I$5:$I$504,Ventas!$C$5:$C$504,$B10)) -> 0 | O10: =IF($C10="","",IF($L10<0,"REVISAR",IF($L10=0,"AGOTADO",IF($L10<=Config!$M$6,"BAJO","OK")))) -> OK | P10: =IF($C10="","",IFERROR(INDEX(Config!$E$6:$E$18,MATCH($E10,Config!$D$6:$D$18,0)),"")) -> 5 | Q10: =IF($C10="","",N($K10)+ROW()/1000000) -> 1e-05 | R10: =IF($C10="","",N($L10)+ROW()/1000000) -> 11.00001
B11: =IF($C11="","",$C11&" · "&$E11&IF($F11=""," "," "&$F11&" ")&"· "&$D11) -> Oso · Único · Bebé | C11: Oso | D11: Bebé | E11: Único | G11: 3 niño - 3 niña | H11: 115000 | I11: 6 | J11: =IF($C11="","",SUMIFS(Entradas!$D$5:$D$204,Entradas!$C$5:$C$204,$B11)) -> 0 | K11: =IF($C11="","",SUMIFS(Ventas!$F$5:$F$504,Ventas!$C$5:$C$504,$B11)) -> 0 | L11: =IF($C11="","",N($I11)+N($J11)-N($K11)) -> 6 | M11: =IF($C11="","",N($L11)*N($H11)) -> 690000 | N11: =IF($C11="","",SUMIFS(Ventas!$I$5:$I$504,Ventas!$C$5:$C$504,$B11)) -> 0 | O11: =IF($C11="","",IF($L11<0,"REVISAR",IF($L11=0,"AGOTADO",IF($L11<=Config!$M$6,"BAJO","OK")))) -> OK | P11: =IF($C11="","",IFERROR(INDEX(Config!$E$6:$E$18,MATCH($E11,Config!$D$6:$D$18,0)),"")) -> 5 | Q11: =IF($C11="","",N($K11)+ROW()/1000000) -> 1.1e-05 | R11: =IF($C11="","",N($L11)+ROW()/1000000) -> 6.000011
B12: =IF($C12="","",$C12&" · "&$E12&IF($F12=""," "," "&$F12&" ")&"· "&$D12) -> Pato · Mediano · Bebé | C12: Pato | D12: Bebé | E12: Mediano | G12: 1 | H12: 115000 | I12: 1 | J12: =IF($C12="","",SUMIFS(Entradas!$D$5:$D$204,Entradas!$C$5:$C$204,$B12)) -> 0 | K12: =IF($C12="","",SUMIFS(Ventas!$F$5:$F$504,Ventas!$C$5:$C$504,$B12)) -> 0 | L12: =IF($C12="","",N($I12)+N($J12)-N($K12)) -> 1 | M12: =IF($C12="","",N($L12)*N($H12)) -> 115000 | N12: =IF($C12="","",SUMIFS(Ventas!$I$5:$I$504,Ventas!$C$5:$C$504,$B12)) -> 0 | O12: =IF($C12="","",IF($L12<0,"REVISAR",IF($L12=0,"AGOTADO",IF($L12<=Config!$M$6,"BAJO","OK")))) -> BAJO | P12: =IF($C12="","",IFERROR(INDEX(Config!$E$6:$E$18,MATCH($E12,Config!$D$6:$D$18,0)),"")) -> 3 | Q12: =IF($C12="","",N($K12)+ROW()/1000000) -> 1.2e-05 | R12: =IF($C12="","",N($L12)+ROW()/1000000) -> 1.000012
B13: =IF($C13="","",$C13&" · "&$E13&IF($F13=""," "," "&$F13&" ")&"· "&$D13) -> Pato · Grande · Bebé | C13: Pato | D13: Bebé | E13: Grande | G13: 1 | H13: 115000 | I13: 1 | J13: =IF($C13="","",SUMIFS(Entradas!$D$5:$D$204,Entradas!$C$5:$C$204,$B13)) -> 0 | K13: =IF($C13="","",SUMIFS(Ventas!$F$5:$F$504,Ventas!$C$5:$C$504,$B13)) -> 0 | L13: =IF($C13="","",N($I13)+N($J13)-N($K13)) -> 1 | M13: =IF($C13="","",N($L13)*N($H13)) -> 115000 | N13: =IF($C13="","",SUMIFS(Ventas!$I$5:$I$504,Ventas!$C$5:$C$504,$B13)) -> 0 | O13: =IF($C13="","",IF($L13<0,"REVISAR",IF($L13=0,"AGOTADO",IF($L13<=Config!$M$6,"BAJO","OK")))) -> BAJO | P13: =IF($C13="","",IFERROR(INDEX(Config!$E$6:$E$18,MATCH($E13,Config!$D$6:$D$18,0)),"")) -> 4 | Q13: =IF($C13="","",N($K13)+ROW()/1000000) -> 1.3e-05 | R13: =IF($C13="","",N($L13)+ROW()/1000000) -> 1.000013
B14: =IF($C14="","",$C14&" · "&$E14&IF($F14=""," "," "&$F14&" ")&"· "&$D14) -> Pato dormilón · Único · Bebé | C14: Pato dormilón | D14: Bebé | E14: Único | G14: 3 | H14: 115000 | I14: 3 | J14: =IF($C14="","",SUMIFS(Entradas!$D$5:$D$204,Entradas!$C$5:$C$204,$B14)) -> 0 | K14: =IF($C14="","",SUMIFS(Ventas!$F$5:$F$504,Ventas!$C$5:$C$504,$B14)) -> 0 | L14: =IF($C14="","",N($I14)+N($J14)-N($K14)) -> 3 | M14: =IF($C14="","",N($L14)*N($H14)) -> 345000 | N14: =IF($C14="","",SUMIFS(Ventas!$I$5:$I$504,Ventas!$C$5:$C$504,$B14)) -> 0 | O14: =IF($C14="","",IF($L14<0,"REVISAR",IF($L14=0,"AGOTADO",IF($L14<=Config!$M$6,"BAJO","OK")))) -> BAJO | P14: =IF($C14="","",IFERROR(INDEX(Config!$E$6:$E$18,MATCH($E14,Config!$D$6:$D$18,0)),"")) -> 5 | Q14: =IF($C14="","",N($K14)+ROW()/1000000) -> 1.4e-05 | R14: =IF($C14="","",N($L14)+ROW()/1000000) -> 3.000014
B15: =IF($C15="","",$C15&" · "&$E15&IF($F15=""," "," "&$F15&" ")&"· "&$D15) -> Perro · Único · Bebé | C15: Perro | D15: Bebé | E15: Único | G15: 3 niño - 3 niña | H15: 115000 | I15: 6 | J15: =IF($C15="","",SUMIFS(Entradas!$D$5:$D$204,Entradas!$C$5:$C$204,$B15)) -> 0 | K15: =IF($C15="","",SUMIFS(Ventas!$F$5:$F$504,Ventas!$C$5:$C$504,$B15)) -> 0 | L15: =IF($C15="","",N($I15)+N($J15)-N($K15)) -> 6 | M15: =IF($C15="","",N($L15)*N($H15)) -> 690000 | N15: =IF($C15="","",SUMIFS(Ventas!$I$5:$I$504,Ventas!$C$5:$C$504,$B15)) -> 0 | O15: =IF($C15="","",IF($L15<0,"REVISAR",IF($L15=0,"AGOTADO",IF($L15<=Config!$M$6,"BAJO","OK")))) -> OK | P15: =IF($C15="","",IFERROR(INDEX(Config!$E$6:$E$18,MATCH($E15,Config!$D$6:$D$18,0)),"")) -> 5 | Q15: =IF($C15="","",N($K15)+ROW()/1000000) -> 1.5e-05 | R15: =IF($C15="","",N($L15)+ROW()/1000000) -> 6.000015
B16: =IF($C16="","",$C16&" · "&$E16&IF($F16=""," "," "&$F16&" ")&"· "&$D16) -> Ratón · Único · Bebé | C16: Ratón | D16: Bebé | E16: Único | G16: 3 niño - 3 niña | H16: 115000 | I16: 6 | J16: =IF($C16="","",SUMIFS(Entradas!$D$5:$D$204,Entradas!$C$5:$C$204,$B16)) -> 0 | K16: =IF($C16="","",SUMIFS(Ventas!$F$5:$F$504,Ventas!$C$5:$C$504,$B16)) -> 0 | L16: =IF($C16="","",N($I16)+N($J16)-N($K16)) -> 6 | M16: =IF($C16="","",N($L16)*N($H16)) -> 690000 | N16: =IF($C16="","",SUMIFS(Ventas!$I$5:$I$504,Ventas!$C$5:$C$504,$B16)) -> 0 | O16: =IF($C16="","",IF($L16<0,"REVISAR",IF($L16=0,"AGOTADO",IF($L16<=Config!$M$6,"BAJO","OK")))) -> OK | P16: =IF($C16="","",IFERROR(INDEX(Config!$E$6:$E$18,MATCH($E16,Config!$D$6:$D$18,0)),"")) -> 5 | Q16: =IF($C16="","",N($K16)+ROW()/1000000) -> 1.6e-05 | R16: =IF($C16="","",N($L16)+ROW()/1000000) -> 6.000016
... B48: =IF($C48="","",$C48&" · "&$E48&IF($F48=""," "," "&$F48&" ")&"· "&$D48) -> Puka · Único · Muñecas | C48: Puka | D48: Muñecas | E48: Único | G48: 5 | H48: 115000 | I48: 5 | J48: =IF($C48="","",SUMIFS(Entradas!$D$5:$D$204,Entradas!$C$5:$C$204,$B48)) -> 0 | K48: =IF($C48="","",SUMIFS(Ventas!$F$5:$F$504,Ventas!$C$5:$C$504,$B48)) -> 0 | L48: =IF($C48="","",N($I48)+N($J48)-N($K48)) -> 5 | M48: =IF($C48="","",N($L48)*N($H48)) -> 575000 | N48: =IF($C48="","",SUMIFS(Ventas!$I$5:$I$504,Ventas!$C$5:$C$504,$B48)) -> 0 | O48: =IF($C48="","",IF($L48<0,"REVISAR",IF($L48=0,"AGOTADO",IF($L48<=Config!$M$6,"BAJO","OK")))) -> OK | P48: =IF($C48="","",IFERROR(INDEX(Config!$E$6:$E$18,MATCH($E48,Config!$D$6:$D$18,0)),"")) -> 5 | Q48: =IF($C48="","",N($K48)+ROW()/1000000) -> 4.8e-05 | R48: =IF($C48="","",N($L48)+ROW()/1000000) -> 5.000048
B49: =IF($C49="","",$C49&" · "&$E49&IF($F49=""," "," "&$F49&" ")&"· "&$D49) -> Tilda · Grande navidad y country · Muñecas | C49: Tilda | D49: Muñecas | E49: Grande | F49: navidad y country | G49: 4 navidad - 4 country | H49: 200000 | I49: 8 | J49: =IF($C49="","",SUMIFS(Entradas!$D$5:$D$204,Entradas!$C$5:$C$204,$B49)) -> 0 | K49: =IF($C49="","",SUMIFS(Ventas!$F$5:$F$504,Ventas!$C$5:$C$504,$B49)) -> 0 | L49: =IF($C49="","",N($I49)+N($J49)-N($K49)) -> 8 | M49: =IF($C49="","",N($L49)*N($H49)) -> 1600000 | N49: =IF($C49="","",SUMIFS(Ventas!$I$5:$I$504,Ventas!$C$5:$C$504,$B49)) -> 0 | O49: =IF($C49="","",IF($L49<0,"REVISAR",IF($L49=0,"AGOTADO",IF($L49<=Config!$M$6,"BAJO","OK")))) -> OK | P49: =IF($C49="","",IFERROR(INDEX(Config!$E$6:$E$18,MATCH($E49,Config!$D$6:$D$18,0)),"")) -> 4 | Q49: =IF($C49="","",N($K49)+ROW()/1000000) -> 4.9e-05 | R49: =IF($C49="","",N($L49)+ROW()/1000000) -> 8.000049
B50: =IF($C50="","",$C50&" · "&$E50&IF($F50=""," "," "&$F50&" ")&"· "&$D50) -> Tilda · Grande vestido azul · Muñecas | C50: Tilda | D50: Muñecas | E50: Grande | F50: vestido azul | G50: 7 vestido azul | H50: 200000 | I50: 7 | J50: =IF($C50="","",SUMIFS(Entradas!$D$5:$D$204,Entradas!$C$5:$C$204,$B50)) -> 0 | K50: =IF($C50="","",SUMIFS(Ventas!$F$5:$F$504,Ventas!$C$5:$C$504,$B50)) -> 0 | L50: =IF($C50="","",N($I50)+N($J50)-N($K50)) -> 7 | M50: =IF($C50="","",N($L50)*N($H50)) -> 1400000 | N50: =IF($C50="","",SUMIFS(Ventas!$I$5:$I$504,Ventas!$C$5:$C$504,$B50)) -> 0 | O50: =IF($C50="","",IF($L50<0,"REVISAR",IF($L50=0,"AGOTADO",IF($L50<=Config!$M$6,"BAJO","OK")))) -> OK | P50: =IF($C50="","",IFERROR(INDEX(Config!$E$6:$E$18,MATCH($E50,Config!$D$6:$D$18,0)),"")) -> 4 | Q50: =IF($C50="","",N($K50)+ROW()/1000000) -> 5e-05 | R50: =IF($C50="","",N($L50)+ROW()/1000000) -> 7.00005
B51: =IF($C51="","",$C51&" · "&$E51&IF($F51=""," "," "&$F51&" ")&"· "&$D51) -> Papá Noel Bernabela · Pequeño · Navidad | C51: Papá Noel Bernabela | D51: Navidad | E51: Pequeño | G51: 2 | H51: 150000 | I51: 2 | J51: =IF($C51="","",SUMIFS(Entradas!$D$5:$D$204,Entradas!$C$5:$C$204,$B51)) -> 0 | K51: =IF($C51="","",SUMIFS(Ventas!$F$5:$F$504,Ventas!$C$5:$C$504,$B51)) -> 0 | L51: =IF($C51="","",N($I51)+N($J51)-N($K51)) -> 2 | M51: =IF($C51="","",N($L51)*N($H51)) -> 300000 | N51: =IF($C51="","",SUMIFS(Ventas!$I$5:$I$504,Ventas!$C$5:$C$504,$B51)) -> 0 | O51: =IF($C51="","",IF($L51<0,"REVISAR",IF($L51=0,"AGOTADO",IF($L51<=Config!$M$6,"BAJO","OK")))) -> BAJO | P51: =IF($C51="","",IFERROR(INDEX(Config!$E$6:$E$18,MATCH($E51,Config!$D$6:$D$18,0)),"")) -> 2 | Q51: =IF($C51="","",N($K51)+ROW()/1000000) -> 5.1e-05 | R51: =IF($C51="","",N($L51)+ROW()/1000000) -> 2.000051
B52: =IF($C52="","",$C52&" · "&$E52&IF($F52=""," "," "&$F52&" ")&"· "&$D52) -> Papá Noel Bernabela · Grande · Navidad | C52: Papá Noel Bernabela | D52: Navidad | E52: Grande | G52: 2 | H52: 250000 | I52: 2 | J52: =IF($C52="","",SUMIFS(Entradas!$D$5:$D$204,Entradas!$C$5:$C$204,$B52)) -> 0 | K52: =IF($C52="","",SUMIFS(Ventas!$F$5:$F$504,Ventas!$C$5:$C$504,$B52)) -> 0 | L52: =IF($C52="","",N($I52)+N($J52)-N($K52)) -> 2 | M52: =IF($C52="","",N($L52)*N($H52)) -> 500000 | N52: =IF($C52="","",SUMIFS(Ventas!$I$5:$I$504,Ventas!$C$5:$C$504,$B52)) -> 0 | O52: =IF($C52="","",IF($L52<0,"REVISAR",IF($L52=0,"AGOTADO",IF($L52<=Config!$M$6,"BAJO","OK")))) -> BAJO | P52: =IF($C52="","",IFERROR(INDEX(Config!$E$6:$E$18,MATCH($E52,Config!$D$6:$D$18,0)),"")) -> 4 | Q52: =IF($C52="","",N($K52)+ROW()/1000000) -> 5.2e-05 | R52: =IF($C52="","",N($L52)+ROW()/1000000) -> 2.000052
B53: =IF($C53="","",$C53&" · "&$E53&IF($F53=""," "," "&$F53&" ")&"· "&$D53) -> Papá Noel pijama · Único · Navidad | C53: Papá Noel pijama | D53: Navidad | E53: Único | G53: 9 niño/a | H53: 90000 | I53: 9 | J53: =IF($C53="","",SUMIFS(Entradas!$D$5:$D$204,Entradas!$C$5:$C$204,$B53)) -> 0 | K53: =IF($C53="","",SUMIFS(Ventas!$F$5:$F$504,Ventas!$C$5:$C$504,$B53)) -> 0 | L53: =IF($C53="","",N($I53)+N($J53)-N($K53)) -> 9 | M53: =IF($C53="","",N($L53)*N($H53)) -> 810000 | N53: =IF($C53="","",SUMIFS(Ventas!$I$5:$I$504,Ventas!$C$5:$C$504,$B53)) -> 0 | O53: =IF($C53="","",IF($L53<0,"REVISAR",IF($L53=0,"AGOTADO",IF($L53<=Config!$M$6,"BAJO","OK")))) -> OK | P53: =IF($C53="","",IFERROR(INDEX(Config!$E$6:$E$18,MATCH($E53,Config!$D$6:$D$18,0)),"")) -> 5 | Q53: =IF($C53="","",N($K53)+ROW()/1000000) -> 5.3e-05 | R53: =IF($C53="","",N($L53)+ROW()/1000000) -> 9.000053
B54: =IF($C54="","",$C54&" · "&$E54&IF($F54=""," "," "&$F54&" ")&"· "&$D54) -> Cadena de corazones · Mini · Otros | C54: Cadena de corazones | D54: Otros | E54: Mini | G54: 3 corazones | I54: 1 | J54: =IF($C54="","",SUMIFS(Entradas!$D$5:$D$204,Entradas!$C$5:$C$204,$B54)) -> 0 | K54: =IF($C54="","",SUMIFS(Ventas!$F$5:$F$504,Ventas!$C$5:$C$504,$B54)) -> 0 | L54: =IF($C54="","",N($I54)+N($J54)-N($K54)) -> 1 | M54: =IF($C54="","",N($L54)*N($H54)) -> 0 | N54: =IF($C54="","",SUMIFS(Ventas!$I$5:$I$504,Ventas!$C$5:$C$504,$B54)) -> 0 | O54: =IF($C54="","",IF($L54<0,"REVISAR",IF($L54=0,"AGOTADO",IF($L54<=Config!$M$6,"BAJO","OK")))) -> BAJO | P54: =IF($C54="","",IFERROR(INDEX(Config!$E$6:$E$18,MATCH($E54,Config!$D$6:$D$18,0)),"")) -> 1 | Q54: =IF($C54="","",N($K54)+ROW()/1000000) -> 5.4e-05 | R54: =IF($C54="","",N($L54)+ROW()/1000000) -> 1.000054
B55: =IF($C55="","",$C55&" · "&$E55&IF($F55=""," "," "&$F55&" ")&"· "&$D55) -> Cadena de corazones · Pequeño · Otros | C55: Cadena de corazones | D55: Otros | E55: Pequeño | G55: 3 corazones cada una | I55: 3 | J55: =IF($C55="","",SUMIFS(Entradas!$D$5:$D$204,Entradas!$C$5:$C$204,$B55)) -> 0 | K55: =IF($C55="","",SUMIFS(Ventas!$F$5:$F$504,Ventas!$C$5:$C$504,$B55)) -> 0 | L55: =IF($C55="","",N($I55)+N($J55)-N($K55)) -> 3 | M55: =IF($C55="","",N($L55)*N($H55)) -> 0 | N55: =IF($C55="","",SUMIFS(Ventas!$I$5:$I$504,Ventas!$C$5:$C$504,$B55)) -> 0 | O55: =IF($C55="","",IF($L55<0,"REVISAR",IF($L55=0,"AGOTADO",IF($L55<=Config!$M$6,"BAJO","OK")))) -> BAJO | P55: =IF($C55="","",IFERROR(INDEX(Config!$E$6:$E$18,MATCH($E55,Config!$D$6:$D$18,0)),"")) -> 2 | Q55: =IF($C55="","",N($K55)+ROW()/1000000) -> 5.5e-05 | R55: =IF($C55="","",N($L55)+ROW()/1000000) -> 3.000055
B56: =IF($C56="","",$C56&" · "&$E56&IF($F56=""," "," "&$F56&" ")&"· "&$D56) -> Cadena de corazones · Mediano · Otros | C56: Cadena de corazones | D56: Otros | E56: Mediano | G56: 4 corazones | I56: 1 | J56: =IF($C56="","",SUMIFS(Entradas!$D$5:$D$204,Entradas!$C$5:$C$204,$B56)) -> 0 | K56: =IF($C56="","",SUMIFS(Ventas!$F$5:$F$504,Ventas!$C$5:$C$504,$B56)) -> 0 | L56: =IF($C56="","",N($I56)+N($J56)-N($K56)) -> 1 | M56: =IF($C56="","",N($L56)*N($H56)) -> 0 | N56: =IF($C56="","",SUMIFS(Ventas!$I$5:$I$504,Ventas!$C$5:$C$504,$B56)) -> 0 | O56: =IF($C56="","",IF($L56<0,"REVISAR",IF($L56=0,"AGOTADO",IF($L56<=Config!$M$6,"BAJO","OK")))) -> BAJO | P56: =IF($C56="","",IFERROR(INDEX(Config!$E$6:$E$18,MATCH($E56,Config!$D$6:$D$18,0)),"")) -> 3 | Q56: =IF($C56="","",N($K56)+ROW()/1000000) -> 5.6e-05 | R56: =IF($C56="","",N($L56)+ROW()/1000000) -> 1.000056
B57: =IF($C57="","",$C57&" · "&$E57&IF($F57=""," "," "&$F57&" ")&"· "&$D57) -> Cadena de corazones · Único mixta · Otros | C57: Cadena de corazones | D57: Otros | E57: Único | F57: mixta | G57: 1 corazón grande + 2 pequeños | I57: 1 | J57: =IF($C57="","",SUMIFS(Entradas!$D$5:$D$204,Entradas!$C$5:$C$204,$B57)) -> 0 | K57: =IF($C57="","",SUMIFS(Ventas!$F$5:$F$504,Ventas!$C$5:$C$504,$B57)) -> 0 | L57: =IF($C57="","",N($I57)+N($J57)-N($K57)) -> 1 | M57: =IF($C57="","",N($L57)*N($H57)) -> 0 | N57: =IF($C57="","",SUMIFS(Ventas!$I$5:$I$504,Ventas!$C$5:$C$504,$B57)) -> 0 | O57: =IF($C57="","",IF($L57<0,"REVISAR",IF($L57=0,"AGOTADO",IF($L57<=Config!$M$6,"BAJO","OK")))) -> BAJO | P57: =IF($C57="","",IFERROR(INDEX(Config!$E$6:$E$18,MATCH($E57,Config!$D$6:$D$18,0)),"")) -> 5 | Q57: =IF($C57="","",N($K57)+ROW()/1000000) -> 5.7e-05 | R57: =IF($C57="","",N($L57)+ROW()/1000000) -> 1.000057
B58: =IF($C58="","",$C58&" · "&$E58&IF($F58=""," "," "&$F58&" ")&"· "&$D58) -> Corazón · Mini · Otros | C58: Corazón | D58: Otros | E58: Mini | G58: 19 | I58: 19 | J58: =IF($C58="","",SUMIFS(Entradas!$D$5:$D$204,Entradas!$C$5:$C$204,$B58)) -> 0 | K58: =IF($C58="","",SUMIFS(Ventas!$F$5:$F$504,Ventas!$C$5:$C$504,$B58)) -> 0 | L58: =IF($C58="","",N($I58)+N($J58)-N($K58)) -> 19 | M58: =IF($C58="","",N($L58)*N($H58)) -> 0 | N58: =IF($C58="","",SUMIFS(Ventas!$I$5:$I$504,Ventas!$C$5:$C$504,$B58)) -> 0 | O58: =IF($C58="","",IF($L58<0,"REVISAR",IF($L58=0,"AGOTADO",IF($L58<=Config!$M$6,"BAJO","OK")))) -> OK | P58: =IF($C58="","",IFERROR(INDEX(Config!$E$6:$E$18,MATCH($E58,Config!$D$6:$D$18,0)),"")) -> 1 | Q58: =IF($C58="","",N($K58)+ROW()/1000000) -> 5.8e-05 | R58: =IF($C58="","",N($L58)+ROW()/1000000) -> 19.000058
B59: =IF($C59="","",$C59&" · "&$E59&IF($F59=""," "," "&$F59&" ")&"· "&$D59) -> Corazón · Pequeño · Otros | C59: Corazón | D59: Otros | E59: Pequeño | G59: 41 | I59: 41 | J59: =IF($C59="","",SUMIFS(Entradas!$D$5:$D$204,Entradas!$C$5:$C$204,$B59)) -> 0 | K59: =IF($C59="","",SUMIFS(Ventas!$F$5:$F$504,Ventas!$C$5:$C$504,$B59)) -> 0 | L59: =IF($C59="","",N($I59)+N($J59)-N($K59)) -> 41 | M59: =IF($C59="","",N($L59)*N($H59)) -> 0 | N59: =IF($C59="","",SUMIFS(Ventas!$I$5:$I$504,Ventas!$C$5:$C$504,$B59)) -> 0 | O59: =IF($C59="","",IF($L59<0,"REVISAR",IF($L59=0,"AGOTADO",IF($L59<=Config!$M$6,"BAJO","OK")))) -> OK | P59: =IF($C59="","",IFERROR(INDEX(Config!$E$6:$E$18,MATCH($E59,Config!$D$6:$D$18,0)),"")) -> 2 | Q59: =IF($C59="","",N($K59)+ROW()/1000000) -> 5.9e-05 | R59: =IF($C59="","",N($L59)+ROW()/1000000) -> 41.000059
B60: =IF($C60="","",$C60&" · "&$E60&IF($F60=""," "," "&$F60&" ")&"· "&$D60) -> Corazón · Mediano · Otros | C60: Corazón | D60: Otros | E60: Mediano | G60: 10 | I60: 10 | J60: =IF($C60="","",SUMIFS(Entradas!$D$5:$D$204,Entradas!$C$5:$C$204,$B60)) -> 0 | K60: =IF($C60="","",SUMIFS(Ventas!$F$5:$F$504,Ventas!$C$5:$C$504,$B60)) -> 0 | L60: =IF($C60="","",N($I60)+N($J60)-N($K60)) -> 10 | M60: =IF($C60="","",N($L60)*N($H60)) -> 0 | N60: =IF($C60="","",SUMIFS(Ventas!$I$5:$I$504,Ventas!$C$5:$C$504,$B60)) -> 0 | O60: =IF($C60="","",IF($L60<0,"REVISAR",IF($L60=0,"AGOTADO",IF($L60<=Config!$M$6,"BAJO","OK")))) -> OK | P60: =IF($C60="","",IFERROR(INDEX(Config!$E$6:$E$18,MATCH($E60,Config!$D$6:$D$18,0)),"")) -> 3 | Q60: =IF($C60="","",N($K60)+ROW()/1000000) -> 6e-05 | R60: =IF($C60="","",N($L60)+ROW()/1000000) -> 10.00006
B61: =IF($C61="","",$C61&" · "&$E61&IF($F61=""," "," "&$F61&" ")&"· "&$D61) -> Corazón · Grande · Otros | C61: Corazón | D61: Otros | E61: Grande | G61: 5 | I61: 5 | J61: =IF($C61="","",SUMIFS(Entradas!$D$5:$D$204,Entradas!$C$5:$C$204,$B61)) -> 0 | K61: =IF($C61="","",SUMIFS(Ventas!$F$5:$F$504,Ventas!$C$5:$C$504,$B61)) -> 0 | L61: =IF($C61="","",N($I61)+N($J61)-N($K61)) -> 5 | M61: =IF($C61="","",N($L61)*N($H61)) -> 0 | N61: =IF($C61="","",SUMIFS(Ventas!$I$5:$I$504,Ventas!$C$5:$C$504,$B61)) -> 0 | O61: =IF($C61="","",IF($L61<0,"REVISAR",IF($L61=0,"AGOTADO",IF($L61<=Config!$M$6,"BAJO","OK")))) -> OK | P61: =IF($C61="","",IFERROR(INDEX(Config!$E$6:$E$18,MATCH($E61,Config!$D$6:$D$18,0)),"")) -> 4 | Q61: =IF($C61="","",N($K61)+ROW()/1000000) -> 6.1e-05 | R61: =IF($C61="","",N($L61)+ROW()/1000000) -> 5.000061
B62: =IF($C62="","",$C62&" · "&$E62&IF($F62=""," "," "&$F62&" ")&"· "&$D62) -> Abejas · Único · Selva | C62: Abejas | D62: Selva | E62: Único | G62: 3 | H62: 115000 | I62: 3 | J62: =IF($C62="","",SUMIFS(Entradas!$D$5:$D$204,Entradas!$C$5:$C$204,$B62)) -> 0 | K62: =IF($C62="","",SUMIFS(Ventas!$F$5:$F$504,Ventas!$C$5:$C$504,$B62)) -> 0 | L62: =IF($C62="","",N($I62)+N($J62)-N($K62)) -> 3 | M62: =IF($C62="","",N($L62)*N($H62)) -> 345000 | N62: =IF($C62="","",SUMIFS(Ventas!$I$5:$I$504,Ventas!$C$5:$C$504,$B62)) -> 0 | O62: =IF($C62="","",IF($L62<0,"REVISAR",IF($L62=0,"AGOTADO",IF($L62<=Config!$M$6,"BAJO","OK")))) -> BAJO | P62: =IF($C62="","",IFERROR(INDEX(Config!$E$6:$E$18,MATCH($E62,Config!$D$6:$D$18,0)),"")) -> 5 | Q62: =IF($C62="","",N($K62)+ROW()/1000000) -> 6.2e-05 | R62: =IF($C62="","",N($L62)+ROW()/1000000) -> 3.000062
B63: =IF($C63="","",$C63&" · "&$E63&IF($F63=""," "," "&$F63&" ")&"· "&$D63) -> Cebra · Grande · Selva | C63: Cebra | D63: Selva | E63: Grande | G63: 2 niño - 2 niña | H63: 110000 | I63: 4 | J63: =IF($C63="","",SUMIFS(Entradas!$D$5:$D$204,Entradas!$C$5:$C$204,$B63)) -> 0 | K63: =IF($C63="","",SUMIFS(Ventas!$F$5:$F$504,Ventas!$C$5:$C$504,$B63)) -> 0 | L63: =IF($C63="","",N($I63)+N($J63)-N($K63)) -> 4 | M63: =IF($C63="","",N($L63)*N($H63)) -> 440000 | N63: =IF($C63="","",SUMIFS(Ventas!$I$5:$I$504,Ventas!$C$5:$C$504,$B63)) -> 0 | O63: =IF($C63="","",IF($L63<0,"REVISAR",IF($L63=0,"AGOTADO",IF($L63<=Config!$M$6,"BAJO","OK")))) -> OK | P63: =IF($C63="","",IFERROR(INDEX(Config!$E$6:$E$18,MATCH($E63,Config!$D$6:$D$18,0)),"")) -> 4 | Q63: =IF($C63="","",N($K63)+ROW()/1000000) -> 6.3e-05 | R63: =IF($C63="","",N($L63)+ROW()/1000000) -> 4.000063
B64: =IF($C64="","",$C64&" · "&$E64&IF($F64=""," "," "&$F64&" ")&"· "&$D64) -> Elefante · Pequeño · Selva | C64: Elefante | D64: Selva | E64: Pequeño | G64: 3 niño - 2 niña | H64: 115000 | I64: 5 | J64: =IF($C64="","",SUMIFS(Entradas!$D$5:$D$204,Entradas!$C$5:$C$204,$B64)) -> 0 | K64: =IF($C64="","",SUMIFS(Ventas!$F$5:$F$504,Ventas!$C$5:$C$504,$B64)) -> 0 | L64: =IF($C64="","",N($I64)+N($J64)-N($K64)) -> 5 | M64: =IF($C64="","",N($L64)*N($H64)) -> 575000 | N64: =IF($C64="","",SUMIFS(Ventas!$I$5:$I$504,Ventas!$C$5:$C$504,$B64)) -> 0 | O64: =IF($C64="","",IF($L64<0,"REVISAR",IF($L64=0,"AGOTADO",IF($L64<=Config!$M$6,"BAJO","OK")))) -> OK | P64: =IF($C64="","",IFERROR(INDEX(Config!$E$6:$E$18,MATCH($E64,Config!$D$6:$D$18,0)),"")) -> 2 | Q64: =IF($C64="","",N($K64)+ROW()/1000000) -> 6.4e-05 | R64: =IF($C64="","",N($L64)+ROW()/1000000) -> 5.000064
B65: =IF($C65="","",$C65&" · "&$E65&IF($F65=""," "," "&$F65&" ")&"· "&$D65) -> Elefante · Grande · Selva | C65: Elefante | D65: Selva | E65: Grande | G65: 3 niño - 6 niña | H65: 140000 | I65: 7 | J65: =IF($C65="","",SUMIFS(Entradas!$D$5:$D$204,Entradas!$C$5:$C$204,$B65)) -> 0 | K65: =IF($C65="","",SUMIFS(Ventas!$F$5:$F$504,Ventas!$C$5:$C$504,$B65)) -> 0 | L65: =IF($C65="","",N($I65)+N($J65)-N($K65)) -> 7 | M65: =IF($C65="","",N($L65)*N($H65)) -> 980000 | N65: =IF($C65="","",SUMIFS(Ventas!$I$5:$I$504,Ventas!$C$5:$C$504,$B65)) -> 0 | O65: =IF($C65="","",IF($L65<0,"REVISAR",IF($L65=0,"AGOTADO",IF($L65<=Config!$M$6,"BAJO","OK")))) -> OK | P65: =IF($C65="","",IFERROR(INDEX(Config!$E$6:$E$18,MATCH($E65,Config!$D$6:$D$18,0)),"")) -> 4 | Q65: =IF($C65="","",N($K65)+ROW()/1000000) -> 6.5e-05 | R65: =IF($C65="","",N($L65)+ROW()/1000000) -> 7.000065
B66: =IF($C66="","",$C66&" · "&$E66&IF($F66=""," "," "&$F66&" ")&"· "&$D66) -> Jirafa · Pequeño · Selva | C66: Jirafa | D66: Selva | E66: Pequeño | G66: 4 niño - 3 niña | H66: 115000 | I66: 7 | J66: =IF($C66="","",SUMIFS(Entradas!$D$5:$D$204,Entradas!$C$5:$C$204,$B66)) -> 0 | K66: =IF($C66="","",SUMIFS(Ventas!$F$5:$F$504,Ventas!$C$5:$C$504,$B66)) -> 0 | L66: =IF($C66="","",N($I66)+N($J66)-N($K66)) -> 7 | M66: =IF($C66="","",N($L66)*N($H66)) -> 805000 | N66: =IF($C66="","",SUMIFS(Ventas!$I$5:$I$504,Ventas!$C$5:$C$504,$B66)) -> 0 | O66: =IF($C66="","",IF($L66<0,"REVISAR",IF($L66=0,"AGOTADO",IF($L66<=Config!$M$6,"BAJO","OK")))) -> OK | P66: =IF($C66="","",IFERROR(INDEX(Config!$E$6:$E$18,MATCH($E66,Config!$D$6:$D$18,0)),"")) -> 2 | Q66: =IF($C66="","",N($K66)+ROW()/1000000) -> 6.6e-05 | R66: =IF($C66="","",N($L66)+ROW()/1000000) -> 7.000066
B67: =IF($C67="","",$C67&" · "&$E67&IF($F67=""," "," "&$F67&" ")&"· "&$D67) -> Jirafa · Grande · Selva | C67: Jirafa | D67: Selva | E67: Grande | G67: 3 niño - 3 niña | H67: 140000 | I67: 6 | J67: =IF($C67="","",SUMIFS(Entradas!$D$5:$D$204,Entradas!$C$5:$C$204,$B67)) -> 0 | K67: =IF($C67="","",SUMIFS(Ventas!$F$5:$F$504,Ventas!$C$5:$C$504,$B67)) -> 0 | L67: =IF($C67="","",N($I67)+N($J67)-N($K67)) -> 6 | M67: =IF($C67="","",N($L67)*N($H67)) -> 840000 | N67: =IF($C67="","",SUMIFS(Ventas!$I$5:$I$504,Ventas!$C$5:$C$504,$B67)) -> 0 | O67: =IF($C67="","",IF($L67<0,"REVISAR",IF($L67=0,"AGOTADO",IF($L67<=Config!$M$6,"BAJO","OK")))) -> OK | P67: =IF($C67="","",IFERROR(INDEX(Config!$E$6:$E$18,MATCH($E67,Config!$D$6:$D$18,0)),"")) -> 4 | Q67: =IF($C67="","",N($K67)+ROW()/1000000) -> 6.7e-05 | R67: =IF($C67="","",N($L67)+ROW()/1000000) -> 6.000067
B68: =IF($C68="","",$C68&" · "&$E68&IF($F68=""," "," "&$F68&" ")&"· "&$D68) -> León · Pequeño · Selva | C68: León | D68: Selva | E68: Pequeño | G68: 12 | H68: 115000 | I68: 12 | J68: =IF($C68="","",SUMIFS(Entradas!$D$5:$D$204,Entradas!$C$5:$C$204,$B68)) -> 0 | K68: =IF($C68="","",SUMIFS(Ventas!$F$5:$F$504,Ventas!$C$5:$C$504,$B68)) -> 0 | L68: =IF($C68="","",N($I68)+N($J68)-N($K68)) -> 12 | M68: =IF($C68="","",N($L68)*N($H68)) -> 1380000 | N68: =IF($C68="","",SUMIFS(Ventas!$I$5:$I$504,Ventas!$C$5:$C$504,$B68)) -> 0 | O68: =IF($C68="","",IF($L68<0,"REVISAR",IF($L68=0,"AGOTADO",IF($L68<=Config!$M$6,"BAJO","OK")))) -> OK | P68: =IF($C68="","",IFERROR(INDEX(Config!$E$6:$E$18,MATCH($E68,Config!$D$6:$D$18,0)),"")) -> 2 | Q68: =IF($C68="","",N($K68)+ROW()/1000000) -> 6.8e-05 | R68: =IF($C68="","",N($L68)+ROW()/1000000) -> 12.000068
B69: =IF($C69="","",$C69&" · "&$E69&IF($F69=""," "," "&$F69&" ")&"· "&$D69) -> León · Grande · Selva | C69: León | D69: Selva | E69: Grande | G69: 7 niño | H69: 140000 | I69: 7 | J69: =IF($C69="","",SUMIFS(Entradas!$D$5:$D$204,Entradas!$C$5:$C$204,$B69)) -> 0 | K69: =IF($C69="","",SUMIFS(Ventas!$F$5:$F$504,Ventas!$C$5:$C$504,$B69)) -> 0 | L69: =IF($C69="","",N($I69)+N($J69)-N($K69)) -> 7 | M69: =IF($C69="","",N($L69)*N($H69)) -> 980000 | N69: =IF($C69="","",SUMIFS(Ventas!$I$5:$I$504,Ventas!$C$5:$C$504,$B69)) -> 0 | O69: =IF($C69="","",IF($L69<0,"REVISAR",IF($L69=0,"AGOTADO",IF($L69<=Config!$M$6,"BAJO","OK")))) -> OK | P69: =IF($C69="","",IFERROR(INDEX(Config!$E$6:$E$18,MATCH($E69,Config!$D$6:$D$18,0)),"")) -> 4 | Q69: =IF($C69="","",N($K69)+ROW()/1000000) -> 6.9e-05 | R69: =IF($C69="","",N($L69)+ROW()/1000000) -> 7.000069
B70: =IF($C70="","",$C70&" · "&$E70&IF($F70=""," "," "&$F70&" ")&"· "&$D70) -> Unicornio · Pequeño · Selva | C70: Unicornio | D70: Selva | E70: Pequeño | G70: 12 niño/a | H70: 95000 | I70: 12 | J70: =IF($C70="","",SUMIFS(Entradas!$D$5:$D$204,Entradas!$C$5:$C$204,$B70)) -> 0 | K70: =IF($C70="","",SUMIFS(Ventas!$F$5:$F$504,Ventas!$C$5:$C$504,$B70)) -> 0 | L70: =IF($C70="","",N($I70)+N($J70)-N($K70)) -> 12 | M70: =IF($C70="","",N($L70)*N($H70)) -> 1140000 | N70: =IF($C70="","",SUMIFS(Ventas!$I$5:$I$504,Ventas!$C$5:$C$504,$B70)) -> 0 | O70: =IF($C70="","",IF($L70<0,"REVISAR",IF($L70=0,"AGOTADO",IF($L70<=Config!$M$6,"BAJO","OK")))) -> OK | P70: =IF($C70="","",IFERROR(INDEX(Config!$E$6:$E$18,MATCH($E70,Config!$D$6:$D$18,0)),"")) -> 2 | Q70: =IF($C70="","",N($K70)+ROW()/1000000) -> 7e-05 | R70: =IF($C70="","",N($L70)+ROW()/1000000) -> 12.00007
B71: =IF($C71="","",$C71&" · "&$E71&IF($F71=""," "," "&$F71&" ")&"· "&$D71) | J71: =IF($C71="","",SUMIFS(Entradas!$D$5:$D$204,Entradas!$C$5:$C$204,$B71)) | K71: =IF($C71="","",SUMIFS(Ventas!$F$5:$F$504,Ventas!$C$5:$C$504,$B71)) | L71: =IF($C71="","",N($I71)+N($J71)-N($K71)) | M71: =IF($C71="","",N($L71)*N($H71)) | N71: =IF($C71="","",SUMIFS(Ventas!$I$5:$I$504,Ventas!$C$5:$C$504,$B71)) | O71: =IF($C71="","",IF($L71<0,"REVISAR",IF($L71=0,"AGOTADO",IF($L71<=Config!$M$6,"BAJO","OK")))) | P71: =IF($C71="","",IFERROR(INDEX(Config!$E$6:$E$18,MATCH($E71,Config!$D$6:$D$18,0)),"")) | Q71: =IF($C71="","",N($K71)+ROW()/1000000) | R71: =IF($C71="","",N($L71)+ROW()/1000000)
B72: =IF($C72="","",$C72&" · "&$E72&IF($F72=""," "," "&$F72&" ")&"· "&$D72) | J72: =IF($C72="","",SUMIFS(Entradas!$D$5:$D$204,Entradas!$C$5:$C$204,$B72)) | K72: =IF($C72="","",SUMIFS(Ventas!$F$5:$F$504,Ventas!$C$5:$C$504,$B72)) | L72: =IF($C72="","",N($I72)+N($J72)-N($K72)) | M72: =IF($C72="","",N($L72)*N($H72)) | N72: =IF($C72="","",SUMIFS(Ventas!$I$5:$I$504,Ventas!$C$5:$C$504,$B72)) | O72: =IF($C72="","",IF($L72<0,"REVISAR",IF($L72=0,"AGOTADO",IF($L72<=Config!$M$6,"BAJO","OK")))) | P72: =IF($C72="","",IFERROR(INDEX(Config!$E$6:$E$18,MATCH($E72,Config!$D$6:$D$18,0)),"")) | Q72: =IF($C72="","",N($K72)+ROW()/1000000) | R72: =IF($C72="","",N($L72)+ROW()/1000000)
...

Sheet Ventas
B1: Registro de ventas
B2: Fecha, producto (lista desplegable), cantidad y método de pago. El precio y el total se calculan solos y el inventario se descuenta al instante.
B4: Fecha | C4: Producto vendido | D4: Colección | E4: Tamaño | F4: Cantidad | G4: Precio unitario | H4: Descuento % | I4: Total venta | J4: Método de pago | K4: Cliente / Nota | L4: Alerta de stock
D5: =IF($C5="","",IFERROR(INDEX(Inventario!$D$5:$D$100,MATCH($C5,Inventario!$B$5:$B$100,0)),"No está en Inventario")) | E5: =IF($C5="","",IFERROR(INDEX(Inventario!$E$5:$E$100,MATCH($C5,Inventario!$B$5:$B$100,0)),"No está en Inventario")) | G5: =IF($C5="","",IFERROR(INDEX(Inventario!$H$5:$H$100,MATCH($C5,Inventario!$B$5:$B$100,0)),"No está en Inventario")) | I5: =IF(OR($C5="",$F5=""),"",N($F5)*N($G5)*(1-N($H5))) | L5: =IF($C5="","",IFERROR(IF(INDEX(Inventario!$L$5:$L$100,MATCH($C5,Inventario!$B$5:$B$100,0))<0,"Stock negativo: revisa","OK"),"No está en Inventario"))
D6: =IF($C6="","",IFERROR(INDEX(Inventario!$D$5:$D$100,MATCH($C6,Inventario!$B$5:$B$100,0)),"No está en Inventario")) | E6: =IF($C6="","",IFERROR(INDEX(Inventario!$E$5:$E$100,MATCH($C6,Inventario!$B$5:$B$100,0)),"No está en Inventario")) | G6: =IF($C6="","",IFERROR(INDEX(Inventario!$H$5:$H$100,MATCH($C6,Inventario!$B$5:$B$100,0)),"No está en Inventario")) | I6: =IF(OR($C6="",$F6=""),"",N($F6)*N($G6)*(1-N($H6))) | L6: =IF($C6="","",IFERROR(IF(INDEX(Inventario!$L$5:$L$100,MATCH($C6,Inventario!$B$5:$B$100,0))<0,"Stock negativo: revisa","OK"),"No está en Inventario"))
D7: =IF($C7="","",IFERROR(INDEX(Inventario!$D$5:$D$100,MATCH($C7,Inventario!$B$5:$B$100,0)),"No está en Inventario")) | E7: =IF($C7="","",IFERROR(INDEX(Inventario!$E$5:$E$100,MATCH($C7,Inventario!$B$5:$B$100,0)),"No está en Inventario")) | G7: =IF($C7="","",IFERROR(INDEX(Inventario!$H$5:$H$100,MATCH($C7,Inventario!$B$5:$B$100,0)),"No está en Inventario")) | I7: =IF(OR($C7="",$F7=""),"",N($F7)*N($G7)*(1-N($H7))) | L7: =IF($C7="","",IFERROR(IF(INDEX(Inventario!$L$5:$L$100,MATCH($C7,Inventario!$B$5:$B$100,0))<0,"Stock negativo: revisa","OK"),"No está en Inventario"))
D8: =IF($C8="","",IFERROR(INDEX(Inventario!$D$5:$D$100,MATCH($C8,Inventario!$B$5:$B$100,0)),"No está en Inventario")) | E8: =IF($C8="","",IFERROR(INDEX(Inventario!$E$5:$E$100,MATCH($C8,Inventario!$B$5:$B$100,0)),"No está en Inventario")) | G8: =IF($C8="","",IFERROR(INDEX(Inventario!$H$5:$H$100,MATCH($C8,Inventario!$B$5:$B$100,0)),"No está en Inventario")) | I8: =IF(OR($C8="",$F8=""),"",N($F8)*N($G8)*(1-N($H8))) | L8: =IF($C8="","",IFERROR(IF(INDEX(Inventario!$L$5:$L$100,MATCH($C8,Inventario!$B$5:$B$100,0))<0,"Stock negativo: revisa","OK"),"No está en Inventario"))
D9: =IF($C9="","",IFERROR(INDEX(Inventario!$D$5:$D$100,MATCH($C9,Inventario!$B$5:$B$100,0)),"No está en Inventario")) | E9: =IF($C9="","",IFERROR(INDEX(Inventario!$E$5:$E$100,MATCH($C9,Inventario!$B$5:$B$100,0)),"No está en Inventario")) | G9: =IF($C9="","",IFERROR(INDEX(Inventario!$H$5:$H$100,MATCH($C9,Inventario!$B$5:$B$100,0)),"No está en Inventario")) | I9: =IF(OR($C9="",$F9=""),"",N($F9)*N($G9)*(1-N($H9))) | L9: =IF($C9="","",IFERROR(IF(INDEX(Inventario!$L$5:$L$100,MATCH($C9,Inventario!$B$5:$B$100,0))<0,"Stock negativo: revisa","OK"),"No está en Inventario"))
D10: =IF($C10="","",IFERROR(INDEX(Inventario!$D$5:$D$100,MATCH($C10,Inventario!$B$5:$B$100,0)),"No está en Inventario")) | E10: =IF($C10="","",IFERROR(INDEX(Inventario!$E$5:$E$100,MATCH($C10,Inventario!$B$5:$B$100,0)),"No está en Inventario")) | G10: =IF($C10="","",IFERROR(INDEX(Inventario!$H$5:$H$100,MATCH($C10,Inventario!$B$5:$B$100,0)),"No está en Inventario")) | I10: =IF(OR($C10="",$F10=""),"",N($F10)*N($G10)*(1-N($H10))) | L10: =IF($C10="","",IFERROR(IF(INDEX(Inventario!$L$5:$L$100,MATCH($C10,Inventario!$B$5:$B$100,0))<0,"Stock negativo: revisa","OK"),"No está en Inventario"))
D11: =IF($C11="","",IFERROR(INDEX(Inventario!$D$5:$D$100,MATCH($C11,Inventario!$B$5:$B$100,0)),"No está en Inventario")) | E11: =IF($C11="","",IFERROR(INDEX(Inventario!$E$5:$E$100,MATCH($C11,Inventario!$B$5:$B$100,0)),"No está en Inventario")) | G11: =IF($C11="","",IFERROR(INDEX(Inventario!$H$5:$H$100,MATCH($C11,Inventario!$B$5:$B$100,0)),"No está en Inventario")) | I11: =IF(OR($C11="",$F11=""),"",N($F11)*N($G11)*(1-N($H11))) | L11: =IF($C11="","",IFERROR(IF(INDEX(Inventario!$L$5:$L$100,MATCH($C11,Inventario!$B$5:$B$100,0))<0,"Stock negativo: revisa","OK"),"No está en Inventario"))
D12: =IF($C12="","",IFERROR(INDEX(Inventario!$D$5:$D$100,MATCH($C12,Inventario!$B$5:$B$100,0)),"No está en Inventario")) | E12: =IF($C12="","",IFERROR(INDEX(Inventario!$E$5:$E$100,MATCH($C12,Inventario!$B$5:$B$100,0)),"No está en Inventario")) | G12: =IF($C12="","",IFERROR(INDEX(Inventario!$H$5:$H$100,MATCH($C12,Inventario!$B$5:$B$100,0)),"No está en Inventario")) | I12: =IF(OR($C12="",$F12=""),"",N($F12)*N($G12)*(1-N($H12))) | L12: =IF($C12="","",IFERROR(IF(INDEX(Inventario!$L$5:$L$100,MATCH($C12,Inventario!$B$5:$B$100,0))<0,"Stock negativo: revisa","OK"),"No está en Inventario"))
D13: =IF($C13="","",IFERROR(INDEX(Inventario!$D$5:$D$100,MATCH($C13,Inventario!$B$5:$B$100,0)),"No está en Inventario")) | E13: =IF($C13="","",IFERROR(INDEX(Inventario!$E$5:$E$100,MATCH($C13,Inventario!$B$5:$B$100,0)),"No está en Inventario")) | G13: =IF($C13="","",IFERROR(INDEX(Inventario!$H$5:$H$100,MATCH($C13,Inventario!$B$5:$B$100,0)),"No está en Inventario")) | I13: =IF(OR($C13="",$F13=""),"",N($F13)*N($G13)*(1-N($H13))) | L13: =IF($C13="","",IFERROR(IF(INDEX(Inventario!$L$5:$L$100,MATCH($C13,Inventario!$B$5:$B$100,0))<0,"Stock negativo: revisa","OK"),"No está en Inventario"))
D14: =IF($C14="","",IFERROR(INDEX(Inventario!$D$5:$D$100,MATCH($C14,Inventario!$B$5:$B$100,0)),"No está en Inventario")) | E14: =IF($C14="","",IFERROR(INDEX(Inventario!$E$5:$E$100,MATCH($C14,Inventario!$B$5:$B$100,0)),"No está en Inventario")) | G14: =IF($C14="","",IFERROR(INDEX(Inventario!$H$5:$H$100,MATCH($C14,Inventario!$B$5:$B$100,0)),"No está en Inventario")) | I14: =IF(OR($C14="",$F14=""),"",N($F14)*N($G14)*(1-N($H14))) | L14: =IF($C14="","",IFERROR(IF(INDEX(Inventario!$L$5:$L$100,MATCH($C14,Inventario!$B$5:$B$100,0))<0,"Stock negativo: revisa","OK"),"No está en Inventario"))
D15: =IF($C15="","",IFERROR(INDEX(Inventario!$D$5:$D$100,MATCH($C15,Inventario!$B$5:$B$100,0)),"No está en Inventario")) | E15: =IF($C15="","",IFERROR(INDEX(Inventario!$E$5:$E$100,MATCH($C15,Inventario!$B$5:$B$100,0)),"No está en Inventario")) | G15: =IF($C15="","",IFERROR(INDEX(Inventario!$H$5:$H$100,MATCH($C15,Inventario!$B$5:$B$100,0)),"No está en Inventario")) | I15: =IF(OR($C15="",$F15=""),"",N($F15)*N($G15)*(1-N($H15))) | L15: =IF($C15="","",IFERROR(IF(INDEX(Inventario!$L$5:$L$100,MATCH($C15,Inventario!$B$5:$B$100,0))<0,"Stock negativo: revisa","OK"),"No está en Inventario"))
D16: =IF($C16="","",IFERROR(INDEX(Inventario!$D$5:$D$100,MATCH($C16,Inventario!$B$5:$B$100,0)),"No está en Inventario")) | E16: =IF($C16="","",IFERROR(INDEX(Inventario!$E$5:$E$100,MATCH($C16,Inventario!$B$5:$B$100,0)),"No está en Inventario")) | G16: =IF($C16="","",IFERROR(INDEX(Inventario!$H$5:$H$100,MATCH($C16,Inventario!$B$5:$B$100,0)),"No está en Inventario")) | I16: =IF(OR($C16="",$F16=""),"",N($F16)*N($G16)*(1-N($H16))) | L16: =IF($C16="","",IFERROR(IF(INDEX(Inventario!$L$5:$L$100,MATCH($C16,Inventario!$B$5:$B$100,0))<0,"Stock negativo: revisa","OK"),"No está en Inventario"))
... D504: =IF($C504="","",IFERROR(INDEX(Inventario!$D$5:$D$100,MATCH($C504,Inventario!$B$5:$B$100,0)),"No está en Inventario")) | E504: =IF($C504="","",IFERROR(INDEX(Inventario!$E$5:$E$100,MATCH($C504,Inventario!$B$5:$B$100,0)),"No está en Inventario")) | G504: =IF($C504="","",IFERROR(INDEX(Inventario!$H$5:$H$100,MATCH($C504,Inventario!$B$5:$B$100,0)),"No está en Inventario")) | I504: =IF(OR($C504="",$F504=""),"",N($F504)*N($G504)*(1-N($H504))) | L504: =IF($C504="","",IFERROR(IF(INDEX(Inventario!$L$5:$L$100,MATCH($C504,Inventario!$B$5:$B$100,0))<0,"Stock negativo: revisa","OK"),"No está en Inventario"))
B506: TOTALES | F506: =SUM(F5:F504) -> 0 | I506: =SUM(I5:I504) -> 0
B508: • Si vendes 2 unidades escribes 2 en Cantidad: el "Stock actual" del Inventario baja 2 automáticamente.
B509: • Para una devolución, registra la misma venta con cantidad en negativo (-2). El stock vuelve a subir.
B510: • Descuento: escribe 10% (no 10). Si no hay descuento, deja la celda vacía.
B511: • Si la alerta dice "Stock negativo: revisa", vendiste más unidades de las que tenías registradas: revisa el stock inicial o registra la entrada que falta.

Sheet Entradas
B1: Entradas de inventario
B2: Solo cantidades. Cada vez que produzcas o repongas unidades regístralo aquí y el stock del inventario sube automáticamente.
B4: Fecha | C4: Producto | D4: Cantidad que entra | E4: Motivo | F4: Nota
B206: TOTAL | D206: =SUM(D5:D204) -> 0
B208: • El producto se elige de la misma lista desplegable del Inventario, así que no hay que escribir códigos.
B209: • Si te equivocaste y entraron menos unidades, registra la diferencia en negativo con motivo "Ajuste de inventario".

Sheet Resumen
B1: Resumen
B2: Todo se calcula solo a partir de Inventario, Ventas y Entradas. No hay nada que escribir en esta hoja.
B4: Inventario y ventas por colección
B5: Colección | C5: Referencias | D5: Unidades en stock | E5: Valor en stock | F5: Unidades vendidas | G5: Ingresos
B6: =Config!$B$6 -> Bebé | C6: =COUNTIFS(Inventario!$D$5:$D$100,$B$6) -> 13 | D6: =SUMIFS(Inventario!$L$5:$L$100,Inventario!$D$5:$D$100,$B$6) -> 95 | E6: =SUMIFS(Inventario!$M$5:$M$100,Inventario!$D$5:$D$100,$B$6) -> 10925000 | F6: =SUMIFS(Inventario!$K$5:$K$100,Inventario!$D$5:$D$100,$B$6) -> 0 | G6: =SUMIFS(Inventario!$N$5:$N$100,Inventario!$D$5:$D$100,$B$6) -> 0
B7: =Config!$B$7 -> Granja | C7: =COUNTIFS(Inventario!$D$5:$D$100,$B$7) -> 15 | D7: =SUMIFS(Inventario!$L$5:$L$100,Inventario!$D$5:$D$100,$B$7) -> 133 | E7: =SUMIFS(Inventario!$M$5:$M$100,Inventario!$D$5:$D$100,$B$7) -> 12525000 | F7: =SUMIFS(Inventario!$K$5:$K$100,Inventario!$D$5:$D$100,$B$7) -> 0 | G7: =SUMIFS(Inventario!$N$5:$N$100,Inventario!$D$5:$D$100,$B$7) -> 0
B8: =Config!$B$8 -> Halloween | C8: =COUNTIFS(Inventario!$D$5:$D$100,$B$8) -> 6 | D8: =SUMIFS(Inventario!$L$5:$L$100,Inventario!$D$5:$D$100,$B$8) -> 43 | E8: =SUMIFS(Inventario!$M$5:$M$100,Inventario!$D$5:$D$100,$B$8) -> 5330000 | F8: =SUMIFS(Inventario!$K$5:$K$100,Inventario!$D$5:$D$100,$B$8) -> 0 | G8: =SUMIFS(Inventario!$N$5:$N$100,Inventario!$D$5:$D$100,$B$8) -> 0
B9: =Config!$B$9 -> Llavero | C9: =COUNTIFS(Inventario!$D$5:$D$100,$B$9) -> 3 | D9: =SUMIFS(Inventario!$L$5:$L$100,Inventario!$D$5:$D$100,$B$9) -> 16 | E9: =SUMIFS(Inventario!$M$5:$M$100,Inventario!$D$5:$D$100,$B$9) -> 1040000 | F9: =SUMIFS(Inventario!$K$5:$K$100,Inventario!$D$5:$D$100,$B$9) -> 0 | G9: =SUMIFS(Inventario!$N$5:$N$100,Inventario!$D$5:$D$100,$B$9) -> 0
B10: =Config!$B$10 -> Mar | C10: =COUNTIFS(Inventario!$D$5:$D$100,$B$10) -> 1 | D10: =SUMIFS(Inventario!$L$5:$L$100,Inventario!$D$5:$D$100,$B$10) -> 2 | E10: =SUMIFS(Inventario!$M$5:$M$100,Inventario!$D$5:$D$100,$B$10) -> 240000 | F10: =SUMIFS(Inventario!$K$5:$K$100,Inventario!$D$5:$D$100,$B$10) -> 0 | G10: =SUMIFS(Inventario!$N$5:$N$100,Inventario!$D$5:$D$100,$B$10) -> 0
B11: =Config!$B$11 -> Muñecas | C11: =COUNTIFS(Inventario!$D$5:$D$100,$B$11) -> 8 | D11: =SUMIFS(Inventario!$L$5:$L$100,Inventario!$D$5:$D$100,$B$11) -> 67 | E11: =SUMIFS(Inventario!$M$5:$M$100,Inventario!$D$5:$D$100,$B$11) -> 9545000 | F11: =SUMIFS(Inventario!$K$5:$K$100,Inventario!$D$5:$D$100,$B$11) -> 0 | G11: =SUMIFS(Inventario!$N$5:$N$100,Inventario!$D$5:$D$100,$B$11) -> 0
B12: =Config!$B$12 -> Navidad | C12: =COUNTIFS(Inventario!$D$5:$D$100,$B$12) -> 3 | D12: =SUMIFS(Inventario!$L$5:$L$100,Inventario!$D$5:$D$100,$B$12) -> 13 | E12: =SUMIFS(Inventario!$M$5:$M$100,Inventario!$D$5:$D$100,$B$12) -> 1610000 | F12: =SUMIFS(Inventario!$K$5:$K$100,Inventario!$D$5:$D$100,$B$12) -> 0 | G12: =SUMIFS(Inventario!$N$5:$N$100,Inventario!$D$5:$D$100,$B$12) -> 0
B13: =Config!$B$13 -> Otros | C13: =COUNTIFS(Inventario!$D$5:$D$100,$B$13) -> 8 | D13: =SUMIFS(Inventario!$L$5:$L$100,Inventario!$D$5:$D$100,$B$13) -> 81 | E13: =SUMIFS(Inventario!$M$5:$M$100,Inventario!$D$5:$D$100,$B$13) -> 0 | F13: =SUMIFS(Inventario!$K$5:$K$100,Inventario!$D$5:$D$100,$B$13) -> 0 | G13: =SUMIFS(Inventario!$N$5:$N$100,Inventario!$D$5:$D$100,$B$13) -> 0
B14: =Config!$B$14 -> Selva | C14: =COUNTIFS(Inventario!$D$5:$D$100,$B$14) -> 9 | D14: =SUMIFS(Inventario!$L$5:$L$100,Inventario!$D$5:$D$100,$B$14) -> 63 | E14: =SUMIFS(Inventario!$M$5:$M$100,Inventario!$D$5:$D$100,$B$14) -> 7485000 | F14: =SUMIFS(Inventario!$K$5:$K$100,Inventario!$D$5:$D$100,$B$14) -> 0 | G14: =SUMIFS(Inventario!$N$5:$N$100,Inventario!$D$5:$D$100,$B$14) -> 0
B15: TOTAL | C15: =SUM(C6:C14) -> 66 | D15: =SUM(D6:D14) -> 513 | E15: =SUM(E6:E14) -> 48700000 | F15: =SUM(F6:F14) -> 0 | G15: =SUM(G6:G14) -> 0
B18: Inventario y ventas por tamaño
B19: Tamaño | C19: Referencias | D19: Unidades en stock | E19: Valor en stock | F19: Unidades vendidas | G19: Ingresos
B20: =Config!$D$6 -> Mini | C20: =COUNTIFS(Inventario!$E$5:$E$100,$B$20) -> 2 | D20: =SUMIFS(Inventario!$L$5:$L$100,Inventario!$E$5:$E$100,$B$20) -> 20 | E20: =SUMIFS(Inventario!$M$5:$M$100,Inventario!$E$5:$E$100,$B$20) -> 0 | F20: =SUMIFS(Inventario!$K$5:$K$100,Inventario!$E$5:$E$100,$B$20) -> 0 | G20: =SUMIFS(Inventario!$N$5:$N$100,Inventario!$E$5:$E$100,$B$20) -> 0
B21: =Config!$D$7 -> Pequeño | C21: =COUNTIFS(Inventario!$E$5:$E$100,$B$21) -> 18 | D21: =SUMIFS(Inventario!$L$5:$L$100,Inventario!$E$5:$E$100,$B$21) -> 176 | E21: =SUMIFS(Inventario!$M$5:$M$100,Inventario!$E$5:$E$100,$B$21) -> 12520000 | F21: =SUMIFS(Inventario!$K$5:$K$100,Inventario!$E$5:$E$100,$B$21) -> 0 | G21: =SUMIFS(Inventario!$N$5:$N$100,Inventario!$E$5:$E$100,$B$21) -> 0
B22: =Config!$D$8 -> Mediano | C22: =COUNTIFS(Inventario!$E$5:$E$100,$B$22) -> 3 | D22: =SUMIFS(Inventario!$L$5:$L$100,Inventario!$E$5:$E$100,$B$22) -> 12 | E22: =SUMIFS(Inventario!$M$5:$M$100,Inventario!$E$5:$E$100,$B$22) -> 115000 | F22: =SUMIFS(Inventario!$K$5:$K$100,Inventario!$E$5:$E$100,$B$22) -> 0 | G22: =SUMIFS(Inventario!$N$5:$N$100,Inventario!$E$5:$E$100,$B$22) -> 0
B23: =Config!$D$9 -> Grande | C23: =COUNTIFS(Inventario!$E$5:$E$100,$B$23) -> 18 | D23: =SUMIFS(Inventario!$L$5:$L$100,Inventario!$E$5:$E$100,$B$23) -> 123 | E23: =SUMIFS(Inventario!$M$5:$M$100,Inventario!$E$5:$E$100,$B$23) -> 15685000 | F23: =SUMIFS(Inventario!$K$5:$K$100,Inventario!$E$5:$E$100,$B$23) -> 0 | G23: =SUMIFS(Inventario!$N$5:$N$100,Inventario!$E$5:$E$100,$B$23) -> 0
B24: =Config!$D$10 -> Único | C24: =COUNTIFS(Inventario!$E$5:$E$100,$B$24) -> 25 | D24: =SUMIFS(Inventario!$L$5:$L$100,Inventario!$E$5:$E$100,$B$24) -> 182 | E24: =SUMIFS(Inventario!$M$5:$M$100,Inventario!$E$5:$E$100,$B$24) -> 20380000 | F24: =SUMIFS(Inventario!$K$5:$K$100,Inventario!$E$5:$E$100,$B$24) -> 0 | G24: =SUMIFS(Inventario!$N$5:$N$100,Inventario!$E$5:$E$100,$B$24) -> 0
B25: TOTAL | C25: =SUM(C20:C24) -> 66 | D25: =SUM(D20:D24) -> 513 | E25: =SUM(E20:E24) -> 48700000 | F25: =SUM(F20:F24) -> 0 | G25: =SUM(G20:G24) -> 0
B28: Ventas por método de pago
B29: Método de pago | C29: N° de ventas | D29: Unidades | E29: Ingresos | F29: % de los ingresos
B30: =Config!$G$6 -> Efectivo | C30: =COUNTIFS(Ventas!$J$5:$J$504,$B$30) -> 0 | D30: =SUMIFS(Ventas!$F$5:$F$504,Ventas!$J$5:$J$504,$B$30) -> 0 | E30: =SUMIFS(Ventas!$I$5:$I$504,Ventas!$J$5:$J$504,$B$30) -> 0 | F30: =IFERROR($E$30/SUM($E$30:$E$34),0) -> 0
B31: =Config!$G$7 -> Nequi | C31: =COUNTIFS(Ventas!$J$5:$J$504,$B$31) -> 0 | D31: =SUMIFS(Ventas!$F$5:$F$504,Ventas!$J$5:$J$504,$B$31) -> 0 | E31: =SUMIFS(Ventas!$I$5:$I$504,Ventas!$J$5:$J$504,$B$31) -> 0 | F31: =IFERROR($E$31/SUM($E$30:$E$34),0) -> 0
B32: =Config!$G$8 -> Tarjeta | C32: =COUNTIFS(Ventas!$J$5:$J$504,$B$32) -> 0 | D32: =SUMIFS(Ventas!$F$5:$F$504,Ventas!$J$5:$J$504,$B$32) -> 0 | E32: =SUMIFS(Ventas!$I$5:$I$504,Ventas!$J$5:$J$504,$B$32) -> 0 | F32: =IFERROR($E$32/SUM($E$30:$E$34),0) -> 0
B33: =Config!$G$9 -> Daviplata | C33: =COUNTIFS(Ventas!$J$5:$J$504,$B$33) -> 0 | D33: =SUMIFS(Ventas!$F$5:$F$504,Ventas!$J$5:$J$504,$B$33) -> 0 | E33: =SUMIFS(Ventas!$I$5:$I$504,Ventas!$J$5:$J$504,$B$33) -> 0 | F33: =IFERROR($E$33/SUM($E$30:$E$34),0) -> 0
B34: =Config!$G$10 -> Llave | C34: =COUNTIFS(Ventas!$J$5:$J$504,$B$34) -> 0 | D34: =SUMIFS(Ventas!$F$5:$F$504,Ventas!$J$5:$J$504,$B$34) -> 0 | E34: =SUMIFS(Ventas!$I$5:$I$504,Ventas!$J$5:$J$504,$B$34) -> 0 | F34: =IFERROR($E$34/SUM($E$30:$E$34),0) -> 0
B35: TOTAL | C35: =SUM(C30:C34) -> 0 | D35: =SUM(D30:D34) -> 0 | E35: =SUM(E30:E34) -> 0 | F35: =SUM(F30:F34) -> 0
B38: Ventas por mes
B39: Mes | C39: N° de ventas | D39: Unidades | E39: Ingresos | F39: Ticket promedio
B40: Enero | C40: =COUNTIFS(Ventas!$B$5:$B$504,">="&DATE(Config!$M$7,1,1),Ventas!$B$5:$B$504,"<"&DATE(Config!$M$7,2,1)) -> 0 | D40: =SUMIFS(Ventas!$F$5:$F$504,Ventas!$B$5:$B$504,">="&DATE(Config!$M$7,1,1),Ventas!$B$5:$B$504,"<"&DATE(Config!$M$7,2,1)) -> 0 | E40: =SUMIFS(Ventas!$I$5:$I$504,Ventas!$B$5:$B$504,">="&DATE(Config!$M$7,1,1),Ventas!$B$5:$B$504,"<"&DATE(Config!$M$7,2,1)) -> 0 | F40: =IFERROR($E$40/$C$40,"-") -> -
B41: Febrero | C41: =COUNTIFS(Ventas!$B$5:$B$504,">="&DATE(Config!$M$7,2,1),Ventas!$B$5:$B$504,"<"&DATE(Config!$M$7,3,1)) -> 0 | D41: =SUMIFS(Ventas!$F$5:$F$504,Ventas!$B$5:$B$504,">="&DATE(Config!$M$7,2,1),Ventas!$B$5:$B$504,"<"&DATE(Config!$M$7,3,1)) -> 0 | E41: =SUMIFS(Ventas!$I$5:$I$504,Ventas!$B$5:$B$504,">="&DATE(Config!$M$7,2,1),Ventas!$B$5:$B$504,"<"&DATE(Config!$M$7,3,1)) -> 0 | F41: =IFERROR($E$41/$C$41,"-") -> -
B42: Marzo | C42: =COUNTIFS(Ventas!$B$5:$B$504,">="&DATE(Config!$M$7,3,1),Ventas!$B$5:$B$504,"<"&DATE(Config!$M$7,4,1)) -> 0 | D42: =SUMIFS(Ventas!$F$5:$F$504,Ventas!$B$5:$B$504,">="&DATE(Config!$M$7,3,1),Ventas!$B$5:$B$504,"<"&DATE(Config!$M$7,4,1)) -> 0 | E42: =SUMIFS(Ventas!$I$5:$I$504,Ventas!$B$5:$B$504,">="&DATE(Config!$M$7,3,1),Ventas!$B$5:$B$504,"<"&DATE(Config!$M$7,4,1)) -> 0 | F42: =IFERROR($E$42/$C$42,"-") -> -
B43: Abril | C43: =COUNTIFS(Ventas!$B$5:$B$504,">="&DATE(Config!$M$7,4,1),Ventas!$B$5:$B$504,"<"&DATE(Config!$M$7,5,1)) -> 0 | D43: =SUMIFS(Ventas!$F$5:$F$504,Ventas!$B$5:$B$504,">="&DATE(Config!$M$7,4,1),Ventas!$B$5:$B$504,"<"&DATE(Config!$M$7,5,1)) -> 0 | E43: =SUMIFS(Ventas!$I$5:$I$504,Ventas!$B$5:$B$504,">="&DATE(Config!$M$7,4,1),Ventas!$B$5:$B$504,"<"&DATE(Config!$M$7,5,1)) -> 0 | F43: =IFERROR($E$43/$C$43,"-") -> -
B44: Mayo | C44: =COUNTIFS(Ventas!$B$5:$B$504,">="&DATE(Config!$M$7,5,1),Ventas!$B$5:$B$504,"<"&DATE(Config!$M$7,6,1)) -> 0 | D44: =SUMIFS(Ventas!$F$5:$F$504,Ventas!$B$5:$B$504,">="&DATE(Config!$M$7,5,1),Ventas!$B$5:$B$504,"<"&DATE(Config!$M$7,6,1)) -> 0 | E44: =SUMIFS(Ventas!$I$5:$I$504,Ventas!$B$5:$B$504,">="&DATE(Config!$M$7,5,1),Ventas!$B$5:$B$504,"<"&DATE(Config!$M$7,6,1)) -> 0 | F44: =IFERROR($E$44/$C$44,"-") -> -
B45: Junio | C45: =COUNTIFS(Ventas!$B$5:$B$504,">="&DATE(Config!$M$7,6,1),Ventas!$B$5:$B$504,"<"&DATE(Config!$M$7,7,1)) -> 0 | D45: =SUMIFS(Ventas!$F$5:$F$504,Ventas!$B$5:$B$504,">="&DATE(Config!$M$7,6,1),Ventas!$B$5:$B$504,"<"&DATE(Config!$M$7,7,1)) -> 0 | E45: =SUMIFS(Ventas!$I$5:$I$504,Ventas!$B$5:$B$504,">="&DATE(Config!$M$7,6,1),Ventas!$B$5:$B$504,"<"&DATE(Config!$M$7,7,1)) -> 0 | F45: =IFERROR($E$45/$C$45,"-") -> -
B46: Julio | C46: =COUNTIFS(Ventas!$B$5:$B$504,">="&DATE(Config!$M$7,7,1),Ventas!$B$5:$B$504,"<"&DATE(Config!$M$7,8,1)) -> 0 | D46: =SUMIFS(Ventas!$F$5:$F$504,Ventas!$B$5:$B$504,">="&DATE(Config!$M$7,7,1),Ventas!$B$5:$B$504,"<"&DATE(Config!$M$7,8,1)) -> 0 | E46: =SUMIFS(Ventas!$I$5:$I$504,Ventas!$B$5:$B$504,">="&DATE(Config!$M$7,7,1),Ventas!$B$5:$B$504,"<"&DATE(Config!$M$7,8,1)) -> 0 | F46: =IFERROR($E$46/$C$46,"-") -> -
B47: Agosto | C47: =COUNTIFS(Ventas!$B$5:$B$504,">="&DATE(Config!$M$7,8,1),Ventas!$B$5:$B$504,"<"&DATE(Config!$M$7,9,1)) -> 0 | D47: =SUMIFS(Ventas!$F$5:$F$504,Ventas!$B$5:$B$504,">="&DATE(Config!$M$7,8,1),Ventas!$B$5:$B$504,"<"&DATE(Config!$M$7,9,1)) -> 0 | E47: =SUMIFS(Ventas!$I$5:$I$504,Ventas!$B$5:$B$504,">="&DATE(Config!$M$7,8,1),Ventas!$B$5:$B$504,"<"&DATE(Config!$M$7,9,1)) -> 0 | F47: =IFERROR($E$47/$C$47,"-") -> -
...

Sheet Config
B1: Configuración
B2: Aquí viven las listas desplegables y los parámetros. Puedes agregar opciones al final de cada lista y el resto del archivo las reconoce.
B4: Colecciones | D4: Tamaños y su orden | G4: Métodos de pago | I4: Motivos de entrada | L4: Parámetros
B5: Colección | D5: Tamaño | E5: Orden | G5: Método | I5: Motivo | L5: Parámetro | M5: Valor
B6: Bebé | D6: Mini | E6: 1 | G6: Efectivo | I6: Producción nueva | L6: Umbral de stock bajo (unidades) | M6: 3
B7: Granja | D7: Pequeño | E7: 2 | G7: Nequi | I7: Reposición | L7: Año de la temporada | M7: 2026
B8: Halloween | D8: Mediano | E8: 3 | G8: Tarjeta | I8: Ajuste de inventario | L8: Moneda | M8: COP
B9: Llavero | D9: Grande | E9: 4 | G9: Daviplata | I9: Devolución de cliente
B10: Mar | D10: Único | E10: 5 | G10: Llave
B11: Muñecas | L11: El umbral marca en amarillo toda referencia con esa cantidad o menos.
B12: Navidad | L12: El año se usa en la tabla "Ventas por mes" del Resumen.
B13: Otros
B14: Selva
